Workbook

Sheet Assumptions
A1: MyAdvocate Financial Model v17 — Assumptions
A2: Source: PMP v22 | v17.0 — March 2026 | SIMPLIFIED: Decay-curve SEO, YT as traffic funnel, IG as traffic boost
A3: Blue = input (user-editable) | Black = calculated | Green = cross-sheet link
A5: CORE BUSINESS ASSUMPTIONS
A6: Launch Month | B6: 1 | C6: Month 1 = Launch
A7: Planning Horizon (months) | B7: 36 | C7: 3-year projection
A9: PRICING STRUCTURE
A10: Founding Advocate Annual Price | B10: 34 | C10: $34/year — first 250 subs, locked forever
A11: Founding Advocate Monthly Equivalent | B11: =B10/12 -> 2.8333333 | C11: $34/12 — MRR calculation
A12: FA Renewal Price (Year 2+) | B12: 55 | C12: $55/yr — permanent FA rate
A13: FA Cohort Cap | B13: 250 | C13: Maximum Founding Advocates
A14: Basic Tier Monthly | B14: 8 | C14: Launch tier — all new subs M1–M8
A15: Standard Tier Monthly (M9+) | B15: 13 | C15: Price increase M9 — new subs only
A16: Advocate Builder Quarterly | B16: 21 | C16: $21/quarter
A17: Advocate Builder Monthly Equiv | B17: =B16/3 -> 7 | C17: $21/3 — MRR purposes
A18: Annual Standard Price | B18: 55 | C18: $55/yr committed annual
A19: Premium Monthly (Phase 4+) | B19: 21 | C19: Native app tier — Phase 4 unlock
A21: CONVERSION RATES — HEALTHCARE COLD TRAFFIC
A22: Conservative Paid Conversion | B22: 0.0015 | C22: 0.15% — cold traffic baseline. Validated: industry 0.5-1.5% for warm; cold = lower
A23: Expected Paid Conversion | B23: 0.0025 | C23: 0.25% — moderate, denial-code SEO boost
A24: Optimistic Paid Conversion | B24: 0.005 | C24: 0.50% — high-intent denial code + optimized funnel
A25: Free Signup / Email Capture Rate | B25: 0.02 | C25: 2.0% of total visitors — email list growth (tracked elsewhere)
A26: Denial Decoder Free-to-Paid Lift | B26: 1.15 | C26: 15% higher conversion from denial code visitors
A27: FA Conversion Rate (of early subs) | B27: 0.4 | C27: ~40% of first subs take FA offer
A29: SEO TRAFFIC — DECAY CURVE MODEL
A30: Month 1 Traffic — Conservative | B30: 250 | C30: New domain, minimal indexed content
A31: Month 1 Traffic — Expected | B31: 500 | C31: Early SEO content live at launch
A32: Month 1 Traffic — Optimistic | B32: 750 | C32: Pre-launch content build + denial codes starting
A34: YEAR 1 (M1-M12) MoM Growth — Conservative | B34: 0.1 | C34: 10% — slow organic compounding, denial codes indexing
A35: YEAR 1 (M1-M12) MoM Growth — Expected | B35: 0.14 | C35: 14% — consistent 2x/week + denial codes
A36: YEAR 1 (M1-M12) MoM Growth — Optimistic | B36: 0.18 | C36: 18% — aggressive SEO + denial codes indexing fast
A38: YEAR 2 (M13-M24) MoM Growth — Conservative | B38: 0.06 | C38: 6% — competition ceilings hit
A39: YEAR 2 (M13-M24) MoM Growth — Expected | B39: 0.09 | C39: 9% — clusters maturing, backlinks growing
A40: YEAR 2 (M13-M24) MoM Growth — Optimistic | B40: 0.12 | C40: 12% — strong domain authority building
A42: YEAR 3 (M25-M36) MoM Growth — Conservative | B42: 0.04 | C42: 4% — mature, near ceiling for solo ops
A43: YEAR 3 (M25-M36) MoM Growth — Expected | B43: 0.06 | C43: 6% — sustained with refresh + new clusters
A44: YEAR 3 (M25-M36) MoM Growth — Optimistic | B44: 0.08 | C44: 8% — strong brand + expanding content
... A47: Content Cluster Maturity Boost (M6+) | B47: 1.08 | C47: 8% lift as pillar/cluster architecture matures
A49: CHURN & RETENTION
A50: Monthly Churn — Conservative | B50: 0.08 | C50: 8% — challenging healthcare retention
...

Sheet Dashboard
A1: MyAdvocate Projections v17 — Executive Dashboard
A2: Simplified: Decay-curve SEO | YT traffic funnel | IG traffic boost | Owner's Draw
B4: Conservative | C4: Expected | D4: Optimistic
A5: Total Monthly Visitors (M36) | B5: =Conservative!E39 -> 3445 | C5: =Expected!E39 -> 15433 | D5: =Optimistic!E39 -> 57029
A6: → Organic SEO | B6: =Conservative!B39 -> 2854 | C6: =Expected!B39 -> 14842 | D6: =Optimistic!B39 -> 56438
A7: → YouTube | B7: =Conservative!C39 -> 540 | C7: =Expected!C39 -> 540 | D7: =Optimistic!C39 -> 540
A8: → Instagram | B8: =Conservative!D39 -> 51 | C8: =Expected!D39 -> 51 | D8: =Optimistic!D39 -> 51
A9: Paid Subscribers (M36) | B9: =Conservative!H39 -> 44 | C9: =Expected!H39 -> 304 | D9: =Optimistic!H39 -> 2116
A10: MRR (M36) | B10: =Conservative!I39 -> 505 | C10: =Expected!I39 -> 3488 | D10: =Optimistic!I39 -> 24281
A11: Total Revenue (M36) | B11: =Conservative!M39 -> 1939 | C11: =Expected!M39 -> 9586 | D11: =Optimistic!M39 -> 46559
A12: Gross Profit (M36) | B12: =Conservative!O39 -> 1717 | C12: =Expected!O39 -> 9127 | D12: =Optimistic!O39 -> 44401
A13: Owner's Draw (M36) | B13: =Conservative!P39 -> 859 | C13: =Expected!P39 -> 4564 | D13: =Optimistic!P39 -> 22201
A14: Reserve Balance (M36) | B14: =Conservative!Q39 -> 11033 | C14: =Expected!Q39 -> 56802 | D14: =Optimistic!Q39 -> 236042
A16: 3-YEAR TOTALS
A17: 3-Yr Subscription Revenue | B17: =Conservative!I40 -> 7149 | C17: =Expected!I40 -> 41836 | D17: =Optimistic!I40 -> 246709
A18: 3-Yr Per-Case Revenue | B18: =Conservative!J40 -> 2345 | C18: =Expected!J40 -> 8425 | D18: =Optimistic!J40 -> 25610
A19: 3-Yr Referral Revenue | B19: =Conservative!K40 -> 20449 | C19: =Expected!K40 -> 74296 | D19: =Optimistic!K40 -> 227747
A20: 3-Yr YT AdSense | B20: =Conservative!L40 -> 1858 | C20: =Expected!L40 -> 1858 | D20: =Optimistic!L40 -> 1858
A21: 3-Yr Total Revenue | B21: =Conservative!M40 -> 31801 | C21: =Expected!M40 -> 126415 | D21: =Optimistic!M40 -> 501924
A22: 3-Yr Total Costs | B22: =Conservative!N40 -> 10243 | C22: =Expected!N40 -> 13007 | D22: =Optimistic!N40 -> 30011
A23: 3-Yr Gross Profit | B23: =Conservative!O40 -> 21558 | C23: =Expected!O40 -> 113408 | D23: =Optimistic!O40 -> 471913
A24: 3-Yr Owner's Draw | B24: =Conservative!P40 -> 10525 | C24: =Expected!P40 -> 56606 | D24: =Optimistic!P40 -> 235871
A26: KEY ASSUMPTIONS
A27: Paid Conversion Rate | B27: =Assumptions!B22 -> 0.0015 | C27: =Assumptions!B23 -> 0.0025 | D27: =Assumptions!B24 -> 0.005
A28: Y1 Traffic Growth | B28: =Assumptions!B34 -> 0.1 | C28: =Assumptions!B35 -> 0.14 | D28: =Assumptions!B36 -> 0.18
A29: Monthly Churn | B29: =Assumptions!B50 -> 0.08 | C29: =Assumptions!B51 -> 0.07 | D29: =Assumptions!B52 -> 0.06

Sheet Conservative
A1: CONSERVATIVE SCENARIO
A3: Month | B3: Organic SEO | C3: YT Visitors | D3: IG Visitors | E3: TOTAL Visitors | F3: New Paid Subs | G3: Churn | H3: Total Paid Subs | I3: MRR ($) | J3: Per-Case Rev ($) | K3: Referral Rev ($) | L3: YT AdSense ($) | M3: Total Revenue ($) | N3: Total Costs ($) | O3: Gross Profit ($) | P3: Owner's Draw ($) | Q3: Reserve ($)
A4: 1 | B4: =Assumptions!B30 -> 250 | C4: =ROUND(IF(A4<Assumptions!B100,0,IF(A4<=8,Assumptions!B103,IF(A4<=12,Assumptions!B104,IF(A4<=18,Assumptions!B105,IF(A4<=24,Assumptions!B106,Assumptions!B107))))*(1+IF(A4>=Assumptions!B101,Assumptions!B109,0))*Assumptions!B111),0) -> 0 | D4: =ROUND(Assumptions!B119*Assumptions!B123,0) -> 1 | E4: =B4+C4+D4 -> 251 | F4: =ROUND(E4*Assumptions!B22,0) -> 0 | G4: 0 | H4: =F4 -> 0 | I4: =ROUND(H4*Assumptions!B14,0) -> 0 | J4: =ROUND(E4*Assumptions!B95*Assumptions!B96*Assumptions!B97*Assumptions!B94,0) -> 10 | K4: 0 | L4: =ROUND(IF(A4<Assumptions!B113,0,IF(A4<=18,Assumptions!B105,Assumptions!B107)/1000*Assumptions!B115*0.55+IF(A4>=Assumptions!B114,IF(A4<=18,Assumptions!B105,Assumptions!B107)*Assumptions!B109/1000*Assumptions!B116*0.55,0)),0) -> 0 | M4: =I4+J4+K4+L4 -> 10 | N4: =ROUND(H4*Assumptions!B62*Assumptions!B61,0)+Assumptions!B63+IF(H4>Assumptions!B64,45,0)+Assumptions!B65+Assumptions!B66+Assumptions!B67+Assumptions!B68+Assumptions!B69/12+IF(A4>=3,Assumptions!B72,0)+ROUND(I4*Assumptions!B70+H4*Assumptions!B71,0)+Assumptions!B75+Assumptions!B76+Assumptions!B77 -> 3366 | O4: =M4-N4 -> -3356 | P4: =IF(O4<N4*Assumptions!B89,0,IF(O4<N4*6,ROUND(MAX(O4,0)*Assumptions!B90,0),ROUND(MAX(O4,0)*Assumptions!B91,0))) -> 0 | Q4: =O4-P4 -> -3356
A5: 2 | B5: =ROUND(B4*(1+Assumptions!B34),0) -> 275 | C5: =ROUND(IF(A5<Assumptions!B100,0,IF(A5<=8,Assumptions!B103,IF(A5<=12,Assumptions!B104,IF(A5<=18,Assumptions!B105,IF(A5<=24,Assumptions!B106,Assumptions!B107))))*(1+IF(A5>=Assumptions!B101,Assumptions!B109,0))*Assumptions!B111),0) -> 0 | D5: =ROUND(ROUND(Assumptions!B119*(1+Assumptions!B120)^(A5-1),0)*Assumptions!B123,0) -> 1 | E5: =B5+C5+D5 -> 276 | F5: =ROUND(E5*Assumptions!B22,0) -> 0 | G5: =ROUND(H4*Assumptions!B50,0) -> 0 | H5: =H4+F5-G5 -> 0 | I5: =ROUND(H5*Assumptions!B14,0) -> 0 | J5: =ROUND(E5*Assumptions!B95*Assumptions!B96*Assumptions!B97*Assumptions!B94,0) -> 11 | K5: 0 | L5: =ROUND(IF(A5<Assumptions!B113,0,IF(A5<=18,Assumptions!B105,Assumptions!B107)/1000*Assumptions!B115*0.55+IF(A5>=Assumptions!B114,IF(A5<=18,Assumptions!B105,Assumptions!B107)*Assumptions!B109/1000*Assumptions!B116*0.55,0)),0) -> 0 | M5: =I5+J5+K5+L5 -> 11 | N5: =ROUND(H5*Assumptions!B62*Assumptions!B61,0)+Assumptions!B63+IF(H5>Assumptions!B64,45,0)+Assumptions!B65+Assumptions!B66+Assumptions!B67+Assumptions!B68+Assumptions!B69/12+IF(A5>=3,Assumptions!B72,0)+ROUND(I5*Assumptions!B70+H5*Assumptions!B71,0)+0 -> 116 | O5: =M5-N5 -> -105 | P5: =IF((Q4+O5)<N5*Assumptions!B89,0,IF((Q4+O5)<N5*6,ROUND(MAX(O5,0)*Assumptions!B90,0),ROUND(MAX(O5,0)*Assumptions!B91,0))) -> 0 | Q5: =Q4+O5-P5 -> -3461
A6: 3 | B6: =ROUND(B5*(1+Assumptions!B34)*Assumptions!B46,0) -> 348 | C6: =ROUND(IF(A6<Assumptions!B100,0,IF(A6<=8,Assumptions!B103,IF(A6<=12,Assumptions!B104,IF(A6<=18,Assumptions!B105,IF(A6<=24,Assumptions!B106,Assumptions!B107))))*(1+IF(A6>=Assumptions!B101,Assumptions!B109,0))*Assumptions!B111),0) -> 10 | D6: =ROUND(ROUND(Assumptions!B119*(1+Assumptions!B120)^(A6-1),0)*Assumptions!B123,0) -> 1 | E6: =B6+C6+D6 -> 359 | F6: =ROUND(E6*Assumptions!B22,0) -> 1 | G6: =ROUND(H5*Assumptions!B50,0) -> 0 | H6: =H5+F6-G6 -> 1 | I6: =ROUND(H6*Assumptions!B14,0) -> 8 | J6: =ROUND(E6*Assumptions!B95*Assumptions!B96*Assumptions!B97*Assumptions!B94,0) -> 14 | K6: 0 | L6: =ROUND(IF(A6<Assumptions!B113,0,IF(A6<=18,Assumptions!B105,Assumptions!B107)/1000*Assumptions!B115*0.55+IF(A6>=Assumptions!B114,IF(A6<=18,Assumptions!B105,Assumptions!B107)*Assumptions!B109/1000*Assumptions!B116*0.55,0)),0) -> 0 | M6: =I6+J6+K6+L6 -> 22 | N6: =ROUND(H6*Assumptions!B62*Assumptions!B61,0)+Assumptions!B63+IF(H6>Assumptions!B64,45,0)+Assumptions!B65+Assumptions!B66+Assumptions!B67+Assumptions!B68+Assumptions!B69/12+IF(A6>=3,Assumptions!B72,0)+ROUND(I6*Assumptions!B70+H6*Assumptions!B71,0)+0 -> 183 | O6: =M6-N6 -> -161 | P6: =IF((Q5+O6)<N6*Assumptions!B89,0,IF((Q5+O6)<N6*6,ROUND(MAX(O6,0)*Assumptions!B90,0),ROUND(MAX(O6,0)*Assumptions!B91,0))) -> 0 | Q6: =Q5+O6-P6 -> -3622
A7: 4 | B7: =ROUND(B6*(1+Assumptions!B34),0) -> 383 | C7: =ROUND(IF(A7<Assumptions!B100,0,IF(A7<=8,Assumptions!B103,IF(A7<=12,Assumptions!B104,IF(A7<=18,Assumptions!B105,IF(A7<=24,Assumptions!B106,Assumptions!B107))))*(1+IF(A7>=Assumptions!B101,Assumptions!B109,0))*Assumptions!B111),0) -> 10 | D7: =ROUND(ROUND(Assumptions!B119*(1+Assumptions!B120)^(A7-1),0)*Assumptions!B123,0) -> 1 | E7: =B7+C7+D7 -> 394 | F7: =ROUND(E7*Assumptions!B22,0) -> 1 | G7: =ROUND(H6*Assumptions!B50,0) -> 0 | H7: =H6+F7-G7 -> 2 | I7: =ROUND(H7*Assumptions!B14,0) -> 16 | J7: =ROUND(E7*Assumptions!B95*Assumptions!B96*Assumptions!B97*Assumptions!B94,0) -> 15 | K7: 0 | L7: =ROUND(IF(A7<Assumptions!B113,0,IF(A7<=18,Assumptions!B105,Assumptions!B107)/1000*Assumptions!B115*0.55+IF(A7>=Assumptions!B114,IF(A7<=18,Assumptions!B105,Assumptions!B107)*Assumptions!B109/1000*Assumptions!B116*0.55,0)),0) -> 0 | M7: =I7+J7+K7+L7 -> 31 | N7: =ROUND(H7*Assumptions!B62*Assumptions!B61,0)+Assumptions!B63+IF(H7>Assumptions!B64,45,0)+Assumptions!B65+Assumptions!B66+Assumptions!B67+Assumptions!B68+Assumptions!B69/12+IF(A7>=3,Assumptions!B72,0)+ROUND(I7*Assumptions!B70+H7*Assumptions!B71,0)+0 -> 184 | O7: =M7-N7 -> -153 | P7: =IF((Q6+O7)<N7*Assumptions!B89,0,IF((Q6+O7)<N7*6,ROUND(MAX(O7,0)*Assumptions!B90,0),ROUND(MAX(O7,0)*Assumptions!B91,0))) -> 0 | Q7: =Q6+O7-P7 -> -3775
A8: 5 | B8: =ROUND(B7*(1+Assumptions!B34),0) -> 421 | C8: =ROUND(IF(A8<Assumptions!B100,0,IF(A8<=8,Assumptions!B103,IF(A8<=12,Assumptions!B104,IF(A8<=18,Assumptions!B105,IF(A8<=24,Assumptions!B106,Assumptions!B107))))*(1+IF(A8>=Assumptions!B101,Assumptions!B109,0))*Assumptions!B111),0) -> 10 | D8: =ROUND(ROUND(Assumptions!B119*(1+Assumptions!B120)^(A8-1),0)*Assumptions!B123,0) -> 2 | E8: =B8+C8+D8 -> 433 | F8: =ROUND(E8*Assumptions!B22,0) -> 1 | G8: =ROUND(H7*Assumptions!B50,0) -> 0 | H8: =H7+F8-G8 -> 3 | I8: =ROUND(H8*Assumptions!B14,0) -> 24 | J8: =ROUND(E8*Assumptions!B95*Assumptions!B96*Assumptions!B97*Assumptions!B94,0) -> 17 | K8: 0 | L8: =ROUND(IF(A8<Assumptions!B113,0,IF(A8<=18,Assumptions!B105,Assumptions!B107)/1000*Assumptions!B115*0.55+IF(A8>=Assumptions!B114,IF(A8<=18,Assumptions!B105,Assumptions!B107)*Assumptions!B109/1000*Assumptions!B116*0.55,0)),0) -> 0 | M8: =I8+J8+K8+L8 -> 41 | N8: =ROUND(H8*Assumptions!B62*Assumptions!B61,0)+Assumptions!B63+IF(H8>Assumptions!B64,45,0)+Assumptions!B65+Assumptions!B66+Assumptions!B67+Assumptions!B68+Assumptions!B69/12+IF(A8>=3,Assumptions!B72,0)+ROUND(I8*Assumptions!B70+H8*Assumptions!B71,0)+0 -> 185 | O8: =M8-N8 -> -144 | P8: =IF((Q7+O8)<N8*Assumptions!B89,0,IF((Q7+O8)<N8*6,ROUND(MAX(O8,0)*Assumptions!B90,0),ROUND(MAX(O8,0)*Assumptions!B91,0))) -> 0 | Q8: =Q7+O8-P8 -> -3919
A9: 6 | B9: =ROUND(B8*(1+Assumptions!B34)*Assumptions!B47,0) -> 500 | C9: =ROUND(IF(A9<Assumptions!B100,0,IF(A9<=8,Assumptions!B103,IF(A9<=12,Assumptions!B104,IF(A9<=18,Assumptions!B105,IF(A9<=24,Assumptions!B106,Assumptions!B107))))*(1+IF(A9>=Assumptions!B101,Assumptions!B109,0))*Assumptions!B111),0) -> 10 | D9: =ROUND(ROUND(Assumptions!B119*(1+Assumptions!B120)^(A9-1),0)*Assumptions!B123,0) -> 2 | E9: =B9+C9+D9 -> 512 | F9: =ROUND(E9*Assumptions!B22,0) -> 1 | G9: =ROUND(H8*Assumptions!B50,0) -> 0 | H9: =H8+F9-G9 -> 4 | I9: =ROUND(H9*Assumptions!B14,0) -> 32 | J9: =ROUND(E9*Assumptions!B95*Assumptions!B96*Assumptions!B97*Assumptions!B94,0) -> 20 | K9: =ROUND(E9*Assumptions!B57*Assumptions!B58,0) -> 179 | L9: =ROUND(IF(A9<Assumptions!B113,0,IF(A9<=18,Assumptions!B105,Assumptions!B107)/1000*Assumptions!B115*0.55+IF(A9>=Assumptions!B114,IF(A9<=18,Assumptions!B105,Assumptions!B107)*Assumptions!B109/1000*Assumptions!B116*0.55,0)),0) -> 0 | M9: =I9+J9+K9+L9 -> 231 | N9: =ROUND(H9*Assumptions!B62*Assumptions!B61,0)+Assumptions!B63+IF(H9>Assumptions!B64,45,0)+Assumptions!B65+Assumptions!B66+Assumptions!B67+Assumptions!B68+Assumptions!B69/12+IF(A9>=3,Assumptions!B72,0)+ROUND(I9*Assumptions!B70+H9*Assumptions!B71,0)+0 -> 185 | O9: =M9-N9 -> 46 | P9: =IF((Q8+O9)<N9*Assumptions!B89,0,IF((Q8+O9)<N9*6,ROUND(MAX(O9,0)*Assumptions!B90,0),ROUND(MAX(O9,0)*Assumptions!B91,0))) -> 0 | Q9: =Q8+O9-P9 -> -3873
A10: 7 | B10: =ROUND(B9*(1+Assumptions!B34),0) -> 550 | C10: =ROUND(IF(A10<Assumptions!B100,0,IF(A10<=8,Assumptions!B103,IF(A10<=12,Assumptions!B104,IF(A10<=18,Assumptions!B105,IF(A10<=24,Assumptions!B106,Assumptions!B107))))*(1+IF(A10>=Assumptions!B101,Assumptions!B109,0))*Assumptions!B111),0) -> 10 | D10: =ROUND(ROUND(Assumptions!B119*(1+Assumptions!B120)^6*(1+Assumptions!B121)^(A10-6),0)*Assumptions!B123,0) -> 3 | E10: =B10+C10+D10 -> 563 | F10: =ROUND(E10*Assumptions!B22,0) -> 1 | G10: =ROUND(H9*Assumptions!B50,0) -> 0 | H10: =H9+F10-G10 -> 5 | I10: =ROUND(H10*Assumptions!B14,0) -> 40 | J10: =ROUND(E10*Assumptions!B95*Assumptions!B96*Assumptions!B97*Assumptions!B94,0) -> 22 | K10: =ROUND(E10*Assumptions!B57*Assumptions!B58,0) -> 197 | L10: =ROUND(IF(A10<Assumptions!B113,0,IF(A10<=18,Assumptions!B105,Assumptions!B107)/1000*Assumptions!B115*0.55+IF(A10>=Assumptions!B114,IF(A10<=18,Assumptions!B105,Assumptions!B107)*Assumptions!B109/1000*Assumptions!B116*0.55,0)),0) -> 0 | M10: =I10+J10+K10+L10 -> 259 | N10: =ROUND(H10*Assumptions!B62*Assumptions!B61,0)+Assumptions!B63+IF(H10>Assumptions!B64,45,0)+Assumptions!B65+Assumptions!B66+Assumptions!B67+Assumptions!B68+Assumptions!B69/12+IF(A10>=3,Assumptions!B72,0)+ROUND(I10*Assumptions!B70+H10*Assumptions!B71,0)+0 -> 186 | O10: =M10-N10 -> 73 | P10: =IF((Q9+O10)<N10*Assumptions!B89,0,IF((Q9+O10)<N10*6,ROUND(MAX(O10,0)*Assumptions!B90,0),ROUND(MAX(O10,0)*Assumptions!B91,0))) -> 0 | Q10: =Q9+O10-P10 -> -3800
A11: 8 | B11: =ROUND(B10*(1+Assumptions!B34),0) -> 605 | C11: =ROUND(IF(A11<Assumptions!B100,0,IF(A11<=8,Assumptions!B103,IF(A11<=12,Assumptions!B104,IF(A11<=18,Assumptions!B105,IF(A11<=24,Assumptions!B106,Assumptions!B107))))*(1+IF(A11>=Assumptions!B101,Assumptions!B109,0))*Assumptions!B111),0) -> 10 | D11: =ROUND(ROUND(Assumptions!B119*(1+Assumptions!B120)^6*(1+Assumptions!B121)^(A11-6),0)*Assumptions!B123,0) -> 3 | E11: =B11+C11+D11 -> 618 | F11: =ROUND(E11*Assumptions!B22,0) -> 1 | G11: =ROUND(H10*Assumptions!B50,0) -> 0 | H11: =H10+F11-G11 -> 6 | I11: =ROUND(H11*Assumptions!B14,0) -> 48 | J11: =ROUND(E11*Assumptions!B95*Assumptions!B96*Assumptions!B97*Assumptions!B94,0) -> 24 | K11: =ROUND(E11*Assumptions!B57*Assumptions!B58,0) -> 216 | L11: =ROUND(IF(A11<Assumptions!B113,0,IF(A11<=18,Assumptions!B105,Assumptions!B107)/1000*Assumptions!B115*0.55+IF(A11>=Assumptions!B114,IF(A11<=18,Assumptions!B105,Assumptions!B107)*Assumptions!B109/1000*Assumptions!B116*0.55,0)),0) -> 0 | M11: =I11+J11+K11+L11 -> 288 | N11: =ROUND(H11*Assumptions!B62*Assumptions!B61,0)+Assumptions!B63+IF(H11>Assumptions!B64,45,0)+Assumptions!B65+Assumptions!B66+Assumptions!B67+Assumptions!B68+Assumptions!B69/12+IF(A11>=3,Assumptions!B72,0)+ROUND(I11*Assumptions!B70+H11*Assumptions!B71,0)+0 -> 187 | O11: =M11-N11 -> 101 | P11: =IF((Q10+O11)<N11*Assumptions!B89,0,IF((Q10+O11)<N11*6,ROUND(MAX(O11,0)*Assumptions!B90,0),ROUND(MAX(O11,0)*Assumptions!B91,0))) -> 0 | Q11: =Q10+O11-P11 -> -3699
A12: 9 | B12: =ROUND(B11*(1+Assumptions!B34),0) -> 666 | C12: =ROUND(IF(A12<Assumptions!B100,0,IF(A12<=8,Assumptions!B103,IF(A12<=12,Assumptions!B104,IF(A12<=18,Assumptions!B105,IF(A12<=24,Assumptions!B106,Assumptions!B107))))*(1+IF(A12>=Assumptions!B101,Assumptions!B109,0))*Assumptions!B111),0) -> 60 | D12: =ROUND(ROUND(Assumptions!B119*(1+Assumptions!B120)^6*(1+Assumptions!B121)^(A12-6),0)*Assumptions!B123,0) -> 3 | E12: =B12+C12+D12 -> 729 | F12: =ROUND(E12*Assumptions!B22,0) -> 1 | G12: =ROUND(H11*Assumptions!B50,0) -> 0 | H12: =H11+F12-G12 -> 7 | I12: =ROUND(H12*((Assumptions!B14+Assumptions!B15)/2),0) -> 74 | J12: =ROUND(E12*Assumptions!B95*Assumptions!B96*Assumptions!B97*Assumptions!B94,0) -> 28 | K12: =ROUND(E12*Assumptions!B57*Assumptions!B58,0) -> 255 | L12: =ROUND(IF(A12<Assumptions!B113,0,IF(A12<=18,Assumptions!B105,Assumptions!B107)/1000*Assumptions!B115*0.55+IF(A12>=Assumptions!B114,IF(A12<=18,Assumptions!B105,Assumptions!B107)*Assumptions!B109/1000*Assumptions!B116*0.55,0)),0) -> 0 | M12: =I12+J12+K12+L12 -> 357 | N12: =ROUND(H12*Assumptions!B62*Assumptions!B61,0)+Assumptions!B63+IF(H12>Assumptions!B64,45,0)+Assumptions!B65+Assumptions!B66+Assumptions!B67+Assumptions!B68+Assumptions!B69/12+IF(A12>=3,Assumptions!B72,0)+ROUND(I12*Assumptions!B70+H12*Assumptions!B71,0)+0 -> 188 | O12: =M12-N12 -> 169 | P12: =IF((Q11+O12)<N12*Assumptions!B89,0,IF((Q11+O12)<N12*6,ROUND(MAX(O12,0)*Assumptions!B90,0),ROUND(MAX(O12,0)*Assumptions!B91,0))) -> 0 | Q12: =Q11+O12-P12 -> -3530
A13: 10 | B13: =ROUND(B12*(1+Assumptions!B34),0) -> 733 | C13: =ROUND(IF(A13<Assumptions!B100,0,IF(A13<=8,Assumptions!B103,IF(A13<=12,Assumptions!B104,IF(A13<=18,Assumptions!B105,IF(A13<=24,Assumptions!B106,Assumptions!B107))))*(1+IF(A13>=Assumptions!B101,Assumptions!B109,0))*Assumptions!B111),0) -> 60 | D13: =ROUND(ROUND(Assumptions!B119*(1+Assumptions!B120)^6*(1+Assumptions!B121)^(A13-6),0)*Assumptions!B123,0) -> 4 | E13: =B13+C13+D13 -> 797 | F13: =ROUND(E13*Assumptions!B22,0) -> 1 | G13: =ROUND(H12*Assumptions!B50,0) -> 1 | H13: =H12+F13-G13 -> 7 | I13: =ROUND(H13*(Assumptions!B15*0.85+Assumptions!B11*0.15),0) -> 80 | J13: =ROUND(E13*Assumptions!B95*Assumptions!B96*Assumptions!B97*Assumptions!B94,0) -> 31 | K13: =ROUND(E13*Assumptions!B57*Assumptions!B58,0) -> 279 | L13: =ROUND(IF(A13<Assumptions!B113,0,IF(A13<=18,Assumptions!B105,Assumptions!B107)/1000*Assumptions!B115*0.55+IF(A13>=Assumptions!B114,IF(A13<=18,Assumptions!B105,Assumptions!B107)*Assumptions!B109/1000*Assumptions!B116*0.55,0)),0) -> 0 | M13: =I13+J13+K13+L13 -> 390 | N13: =ROUND(H13*Assumptions!B62*Assumptions!B61,0)+Assumptions!B63+IF(H13>Assumptions!B64,45,0)+Assumptions!B65+Assumptions!B66+Assumptions!B67+Assumptions!B68+Assumptions!B69/12+IF(A13>=3,Assumptions!B72,0)+ROUND(I13*Assumptions!B70+H13*Assumptions!B71,0)+0 -> 188 | O13: =M13-N13 -> 202 | P13: =IF((Q12+O13)<N13*Assumptions!B89,0,IF((Q12+O13)<N13*6,ROUND(MAX(O13,0)*Assumptions!B90,0),ROUND(MAX(O13,0)*Assumptions!B91,0))) -> 0 | Q13: =Q12+O13-P13 -> -3328
A14: 11 | B14: =ROUND(B13*(1+Assumptions!B34),0) -> 806 | C14: =ROUND(IF(A14<Assumptions!B100,0,IF(A14<=8,Assumptions!B103,IF(A14<=12,Assumptions!B104,IF(A14<=18,Assumptions!B105,IF(A14<=24,Assumptions!B106,Assumptions!B107))))*(1+IF(A14>=Assumptions!B101,Assumptions!B109,0))*Assumptions!B111),0) -> 60 | D14: =ROUND(ROUND(Assumptions!B119*(1+Assumptions!B120)^6*(1+Assumptions!B121)^(A14-6),0)*Assumptions!B123,0) -> 5 | E14: =B14+C14+D14 -> 871 | F14: =ROUND(E14*Assumptions!B22,0) -> 1 | G14: =ROUND(H13*Assumptions!B50,0) -> 1 | H14: =H13+F14-G14 -> 7 | I14: =ROUND(H14*(Assumptions!B15*0.85+Assumptions!B11*0.15),0) -> 80 | J14: =ROUND(E14*Assumptions!B95*Assumptions!B96*Assumptions!B97*Assumptions!B94,0) -> 34 | K14: =ROUND(E14*Assumptions!B57*Assumptions!B58,0) -> 305 | L14: =ROUND(IF(A14<Assumptions!B113,0,IF(A14<=18,Assumptions!B105,Assumptions!B107)/1000*Assumptions!B115*0.55+IF(A14>=Assumptions!B114,IF(A14<=18,Assumptions!B105,Assumptions!B107)*Assumptions!B109/1000*Assumptions!B116*0.55,0)),0) -> 0 | M14: =I14+J14+K14+L14 -> 419 | N14: =ROUND(H14*Assumptions!B62*Assumptions!B61,0)+Assumptions!B63+IF(H14>Assumptions!B64,45,0)+Assumptions!B65+Assumptions!B66+Assumptions!B67+Assumptions!B68+Assumptions!B69/12+IF(A14>=3,Assumptions!B72,0)+ROUND(I14*Assumptions!B70+H14*Assumptions!B71,0)+0 -> 188 | O14: =M14-N14 -> 231 | P14: =IF((Q13+O14)<N14*Assumptions!B89,0,IF((Q13+O14)<N14*6,ROUND(MAX(O14,0)*Assumptions!B90,0),ROUND(MAX(O14,0)*Assumptions!B91,0))) -> 0 | Q14: =Q13+O14-P14 -> -3097
A15: 12 | B15: =ROUND(B14*(1+Assumptions!B34),0) -> 887 | C15: =ROUND(IF(A15<Assumptions!B100,0,IF(A15<=8,Assumptions!B103,IF(A15<=12,Assumptions!B104,IF(A15<=18,Assumptions!B105,IF(A15<=24,Assumptions!B106,Assumptions!B107))))*(1+IF(A15>=Assumptions!B101,Assumptions!B109,0))*Assumptions!B111),0) -> 60 | D15: =ROUND(ROUND(Assumptions!B119*(1+Assumptions!B120)^6*(1+Assumptions!B121)^(A15-6),0)*Assumptions!B123,0) -> 5 | E15: =B15+C15+D15 -> 952 | F15: =ROUND(E15*Assumptions!B22,0) -> 1 | G15: =ROUND(H14*Assumptions!B50,0) -> 1 | H15: =H14+F15-G15 -> 7 | I15: =ROUND(H15*(Assumptions!B15*0.85+Assumptions!B11*0.15),0) -> 80 | J15: =ROUND(E15*Assumptions!B95*Assumptions!B96*Assumptions!B97*Assumptions!B94,0) -> 37 | K15: =ROUND(E15*Assumptions!B57*Assumptions!B58,0) -> 333 | L15: =ROUND(IF(A15<Assumptions!B113,0,IF(A15<=18,Assumptions!B105,Assumptions!B107)/1000*Assumptions!B115*0.55+IF(A15>=Assumptions!B114,IF(A15<=18,Assumptions!B105,Assumptions!B107)*Assumptions!B109/1000*Assumptions!B116*0.55,0)),0) -> 22 | M15: =I15+J15+K15+L15 -> 472 | N15: =ROUND(H15*Assumptions!B62*Assumptions!B61,0)+Assumptions!B63+IF(H15>Assumptions!B64,45,0)+Assumptions!B65+Assumptions!B66+Assumptions!B67+Assumptions!B68+Assumptions!B69/12+IF(A15>=3,Assumptions!B72,0)+ROUND(I15*Assumptions!B70+H15*Assumptions!B71,0)+0 -> 188 | O15: =M15-N15 -> 284 | P15: =IF((Q14+O15)<N15*Assumptions!B89,0,IF((Q14+O15)<N15*6,ROUND(MAX(O15,0)*Assumptions!B90,0),ROUND(MAX(O15,0)*Assumptions!B91,0))) -> 0 | Q15: =Q14+O15-P15 -> -2813
A16: 13 | B16: =ROUND(B15*(1+Assumptions!B38),0) -> 940 | C16: =ROUND(IF(A16<Assumptions!B100,0,IF(A16<=8,Assumptions!B103,IF(A16<=12,Assumptions!B104,IF(A16<=18,Assumptions!B105,IF(A16<=24,Assumptions!B106,Assumptions!B107))))*(1+IF(A16>=Assumptions!B101,Assumptions!B109,0))*Assumptions!B111),0) -> 150 | D16: =ROUND(ROUND(Assumptions!B119*(1+Assumptions!B120)^6*(1+Assumptions!B121)^6*(1+Assumptions!B122)^(A16-12),0)*Assumptions!B123,0) -> 6 | E16: =B16+C16+D16 -> 1096 | F16: =ROUND(E16*Assumptions!B22,0) -> 2 | G16: =ROUND(H15*Assumptions!B50,0) -> 1 | H16: =H15+F16-G16 -> 8 | I16: =ROUND(H16*(Assumptions!B15*0.85+Assumptions!B11*0.15),0) -> 92 | J16: =ROUND(E16*Assumptions!B95*Assumptions!B96*Assumptions!B97*Assumptions!B94,0) -> 43 | K16: =ROUND(E16*Assumptions!B57*Assumptions!B58,0) -> 384 | L16: =ROUND(IF(A16<Assumptions!B113,0,IF(A16<=18,Assumptions!B105,Assumptions!B107)/1000*Assumptions!B115*0.55+IF(A16>=Assumptions!B114,IF(A16<=18,Assumptions!B105,Assumptions!B107)*Assumptions!B109/1000*Assumptions!B116*0.55,0)),0) -> 22 | M16: =I16+J16+K16+L16 -> 541 | N16: =ROUND(H16*Assumptions!B62*Assumptions!B61,0)+Assumptions!B63+IF(H16>Assumptions!B64,45,0)+Assumptions!B65+Assumptions!B66+Assumptions!B67+Assumptions!B68+Assumptions!B69/12+IF(A16>=3,Assumptions!B72,0)+ROUND(I16*Assumptions!B70+H16*Assumptions!B71,0)+0 -> 189 | O16: =M16-N16 -> 352 | P16: =IF((Q15+O16)<N16*Assumptions!B89,0,IF((Q15+O16)<N16*6,ROUND(MAX(O16,0)*Assumptions!B90,0),ROUND(MAX(O16,0)*Assumptions!B91,0))) -> 0 | Q16: =Q15+O16-P16 -> -2461
A17: 14 | B17: =ROUND(B16*(1+Assumptions!B38),0) -> 996 | C17: =ROUND(IF(A17<Assumptions!B100,0,IF(A17<=8,Assumptions!B103,IF(A17<=12,Assumptions!B104,IF(A17<=18,Assumptions!B105,IF(A17<=24,Assumptions!B106,Assumptions!B107))))*(1+IF(A17>=Assumptions!B101,Assumptions!B109,0))*Assumptions!B111),0) -> 150 | D17: =ROUND(ROUND(Assumptions!B119*(1+Assumptions!B120)^6*(1+Assumptions!B121)^6*(1+Assumptions!B122)^(A17-12),0)*Assumptions!B123,0) -> 6 | E17: =B17+C17+D17 -> 1152 | F17: =ROUND(E17*Assumptions!B22,0) -> 2 | G17: =ROUND(H16*Assumptions!B50,0) -> 1 | H17: =H16+F17-G17 -> 9 | I17: =ROUND(H17*(Assumptions!B15*0.85+Assumptions!B11*0.15),0) -> 103 | J17: =ROUND(E17*Assumptions!B95*Assumptions!B96*Assumptions!B97*Assumptions!B94,0) -> 45 | K17: =ROUND(E17*Assumptions!B57*Assumptions!B58,0) -> 403 | L17: =ROUND(IF(A17<Assumptions!B113,0,IF(A17<=18,Assumptions!B105,Assumptions!B107)/1000*Assumptions!B115*0.55+IF(A17>=Assumptions!B114,IF(A17<=18,Assumptions!B105,Assumptions!B107)*Assumptions!B109/1000*Assumptions!B116*0.55,0)),0) -> 22 | M17: =I17+J17+K17+L17 -> 573 | N17: =ROUND(H17*Assumptions!B62*Assumptions!B61,0)+Assumptions!B63+IF(H17>Assumptions!B64,45,0)+Assumptions!B65+Assumptions!B66+Assumptions!B67+Assumptions!B68+Assumptions!B69/12+IF(A17>=3,Assumptions!B72,0)+ROUND(I17*Assumptions!B70+H17*Assumptions!B71,0)+0 -> 191 | O17: =M17-N17 -> 382 | P17: =IF((Q16+O17)<N17*Assumptions!B89,0,IF((Q16+O17)<N17*6,ROUND(MAX(O17,0)*Assumptions!B90,0),ROUND(MAX(O17,0)*Assumptions!B91,0))) -> 0 | Q17: =Q16+O17-P17 -> -2079
A18: 15 | B18: =ROUND(B17*(1+Assumptions!B38),0) -> 1056 | C18: =ROUND(IF(A18<Assumptions!B100,0,IF(A18<=8,Assumptions!B103,IF(A18<=12,Assumptions!B104,IF(A18<=18,Assumptions!B105,IF(A18<=24,Assumptions!B106,Assumptions!B107))))*(1+IF(A18>=Assumptions!B101,Assumptions!B109,0))*Assumptions!B111),0) -> 150 | D18: =ROUND(ROUND(Assumptions!B119*(1+Assumptions!B120)^6*(1+Assumptions!B121)^6*(1+Assumptions!B122)^(A18-12),0)*Assumptions!B123,0) -> 7 | E18: =B18+C18+D18 -> 1213 | F18: =ROUND(E18*Assumptions!B22,0) -> 2 | G18: =ROUND(H17*Assumptions!B50,0) -> 1 | H18: =H17+F18-G18 -> 10 | I18: =ROUND(H18*(Assumptions!B15*0.85+Assumptions!B11*0.15),0) -> 115 | J18: =ROUND(E18*Assumptions!B95*Assumptions!B96*Assumptions!B97*Assumptions!B94,0) -> 47 | K18: =ROUND(E18*Assumptions!B57*Assumptions!B58,0) -> 425 | L18: =ROUND(IF(A18<Assumptions!B113,0,IF(A18<=18,Assumptions!B105,Assumptions!B107)/1000*Assumptions!B115*0.55+IF(A18>=Assumptions!B114,IF(A18<=18,Assumptions!B105,Assumptions!B107)*Assumptions!B109/1000*Assumptions!B116*0.55,0)),0) -> 22 | M18: =I18+J18+K18+L18 -> 609 | N18: =ROUND(H18*Assumptions!B62*Assumptions!B61,0)+Assumptions!B63+IF(H18>Assumptions!B64,45,0)+Assumptions!B65+Assumptions!B66+Assumptions!B67+Assumptions!B68+Assumptions!B69/12+IF(A18>=3,Assumptions!B72,0)+ROUND(I18*Assumptions!B70+H18*Assumptions!B71,0)+0 -> 191 | O18: =M18-N18 -> 418 | P18: =IF((Q17+O18)<N18*Assumptions!B89,0,IF((Q17+O18)<N18*6,ROUND(MAX(O18,0)*Assumptions!B90,0),ROUND(MAX(O18,0)*Assumptions!B91,0))) -> 0 | Q18: =Q17+O18-P18 -> -1661
A19: 16 | B19: =ROUND(B18*(1+Assumptions!B38),0) -> 1119 | C19: =ROUND(IF(A19<Assumptions!B100,0,IF(A19<=8,Assumptions!B103,IF(A19<=12,Assumptions!B104,IF(A19<=18,Assumptions!B105,IF(A19<=24,Assumptions!B106,Assumptions!B107))))*(1+IF(A19>=Assumptions!B101,Assumptions!B109,0))*Assumptions!B111),0) -> 150 | D19: =ROUND(ROUND(Assumptions!B119*(1+Assumptions!B120)^6*(1+Assumptions!B121)^6*(1+Assumptions!B122)^(A19-12),0)*Assumptions!B123,0) -> 8 | E19: =B19+C19+D19 -> 1277 | F19: =ROUND(E19*Assumptions!B22,0) -> 2 | G19: =ROUND(H18*Assumptions!B50,0) -> 1 | H19: =H18+F19-G19 -> 11 | I19: =ROUND(H19*(Assumptions!B15*0.85+Assumptions!B11*0.15),0) -> 126 | J19: =ROUND(E19*Assumptions!B95*Assumptions!B96*Assumptions!B97*Assumptions!B94,0) -> 50 | K19: =ROUND(E19*Assumptions!B57*Assumptions!B58,0) -> 447 | L19: =ROUND(IF(A19<Assumptions!B113,0,IF(A19<=18,Assumptions!B105,Assumptions!B107)/1000*Assumptions!B115*0.55+IF(A19>=Assumptions!B114,IF(A19<=18,Assumptions!B105,Assumptions!B107)*Assumptions!B109/1000*Assumptions!B116*0.55,0)),0) -> 26 | M19: =I19+J19+K19+L19 -> 649 | N19: =ROUND(H19*Assumptions!B62*Assumptions!B61,0)+Assumptions!B63+IF(H19>Assumptions!B64,45,0)+Assumptions!B65+Assumptions!B66+Assumptions!B67+Assumptions!B68+Assumptions!B69/12+IF(A19>=3,Assumptions!B72,0)+ROUND(I19*Assumptions!B70+H19*Assumptions!B71,0)+0 -> 192 | O19: =M19-N19 -> 457 | P19: =IF((Q18+O19)<N19*Assumptions!B89,0,IF((Q18+O19)<N19*6,ROUND(MAX(O19,0)*Assumptions!B90,0),ROUND(MAX(O19,0)*Assumptions!B91,0))) -> 0 | Q19: =Q18+O19-P19 -> -1204
A20: 17 | B20: =ROUND(B19*(1+Assumptions!B38),0) -> 1186 | C20: =ROUND(IF(A20<Assumptions!B100,0,IF(A20<=8,Assumptions!B103,IF(A20<=12,Assumptions!B104,IF(A20<=18,Assumptions!B105,IF(A20<=24,Assumptions!B106,Assumptions!B107))))*(1+IF(A20>=Assumptions!B101,Assumptions!B109,0))*Assumptions!B111),0) -> 150 | D20: =ROUND(ROUND(Assumptions!B119*(1+Assumptions!B120)^6*(1+Assumptions!B121)^6*(1+Assumptions!B122)^(A20-12),0)*Assumptions!B123,0) -> 8 | E20: =B20+C20+D20 -> 1344 | F20: =ROUND(E20*Assumptions!B22,0) -> 2 | G20: =ROUND(H19*Assumptions!B50,0) -> 1 | H20: =H19+F20-G20 -> 12 | I20: =ROUND(H20*(Assumptions!B15*0.85+Assumptions!B11*0.15),0) -> 138 | J20: =ROUND(E20*Assumptions!B95*Assumptions!B96*Assumptions!B97*Assumptions!B94,0) -> 52 | K20: =ROUND(E20*Assumptions!B57*Assumptions!B58,0) -> 470 | L20: =ROUND(IF(A20<Assumptions!B113,0,IF(A20<=18,Assumptions!B105,Assumptions!B107)/1000*Assumptions!B115*0.55+IF(A20>=Assumptions!B114,IF(A20<=18,Assumptions!B105,Assumptions!B107)*Assumptions!B109/1000*Assumptions!B116*0.55,0)),0) -> 26 | M20: =I20+J20+K20+L20 -> 686 | N20: =ROUND(H20*Assumptions!B62*Assumptions!B61,0)+Assumptions!B63+IF(H20>Assumptions!B64,45,0)+Assumptions!B65+Assumptions!B66+Assumptions!B67+Assumptions!B68+Assumptions!B69/12+IF(A20>=3,Assumptions!B72,0)+ROUND(I20*Assumptions!B70+H20*Assumptions!B71,0)+0 -> 193 | O20: =M20-N20 -> 493 | P20: =IF((Q19+O20)<N20*Assumptions!B89,0,IF((Q19+O20)<N20*6,ROUND(MAX(O20,0)*Assumptions!B90,0),ROUND(MAX(O20,0)*Assumptions!B91,0))) -> 0 | Q20: =Q19+O20-P20 -> -711
A21: 18 | B21: =ROUND(B20*(1+Assumptions!B38),0) -> 1257 | C21: =ROUND(IF(A21<Assumptions!B100,0,IF(A21<=8,Assumptions!B103,IF(A21<=12,Assumptions!B104,IF(A21<=18,Assumptions!B105,IF(A21<=24,Assumptions!B106,Assumptions!B107))))*(1+IF(A21>=Assumptions!B101,Assumptions!B109,0))*Assumptions!B111),0) -> 150 | D21: =ROUND(ROUND(Assumptions!B119*(1+Assumptions!B120)^6*(1+Assumptions!B121)^6*(1+Assumptions!B122)^(A21-12),0)*Assumptions!B123,0) -> 9 | E21: =B21+C21+D21 -> 1416 | F21: =ROUND(E21*Assumptions!B22,0) -> 2 | G21: =ROUND(H20*Assumptions!B50,0) -> 1 | H21: =H20+F21-G21 -> 13 | I21: =ROUND(H21*(Assumptions!B15*0.85+Assumptions!B11*0.15),0) -> 149 | J21: =ROUND(E21*Assumptions!B95*Assumptions!B96*Assumptions!B97*Assumptions!B94,0) -> 55 | K21: =ROUND(E21*Assumptions!B57*Assumptions!B58,0) -> 496 | L21: =ROUND(IF(A21<Assumptions!B113,0,IF(A21<=18,Assumptions!B105,Assumptions!B107)/1000*Assumptions!B115*0.55+IF(A21>=Assumptions!B114,IF(A21<=18,Assumptions!B105,Assumptions!B107)*Assumptions!B109/1000*Assumptions!B116*0.55,0)),0) -> 26 | M21: =I21+J21+K21+L21 -> 726 | N21: =ROUND(H21*Assumptions!B62*Assumptions!B61,0)+Assumptions!B63+IF(H21>Assumptions!B64,45,0)+Assumptions!B65+Assumptions!B66+Assumptions!B67+Assumptions!B68+Assumptions!B69/12+IF(A21>=3,Assumptions!B72,0)+ROUND(I21*Assumptions!B70+H21*Assumptions!B71,0)+0 -> 194 | O21: =M21-N21 -> 532 | P21: =IF((Q20+O21)<N21*Assumptions!B89,0,IF((Q20+O21)<N21*6,ROUND(MAX(O21,0)*Assumptions!B90,0),ROUND(MAX(O21,0)*Assumptions!B91,0))) -> 0 | Q21: =Q20+O21-P21 -> -179
A22: 19 | B22: =ROUND(B21*(1+Assumptions!B38),0) -> 1332 | C22: =ROUND(IF(A22<Assumptions!B100,0,IF(A22<=8,Assumptions!B103,IF(A22<=12,Assumptions!B104,IF(A22<=18,Assumptions!B105,IF(A22<=24,Assumptions!B106,Assumptions!B107))))*(1+IF(A22>=Assumptions!B101,Assumptions!B109,0))*Assumptions!B111),0) -> 300 | D22: =ROUND(ROUND(Assumptions!B119*(1+Assumptions!B120)^6*(1+Assumptions!B121)^6*(1+Assumptions!B122)^(A22-12),0)*Assumptions!B123,0) -> 10 | E22: =B22+C22+D22 -> 1642 | F22: =ROUND(E22*Assumptions!B22,0) -> 2 | G22: =ROUND(H21*Assumptions!B50,0) -> 1 | H22: =H21+F22-G22 -> 14 | I22: =ROUND(H22*(Assumptions!B15*0.85+Assumptions!B11*0.15),0) -> 161 | J22: =ROUND(E22*Assumptions!B95*Assumptions!B96*Assumptions!B97*Assumptions!B94,0) -> 64 | K22: =ROUND(E22*Assumptions!B57*Assumptions!B58,0) -> 575 | L22: =ROUND(IF(A22<Assumptions!B113,0,IF(A22<=18,Assumptions!B105,Assumptions!B107)/1000*Assumptions!B115*0.55+IF(A22>=Assumptions!B114,IF(A22<=18,Assumptions!B105,Assumptions!B107)*Assumptions!B109/1000*Assumptions!B116*0.55,0)),0) -> 94 | M22: =I22+J22+K22+L22 -> 894 | N22: =ROUND(H22*Assumptions!B62*Assumptions!B61,0)+Assumptions!B63+IF(H22>Assumptions!B64,45,0)+Assumptions!B65+Assumptions!B66+Assumptions!B67+Assumptions!B68+Assumptions!B69/12+IF(A22>=3,Assumptions!B72,0)+ROUND(I22*Assumptions!B70+H22*Assumptions!B71,0)+0 -> 195 | O22: =M22-N22 -> 699 | P22: =IF((Q21+O22)<N22*Assumptions!B89,0,IF((Q21+O22)<N22*6,ROUND(MAX(O22,0)*Assumptions!B90,0),ROUND(MAX(O22,0)*Assumptions!B91,0))) -> 0 | Q22: =Q21+O22-P22 -> 520
A23: 20 | B23: =ROUND(B22*(1+Assumptions!B38),0) -> 1412 | C23: =ROUND(IF(A23<Assumptions!B100,0,IF(A23<=8,Assumptions!B103,IF(A23<=12,Assumptions!B104,IF(A23<=18,Assumptions!B105,IF(A23<=24,Assumptions!B106,Assumptions!B107))))*(1+IF(A23>=Assumptions!B101,Assumptions!B109,0))*Assumptions!B111),0) -> 300 | D23: =ROUND(ROUND(Assumptions!B119*(1+Assumptions!B120)^6*(1+Assumptions!B121)^6*(1+Assumptions!B122)^(A23-12),0)*Assumptions!B123,0) -> 11 | E23: =B23+C23+D23 -> 1723 | F23: =ROUND(E23*Assumptions!B22,0) -> 3 | G23: =ROUND(H22*Assumptions!B50,0) -> 1 | H23: =H22+F23-G23 -> 16 | I23: =ROUND(H23*(Assumptions!B15*0.85+Assumptions!B11*0.15),0) -> 184 | J23: =ROUND(E23*Assumptions!B95*Assumptions!B96*Assumptions!B97*Assumptions!B94,0) -> 67 | K23: =ROUND(E23*Assumptions!B57*Assumptions!B58,0) -> 603 | L23: =ROUND(IF(A23<Assumptions!B113,0,IF(A23<=18,Assumptions!B105,Assumptions!B107)/1000*Assumptions!B115*0.55+IF(A23>=Assumptions!B114,IF(A23<=18,Assumptions!B105,Assumptions!B107)*Assumptions!B109/1000*Assumptions!B116*0.55,0)),0) -> 94 | M23: =I23+J23+K23+L23 -> 948 | N23: =ROUND(H23*Assumptions!B62*Assumptions!B61,0)+Assumptions!B63+IF(H23>Assumptions!B64,45,0)+Assumptions!B65+Assumptions!B66+Assumptions!B67+Assumptions!B68+Assumptions!B69/12+IF(A23>=3,Assumptions!B72,0)+ROUND(I23*Assumptions!B70+H23*Assumptions!B71,0)+0 -> 196 | O23: =M23-N23 -> 752 | P23: =IF((Q22+O23)<N23*Assumptions!B89,0,IF((Q22+O23)<N23*6,ROUND(MAX(O23,0)*Assumptions!B90,0),ROUND(MAX(O23,0)*Assumptions!B91,0))) -> 376 | Q23: =Q22+O23-P23 -> 896
A24: 21 | B24: =ROUND(B23*(1+Assumptions!B38),0) -> 1497 | C24: =ROUND(IF(A24<Assumptions!B100,0,IF(A24<=8,Assumptions!B103,IF(A24<=12,Assumptions!B104,IF(A24<=18,Assumptions!B105,IF(A24<=24,Assumptions!B106,Assumptions!B107))))*(1+IF(A24>=Assumptions!B101,Assumptions!B109,0))*Assumptions!B111),0) -> 300 | D24: =ROUND(ROUND(Assumptions!B119*(1+Assumptions!B120)^6*(1+Assumptions!B121)^6*(1+Assumptions!B122)^(A24-12),0)*Assumptions!B123,0) -> 12 | E24: =B24+C24+D24 -> 1809 | F24: =ROUND(E24*Assumptions!B22,0) -> 3 | G24: =ROUND(H23*Assumptions!B50,0) -> 1 | H24: =H23+F24-G24 -> 18 | I24: =ROUND(H24*(Assumptions!B15*0.85+Assumptions!B11*0.15),0) -> 207 | J24: =ROUND(E24*Assumptions!B95*Assumptions!B96*Assumptions!B97*Assumptions!B94,0) -> 71 | K24: =ROUND(E24*Assumptions!B57*Assumptions!B58,0) -> 633 | L24: =ROUND(IF(A24<Assumptions!B113,0,IF(A24<=18,Assumptions!B105,Assumptions!B107)/1000*Assumptions!B115*0.55+IF(A24>=Assumptions!B114,IF(A24<=18,Assumptions!B105,Assumptions!B107)*Assumptions!B109/1000*Assumptions!B116*0.55,0)),0) -> 94 | M24: =I24+J24+K24+L24 -> 1005 | N24: =ROUND(H24*Assumptions!B62*Assumptions!B61,0)+Assumptions!B63+IF(H24>Assumptions!B64,45,0)+Assumptions!B65+Assumptions!B66+Assumptions!B67+Assumptions!B68+Assumptions!B69/12+IF(A24>=3,Assumptions!B72,0)+ROUND(I24*Assumptions!B70+H24*Assumptions!B71,0)+0 -> 198 | O24: =M24-N24 -> 807 | P24: =IF((Q23+O24)<N24*Assumptions!B89,0,IF((Q23+O24)<N24*6,ROUND(MAX(O24,0)*Assumptions!B90,0),ROUND(MAX(O24,0)*Assumptions!B91,0))) -> 404 | Q24: =Q23+O24-P24 -> 1299
A25: 22 | B25: =ROUND(B24*(1+Assumptions!B38),0) -> 1587 | C25: =ROUND(IF(A25<Assumptions!B100,0,IF(A25<=8,Assumptions!B103,IF(A25<=12,Assumptions!B104,IF(A25<=18,Assumptions!B105,IF(A25<=24,Assumptions!B106,Assumptions!B107))))*(1+IF(A25>=Assumptions!B101,Assumptions!B109,0))*Assumptions!B111),0) -> 300 | D25: =ROUND(ROUND(Assumptions!B119*(1+Assumptions!B120)^6*(1+Assumptions!B121)^6*(1+Assumptions!B122)^(A25-12),0)*Assumptions!B123,0) -> 13 | E25: =B25+C25+D25 -> 1900 | F25: =ROUND(E25*Assumptions!B22,0) -> 3 | G25: =ROUND(H24*Assumptions!B50,0) -> 1 | H25: =H24+F25-G25 -> 20 | I25: =ROUND(H25*(Assumptions!B15*0.85+Assumptions!B11*0.15),0) -> 230 | J25: =ROUND(E25*Assumptions!B95*Assumptions!B96*Assumptions!B97*Assumptions!B94,0) -> 74 | K25: =ROUND(E25*Assumptions!B57*Assumptions!B58,0) -> 665 | L25: =ROUND(IF(A25<Assumptions!B113,0,IF(A25<=18,Assumptions!B105,Assumptions!B107)/1000*Assumptions!B115*0.55+IF(A25>=Assumptions!B114,IF(A25<=18,Assumptions!B105,Assumptions!B107)*Assumptions!B109/1000*Assumptions!B116*0.55,0)),0) -> 94 | M25: =I25+J25+K25+L25 -> 1063 | N25: =ROUND(H25*Assumptions!B62*Assumptions!B61,0)+Assumptions!B63+IF(H25>Assumptions!B64,45,0)+Assumptions!B65+Assumptions!B66+Assumptions!B67+Assumptions!B68+Assumptions!B69/12+IF(A25>=3,Assumptions!B72,0)+ROUND(I25*Assumptions!B70+H25*Assumptions!B71,0)+0 -> 201 | O25: =M25-N25 -> 862 | P25: =IF((Q24+O25)<N25*Assumptions!B89,0,IF((Q24+O25)<N25*6,ROUND(MAX(O25,0)*Assumptions!B90,0),ROUND(MAX(O25,0)*Assumptions!B91,0))) -> 431 | Q25: =Q24+O25-P25 -> 1730
A26: 23 | B26: =ROUND(B25*(1+Assumptions!B38),0) -> 1682 | C26: =ROUND(IF(A26<Assumptions!B100,0,IF(A26<=8,Assumptions!B103,IF(A26<=12,Assumptions!B104,IF(A26<=18,Assumptions!B105,IF(A26<=24,Assumptions!B106,Assumptions!B107))))*(1+IF(A26>=Assumptions!B101,Assumptions!B109,0))*Assumptions!B111),0) -> 300 | D26: =ROUND(ROUND(Assumptions!B119*(1+Assumptions!B120)^6*(1+Assumptions!B121)^6*(1+Assumptions!B122)^(A26-12),0)*Assumptions!B123,0) -> 15 | E26: =B26+C26+D26 -> 1997 | F26: =ROUND(E26*Assumptions!B22,0) -> 3 | G26: =ROUND(H25*Assumptions!B50,0) -> 2 | H26: =H25+F26-G26 -> 21 | I26: =ROUND(H26*(Assumptions!B15*0.85+Assumptions!B11*0.15),0) -> 241 | J26: =ROUND(E26*Assumptions!B95*Assumptions!B96*Assumptions!B97*Assumptions!B94,0) -> 78 | K26: =ROUND(E26*Assumptions!B57*Assumptions!B58,0) -> 699 | L26: =ROUND(IF(A26<Assumptions!B113,0,IF(A26<=18,Assumptions!B105,Assumptions!B107)/1000*Assumptions!B115*0.55+IF(A26>=Assumptions!B114,IF(A26<=18,Assumptions!B105,Assumptions!B107)*Assumptions!B109/1000*Assumptions!B116*0.55,0)),0) -> 94 | M26: =I26+J26+K26+L26 -> 1112 | N26: =ROUND(H26*Assumptions!B62*Assumptions!B61,0)+Assumptions!B63+IF(H26>Assumptions!B64,45,0)+Assumptions!B65+Assumptions!B66+Assumptions!B67+Assumptions!B68+Assumptions!B69/12+IF(A26>=3,Assumptions!B72,0)+ROUND(I26*Assumptions!B70+H26*Assumptions!B71,0)+0 -> 201 | O26: =M26-N26 -> 911 | P26: =IF((Q25+O26)<N26*Assumptions!B89,0,IF((Q25+O26)<N26*6,ROUND(MAX(O26,0)*Assumptions!B90,0),ROUND(MAX(O26,0)*Assumptions!B91,0))) -> 456 | Q26: =Q25+O26-P26 -> 2185
A27: 24 | B27: =ROUND(B26*(1+Assumptions!B38),0) -> 1783 | C27: =ROUND(IF(A27<Assumptions!B100,0,IF(A27<=8,Assumptions!B103,IF(A27<=12,Assumptions!B104,IF(A27<=18,Assumptions!B105,IF(A27<=24,Assumptions!B106,Assumptions!B107))))*(1+IF(A27>=Assumptions!B101,Assumptions!B109,0))*Assumptions!B111),0) -> 300 | D27: =ROUND(ROUND(Assumptions!B119*(1+Assumptions!B120)^6*(1+Assumptions!B121)^6*(1+Assumptions!B122)^(A27-12),0)*Assumptions!B123,0) -> 16 | E27: =B27+C27+D27 -> 2099 | F27: =ROUND(E27*Assumptions!B22,0) -> 3 | G27: =ROUND(H26*Assumptions!B50,0) -> 2 | H27: =H26+F27-G27 -> 22 | I27: =ROUND(H27*(Assumptions!B15*0.85+Assumptions!B11*0.15),0) -> 252 | J27: =ROUND(E27*Assumptions!B95*Assumptions!B96*Assumptions!B97*Assumptions!B94,0) -> 82 | K27: =ROUND(E27*Assumptions!B57*Assumptions!B58,0) -> 735 | L27: =ROUND(IF(A27<Assumptions!B113,0,IF(A27<=18,Assumptions!B105,Assumptions!B107)/1000*Assumptions!B115*0.55+IF(A27>=Assumptions!B114,IF(A27<=18,Assumptions!B105,Assumptions!B107)*Assumptions!B109/1000*Assumptions!B116*0.55,0)),0) -> 94 | M27: =I27+J27+K27+L27 -> 1163 | N27: =ROUND(H27*Assumptions!B62*Assumptions!B61,0)+Assumptions!B63+IF(H27>Assumptions!B64,45,0)+Assumptions!B65+Assumptions!B66+Assumptions!B67+Assumptions!B68+Assumptions!B69/12+IF(A27>=3,Assumptions!B72,0)+ROUND(I27*Assumptions!B70+H27*Assumptions!B71,0)+0 -> 202 | O27: =M27-N27 -> 961 | P27: =IF((Q26+O27)<N27*Assumptions!B89,0,IF((Q26+O27)<N27*6,ROUND(MAX(O27,0)*Assumptions!B90,0),ROUND(MAX(O27,0)*Assumptions!B91,0))) -> 481 | Q27: =Q26+O27-P27 -> 2665
A28: 25 | B28: =ROUND(B27*(1+Assumptions!B42),0) -> 1854 | C28: =ROUND(IF(A28<Assumptions!B100,0,IF(A28<=8,Assumptions!B103,IF(A28<=12,Assumptions!B104,IF(A28<=18,Assumptions!B105,IF(A28<=24,Assumptions!B106,Assumptions!B107))))*(1+IF(A28>=Assumptions!B101,Assumptions!B109,0))*Assumptions!B111),0) -> 540 | D28: =ROUND(ROUND(Assumptions!B119*(1+Assumptions!B120)^6*(1+Assumptions!B121)^6*(1+Assumptions!B122)^(A28-12),0)*Assumptions!B123,0) -> 18 | E28: =B28+C28+D28 -> 2412 | F28: =ROUND(E28*Assumptions!B22,0) -> 4 | G28: =ROUND(H27*Assumptions!B50,0) -> 2 | H28: =H27+F28-G28 -> 24 | I28: =ROUND(H28*(Assumptions!B15*0.85+Assumptions!B11*0.15),0) -> 275 | J28: =ROUND(E28*Assumptions!B95*Assumptions!B96*Assumptions!B97*Assumptions!B94,0) -> 94 | K28: =ROUND(E28*Assumptions!B57*Assumptions!B58,0) -> 844 | L28: =ROUND(IF(A28<Assumptions!B113,0,IF(A28<=18,Assumptions!B105,Assumptions!B107)/1000*Assumptions!B115*0.55+IF(A28>=Assumptions!B114,IF(A28<=18,Assumptions!B105,Assumptions!B107)*Assumptions!B109/1000*Assumptions!B116*0.55,0)),0) -> 94 | M28: =I28+J28+K28+L28 -> 1307 | N28: =ROUND(H28*Assumptions!B62*Assumptions!B61,0)+Assumptions!B63+IF(H28>Assumptions!B64,45,0)+Assumptions!B65+Assumptions!B66+Assumptions!B67+Assumptions!B68+Assumptions!B69/12+IF(A28>=3,Assumptions!B72,0)+ROUND(I28*Assumptions!B70+H28*Assumptions!B71,0)+0 -> 204 | O28: =M28-N28 -> 1103 | P28: =IF((Q27+O28)<N28*Assumptions!B89,0,IF((Q27+O28)<N28*6,ROUND(MAX(O28,0)*Assumptions!B90,0),ROUND(MAX(O28,0)*Assumptions!B91,0))) -> 552 | Q28: =Q27+O28-P28 -> 3216
A29: 26 | B29: =ROUND(B28*(1+Assumptions!B42),0) -> 1928 | C29: =ROUND(IF(A29<Assumptions!B100,0,IF(A29<=8,Assumptions!B103,IF(A29<=12,Assumptions!B104,IF(A29<=18,Assumptions!B105,IF(A29<=24,Assumptions!B106,Assumptions!B107))))*(1+IF(A29>=Assumptions!B101,Assumptions!B109,0))*Assumptions!B111),0) -> 540 | D29: =ROUND(ROUND(Assumptions!B119*(1+Assumptions!B120)^6*(1+Assumptions!B121)^6*(1+Assumptions!B122)^(A29-12),0)*Assumptions!B123,0) -> 20 | E29: =B29+C29+D29 -> 2488 | F29: =ROUND(E29*Assumptions!B22,0) -> 4 | G29: =ROUND(H28*Assumptions!B50,0) -> 2 | H29: =H28+F29-G29 -> 26 | I29: =ROUND(H29*(Assumptions!B15*0.85+Assumptions!B11*0.15),0) -> 298 | J29: =ROUND(E29*Assumptions!B95*Assumptions!B96*Assumptions!B97*Assumptions!B94,0) -> 97 | K29: =ROUND(E29*Assumptions!B57*Assumptions!B58,0) -> 871 | L29: =ROUND(IF(A29<Assumptions!B113,0,IF(A29<=18,Assumptions!B105,Assumptions!B107)/1000*Assumptions!B115*0.55+IF(A29>=Assumptions!B114,IF(A29<=18,Assumptions!B105,Assumptions!B107)*Assumptions!B109/1000*Assumptions!B116*0.55,0)),0) -> 94 | M29: =I29+J29+K29+L29 -> 1360 | N29: =ROUND(H29*Assumptions!B62*Assumptions!B61,0)+Assumptions!B63+IF(H29>Assumptions!B64,45,0)+Assumptions!B65+Assumptions!B66+Assumptions!B67+Assumptions!B68+Assumptions!B69/12+IF(A29>=3,Assumptions!B72,0)+ROUND(I29*Assumptions!B70+H29*Assumptions!B71,0)+0 -> 205 | O29: =M29-N29 -> 1155 | P29: =IF((Q28+O29)<N29*Assumptions!B89,0,IF((Q28+O29)<N29*6,ROUND(MAX(O29,0)*Assumptions!B90,0),ROUND(MAX(O29,0)*Assumptions!B91,0))) -> 578 | Q29: =Q28+O29-P29 -> 3793
A30: 27 | B30: =ROUND(B29*(1+Assumptions!B42),0) -> 2005 | C30: =ROUND(IF(A30<Assumptions!B100,0,IF(A30<=8,Assumptions!B103,IF(A30<=12,Assumptions!B104,IF(A30<=18,Assumptions!B105,IF(A30<=24,Assumptions!B106,Assumptions!B107))))*(1+IF(A30>=Assumptions!B101,Assumptions!B109,0))*Assumptions!B111),0) -> 540 | D30: =ROUND(ROUND(Assumptions!B119*(1+Assumptions!B120)^6*(1+Assumptions!B121)^6*(1+Assumptions!B122)^(A30-12),0)*Assumptions!B123,0) -> 22 | E30: =B30+C30+D30 -> 2567 | F30: =ROUND(E30*Assumptions!B22,0) -> 4 | G30: =ROUND(H29*Assumptions!B50,0) -> 2 | H30: =H29+F30-G30 -> 28 | I30: =ROUND(H30*(Assumptions!B15*0.85+Assumptions!B11*0.15),0) -> 321 | J30: =ROUND(E30*Assumptions!B95*Assumptions!B96*Assumptions!B97*Assumptions!B94,0) -> 100 | K30: =ROUND(E30*Assumptions!B57*Assumptions!B58,0) -> 898 | L30: =ROUND(IF(A30<Assumptions!B113,0,IF(A30<=18,Assumptions!B105,Assumptions!B107)/1000*Assumptions!B115*0.55+IF(A30>=Assumptions!B114,IF(A30<=18,Assumptions!B105,Assumptions!B107)*Assumptions!B109/1000*Assumptions!B116*0.55,0)),0) -> 94 | M30: =I30+J30+K30+L30 -> 1413 | N30: =ROUND(H30*Assumptions!B62*Assumptions!B61,0)+Assumptions!B63+IF(H30>Assumptions!B64,45,0)+Assumptions!B65+Assumptions!B66+Assumptions!B67+Assumptions!B68+Assumptions!B69/12+IF(A30>=3,Assumptions!B72,0)+ROUND(I30*Assumptions!B70+H30*Assumptions!B71,0)+0 -> 208 | O30: =M30-N30 -> 1205 | P30: =IF((Q29+O30)<N30*Assumptions!B89,0,IF((Q29+O30)<N30*6,ROUND(MAX(O30,0)*Assumptions!B90,0),ROUND(MAX(O30,0)*Assumptions!B91,0))) -> 603 | Q30: =Q29+O30-P30 -> 4395
A31: 28 | B31: =ROUND(B30*(1+Assumptions!B42),0) -> 2085 | C31: =ROUND(IF(A31<Assumptions!B100,0,IF(A31<=8,Assumptions!B103,IF(A31<=12,Assumptions!B104,IF(A31<=18,Assumptions!B105,IF(A31<=24,Assumptions!B106,Assumptions!B107))))*(1+IF(A31>=Assumptions!B101,Assumptions!B109,0))*Assumptions!B111),0) -> 540 | D31: =ROUND(ROUND(Assumptions!B119*(1+Assumptions!B120)^6*(1+Assumptions!B121)^6*(1+Assumptions!B122)^(A31-12),0)*Assumptions!B123,0) -> 24 | E31: =B31+C31+D31 -> 2649 | F31: =ROUND(E31*Assumptions!B22,0) -> 4 | G31: =ROUND(H30*Assumptions!B50,0) -> 2 | H31: =H30+F31-G31 -> 30 | I31: =ROUND(H31*(Assumptions!B15*0.85+Assumptions!B11*0.15),0) -> 344 | J31: =ROUND(E31*Assumptions!B95*Assumptions!B96*Assumptions!B97*Assumptions!B94,0) -> 103 | K31: =ROUND(E31*Assumptions!B57*Assumptions!B58,0) -> 927 | L31: =ROUND(IF(A31<Assumptions!B113,0,IF(A31<=18,Assumptions!B105,Assumptions!B107)/1000*Assumptions!B115*0.55+IF(A31>=Assumptions!B114,IF(A31<=18,Assumptions!B105,Assumptions!B107)*Assumptions!B109/1000*Assumptions!B116*0.55,0)),0) -> 94 | M31: =I31+J31+K31+L31 -> 1468 | N31: =ROUND(H31*Assumptions!B62*Assumptions!B61,0)+Assumptions!B63+IF(H31>Assumptions!B64,45,0)+Assumptions!B65+Assumptions!B66+Assumptions!B67+Assumptions!B68+Assumptions!B69/12+IF(A31>=3,Assumptions!B72,0)+ROUND(I31*Assumptions!B70+H31*Assumptions!B71,0)+0 -> 209 | O31: =M31-N31 -> 1259 | P31: =IF((Q30+O31)<N31*Assumptions!B89,0,IF((Q30+O31)<N31*6,ROUND(MAX(O31,0)*Assumptions!B90,0),ROUND(MAX(O31,0)*Assumptions!B91,0))) -> 630 | Q31: =Q30+O31-P31 -> 5024
A32: 29 | B32: =ROUND(B31*(1+Assumptions!B42),0) -> 2168 | C32: =ROUND(IF(A32<Assumptions!B100,0,IF(A32<=8,Assumptions!B103,IF(A32<=12,Assumptions!B104,IF(A32<=18,Assumptions!B105,IF(A32<=24,Assumptions!B106,Assumptions!B107))))*(1+IF(A32>=Assumptions!B101,Assumptions!B109,0))*Assumptions!B111),0) -> 540 | D32: =ROUND(ROUND(Assumptions!B119*(1+Assumptions!B120)^6*(1+Assumptions!B121)^6*(1+Assumptions!B122)^(A32-12),0)*Assumptions!B123,0) -> 26 | E32: =B32+C32+D32 -> 2734 | F32: =ROUND(E32*Assumptions!B22,0) -> 4 | G32: =ROUND(H31*Assumptions!B50,0) -> 2 | H32: =H31+F32-G32 -> 32 | I32: =ROUND(H32*(Assumptions!B15*0.85+Assumptions!B11*0.15),0) -> 367 | J32: =ROUND(E32*Assumptions!B95*Assumptions!B96*Assumptions!B97*Assumptions!B94,0) -> 107 | K32: =ROUND(E32*Assumptions!B57*Assumptions!B58,0) -> 957 | L32: =ROUND(IF(A32<Assumptions!B113,0,IF(A32<=18,Assumptions!B105,Assumptions!B107)/1000*Assumptions!B115*0.55+IF(A32>=Assumptions!B114,IF(A32<=18,Assumptions!B105,Assumptions!B107)*Assumptions!B109/1000*Assumptions!B116*0.55,0)),0) -> 94 | M32: =I32+J32+K32+L32 -> 1525 | N32: =ROUND(H32*Assumptions!B62*Assumptions!B61,0)+Assumptions!B63+IF(H32>Assumptions!B64,45,0)+Assumptions!B65+Assumptions!B66+Assumptions!B67+Assumptions!B68+Assumptions!B69/12+IF(A32>=3,Assumptions!B72,0)+ROUND(I32*Assumptions!B70+H32*Assumptions!B71,0)+0 -> 211 | O32: =M32-N32 -> 1314 | P32: =IF((Q31+O32)<N32*Assumptions!B89,0,IF((Q31+O32)<N32*6,ROUND(MAX(O32,0)*Assumptions!B90,0),ROUND(MAX(O32,0)*Assumptions!B91,0))) -> 657 | Q32: =Q31+O32-P32 -> 5681
A33: 30 | B33: =ROUND(B32*(1+Assumptions!B42),0) -> 2255 | C33: =ROUND(IF(A33<Assumptions!B100,0,IF(A33<=8,Assumptions!B103,IF(A33<=12,Assumptions!B104,IF(A33<=18,Assumptions!B105,IF(A33<=24,Assumptions!B106,Assumptions!B107))))*(1+IF(A33>=Assumptions!B101,Assumptions!B109,0))*Assumptions!B111),0) -> 540 | D33: =ROUND(ROUND(Assumptions!B119*(1+Assumptions!B120)^6*(1+Assumptions!B121)^6*(1+Assumptions!B122)^(A33-12),0)*Assumptions!B123,0) -> 29 | E33: =B33+C33+D33 -> 2824 | F33: =ROUND(E33*Assumptions!B22,0) -> 4 | G33: =ROUND(H32*Assumptions!B50,0) -> 3 | H33: =H32+F33-G33 -> 33 | I33: =ROUND(H33*(Assumptions!B15*0.85+Assumptions!B11*0.15),0) -> 379 | J33: =ROUND(E33*Assumptions!B95*Assumptions!B96*Assumptions!B97*Assumptions!B94,0) -> 110 | K33: =ROUND(E33*Assumptions!B57*Assumptions!B58,0) -> 988 | L33: =ROUND(IF(A33<Assumptions!B113,0,IF(A33<=18,Assumptions!B105,Assumptions!B107)/1000*Assumptions!B115*0.55+IF(A33>=Assumptions!B114,IF(A33<=18,Assumptions!B105,Assumptions!B107)*Assumptions!B109/1000*Assumptions!B116*0.55,0)),0) -> 94 | M33: =I33+J33+K33+L33 -> 1571 | N33: =ROUND(H33*Assumptions!B62*Assumptions!B61,0)+Assumptions!B63+IF(H33>Assumptions!B64,45,0)+Assumptions!B65+Assumptions!B66+Assumptions!B67+Assumptions!B68+Assumptions!B69/12+IF(A33>=3,Assumptions!B72,0)+ROUND(I33*Assumptions!B70+H33*Assumptions!B71,0)+0 -> 212 | O33: =M33-N33 -> 1359 | P33: =IF((Q32+O33)<N33*Assumptions!B89,0,IF((Q32+O33)<N33*6,ROUND(MAX(O33,0)*Assumptions!B90,0),ROUND(MAX(O33,0)*Assumptions!B91,0))) -> 680 | Q33: =Q32+O33-P33 -> 6360
A34: 31 | B34: =ROUND(B33*(1+Assumptions!B42),0) -> 2345 | C34: =ROUND(IF(A34<Assumptions!B100,0,IF(A34<=8,Assumptions!B103,IF(A34<=12,Assumptions!B104,IF(A34<=18,Assumptions!B105,IF(A34<=24,Assumptions!B106,Assumptions!B107))))*(1+IF(A34>=Assumptions!B101,Assumptions!B109,0))*Assumptions!B111),0) -> 540 | D34: =ROUND(ROUND(Assumptions!B119*(1+Assumptions!B120)^6*(1+Assumptions!B121)^6*(1+Assumptions!B122)^(A34-12),0)*Assumptions!B123,0) -> 32 | E34: =B34+C34+D34 -> 2917 | F34: =ROUND(E34*Assumptions!B22,0) -> 4 | G34: =ROUND(H33*Assumptions!B50,0) -> 3 | H34: =H33+F34-G34 -> 34 | I34: =ROUND(H34*(Assumptions!B15*0.85+Assumptions!B11*0.15),0) -> 390 | J34: =ROUND(E34*Assumptions!B95*Assumptions!B96*Assumptions!B97*Assumptions!B94,0) -> 114 | K34: =ROUND(E34*Assumptions!B57*Assumptions!B58,0) -> 1021 | L34: =ROUND(IF(A34<Assumptions!B113,0,IF(A34<=18,Assumptions!B105,Assumptions!B107)/1000*Assumptions!B115*0.55+IF(A34>=Assumptions!B114,IF(A34<=18,Assumptions!B105,Assumptions!B107)*Assumptions!B109/1000*Assumptions!B116*0.55,0)),0) -> 94 | M34: =I34+J34+K34+L34 -> 1619 | N34: =ROUND(H34*Assumptions!B62*Assumptions!B61,0)+Assumptions!B63+IF(H34>Assumptions!B64,45,0)+Assumptions!B65+Assumptions!B66+Assumptions!B67+Assumptions!B68+Assumptions!B69/12+IF(A34>=3,Assumptions!B72,0)+ROUND(I34*Assumptions!B70+H34*Assumptions!B71,0)+0 -> 214 | O34: =M34-N34 -> 1405 | P34: =IF((Q33+O34)<N34*Assumptions!B89,0,IF((Q33+O34)<N34*6,ROUND(MAX(O34,0)*Assumptions!B90,0),ROUND(MAX(O34,0)*Assumptions!B91,0))) -> 703 | Q34: =Q33+O34-P34 -> 7062
A35: 32 | B35: =ROUND(B34*(1+Assumptions!B42),0) -> 2439 | C35: =ROUND(IF(A35<Assumptions!B100,0,IF(A35<=8,Assumptions!B103,IF(A35<=12,Assumptions!B104,IF(A35<=18,Assumptions!B105,IF(A35<=24,Assumptions!B106,Assumptions!B107))))*(1+IF(A35>=Assumptions!B101,Assumptions!B109,0))*Assumptions!B111),0) -> 540 | D35: =ROUND(ROUND(Assumptions!B119*(1+Assumptions!B120)^6*(1+Assumptions!B121)^6*(1+Assumptions!B122)^(A35-12),0)*Assumptions!B123,0) -> 35 | E35: =B35+C35+D35 -> 3014 | F35: =ROUND(E35*Assumptions!B22,0) -> 5 | G35: =ROUND(H34*Assumptions!B50,0) -> 3 | H35: =H34+F35-G35 -> 36 | I35: =ROUND(H35*(Assumptions!B15*0.85+Assumptions!B11*0.15),0) -> 413 | J35: =ROUND(E35*Assumptions!B95*Assumptions!B96*Assumptions!B97*Assumptions!B94,0) -> 118 | K35: =ROUND(E35*Assumptions!B57*Assumptions!B58,0) -> 1055 | L35: =ROUND(IF(A35<Assumptions!B113,0,IF(A35<=18,Assumptions!B105,Assumptions!B107)/1000*Assumptions!B115*0.55+IF(A35>=Assumptions!B114,IF(A35<=18,Assumptions!B105,Assumptions!B107)*Assumptions!B109/1000*Assumptions!B116*0.55,0)),0) -> 94 | M35: =I35+J35+K35+L35 -> 1680 | N35: =ROUND(H35*Assumptions!B62*Assumptions!B61,0)+Assumptions!B63+IF(H35>Assumptions!B64,45,0)+Assumptions!B65+Assumptions!B66+Assumptions!B67+Assumptions!B68+Assumptions!B69/12+IF(A35>=3,Assumptions!B72,0)+ROUND(I35*Assumptions!B70+H35*Assumptions!B71,0)+0 -> 215 | O35: =M35-N35 -> 1465 | P35: =IF((Q34+O35)<N35*Assumptions!B89,0,IF((Q34+O35)<N35*6,ROUND(MAX(O35,0)*Assumptions!B90,0),ROUND(MAX(O35,0)*Assumptions!B91,0))) -> 733 | Q35: =Q34+O35-P35 -> 7794
A36: 33 | B36: =ROUND(B35*(1+Assumptions!B42),0) -> 2537 | C36: =ROUND(IF(A36<Assumptions!B100,0,IF(A36<=8,Assumptions!B103,IF(A36<=12,Assumptions!B104,IF(A36<=18,Assumptions!B105,IF(A36<=24,Assumptions!B106,Assumptions!B107))))*(1+IF(A36>=Assumptions!B101,Assumptions!B109,0))*Assumptions!B111),0) -> 540 | D36: =ROUND(ROUND(Assumptions!B119*(1+Assumptions!B120)^6*(1+Assumptions!B121)^6*(1+Assumptions!B122)^(A36-12),0)*Assumptions!B123,0) -> 38 | E36: =B36+C36+D36 -> 3115 | F36: =ROUND(E36*Assumptions!B22,0) -> 5 | G36: =ROUND(H35*Assumptions!B50,0) -> 3 | H36: =H35+F36-G36 -> 38 | I36: =ROUND(H36*(Assumptions!B15*0.85+Assumptions!B11*0.15),0) -> 436 | J36: =ROUND(E36*Assumptions!B95*Assumptions!B96*Assumptions!B97*Assumptions!B94,0) -> 121 | K36: =ROUND(E36*Assumptions!B57*Assumptions!B58,0) -> 1090 | L36: =ROUND(IF(A36<Assumptions!B113,0,IF(A36<=18,Assumptions!B105,Assumptions!B107)/1000*Assumptions!B115*0.55+IF(A36>=Assumptions!B114,IF(A36<=18,Assumptions!B105,Assumptions!B107)*Assumptions!B109/1000*Assumptions!B116*0.55,0)),0) -> 94 | M36: =I36+J36+K36+L36 -> 1741 | N36: =ROUND(H36*Assumptions!B62*Assumptions!B61,0)+Assumptions!B63+IF(H36>Assumptions!B64,45,0)+Assumptions!B65+Assumptions!B66+Assumptions!B67+Assumptions!B68+Assumptions!B69/12+IF(A36>=3,Assumptions!B72,0)+ROUND(I36*Assumptions!B70+H36*Assumptions!B71,0)+0 -> 217 | O36: =M36-N36 -> 1524 | P36: =IF((Q35+O36)<N36*Assumptions!B89,0,IF((Q35+O36)<N36*6,ROUND(MAX(O36,0)*Assumptions!B90,0),ROUND(MAX(O36,0)*Assumptions!B91,0))) -> 762 | Q36: =Q35+O36-P36 -> 8556
A37: 34 | B37: =ROUND(B36*(1+Assumptions!B42),0) -> 2638 | C37: =ROUND(IF(A37<Assumptions!B100,0,IF(A37<=8,Assumptions!B103,IF(A37<=12,Assumptions!B104,IF(A37<=18,Assumptions!B105,IF(A37<=24,Assumptions!B106,Assumptions!B107))))*(1+IF(A37>=Assumptions!B101,Assumptions!B109,0))*Assumptions!B111),0) -> 540 | D37: =ROUND(ROUND(Assumptions!B119*(1+Assumptions!B120)^6*(1+Assumptions!B121)^6*(1+Assumptions!B122)^(A37-12),0)*Assumptions!B123,0) -> 42 | E37: =B37+C37+D37 -> 3220 | F37: =ROUND(E37*Assumptions!B22,0) -> 5 | G37: =ROUND(H36*Assumptions!B50,0) -> 3 | H37: =H36+F37-G37 -> 40 | I37: =ROUND(H37*(Assumptions!B15*0.85+Assumptions!B11*0.15),0) -> 459 | J37: =ROUND(E37*Assumptions!B95*Assumptions!B96*Assumptions!B97*Assumptions!B94,0) -> 126 | K37: =ROUND(E37*Assumptions!B57*Assumptions!B58,0) -> 1127 | L37: =ROUND(IF(A37<Assumptions!B113,0,IF(A37<=18,Assumptions!B105,Assumptions!B107)/1000*Assumptions!B115*0.55+IF(A37>=Assumptions!B114,IF(A37<=18,Assumptions!B105,Assumptions!B107)*Assumptions!B109/1000*Assumptions!B116*0.55,0)),0) -> 94 | M37: =I37+J37+K37+L37 -> 1806 | N37: =ROUND(H37*Assumptions!B62*Assumptions!B61,0)+Assumptions!B63+IF(H37>Assumptions!B64,45,0)+Assumptions!B65+Assumptions!B66+Assumptions!B67+Assumptions!B68+Assumptions!B69/12+IF(A37>=3,Assumptions!B72,0)+ROUND(I37*Assumptions!B70+H37*Assumptions!B71,0)+0 -> 218 | O37: =M37-N37 -> 1588 | P37: =IF((Q36+O37)<N37*Assumptions!B89,0,IF((Q36+O37)<N37*6,ROUND(MAX(O37,0)*Assumptions!B90,0),ROUND(MAX(O37,0)*Assumptions!B91,0))) -> 794 | Q37: =Q36+O37-P37 -> 9350
A38: 35 | B38: =ROUND(B37*(1+Assumptions!B42),0) -> 2744 | C38: =ROUND(IF(A38<Assumptions!B100,0,IF(A38<=8,Assumptions!B103,IF(A38<=12,Assumptions!B104,IF(A38<=18,Assumptions!B105,IF(A38<=24,Assumptions!B106,Assumptions!B107))))*(1+IF(A38>=Assumptions!B101,Assumptions!B109,0))*Assumptions!B111),0) -> 540 | D38: =ROUND(ROUND(Assumptions!B119*(1+Assumptions!B120)^6*(1+Assumptions!B121)^6*(1+Assumptions!B122)^(A38-12),0)*Assumptions!B123,0) -> 46 | E38: =B38+C38+D38 -> 3330 | F38: =ROUND(E38*Assumptions!B22,0) -> 5 | G38: =ROUND(H37*Assumptions!B50,0) -> 3 | H38: =H37+F38-G38 -> 42 | I38: =ROUND(H38*(Assumptions!B15*0.85+Assumptions!B11*0.15),0) -> 482 | J38: =ROUND(E38*Assumptions!B95*Assumptions!B96*Assumptions!B97*Assumptions!B94,0) -> 130 | K38: =ROUND(E38*Assumptions!B57*Assumptions!B58,0) -> 1166 | L38: =ROUND(IF(A38<Assumptions!B113,0,IF(A38<=18,Assumptions!B105,Assumptions!B107)/1000*Assumptions!B115*0.55+IF(A38>=Assumptions!B114,IF(A38<=18,Assumptions!B105,Assumptions!B107)*Assumptions!B109/1000*Assumptions!B116*0.55,0)),0) -> 94 | M38: =I38+J38+K38+L38 -> 1872 | N38: =ROUND(H38*Assumptions!B62*Assumptions!B61,0)+Assumptions!B63+IF(H38>Assumptions!B64,45,0)+Assumptions!B65+Assumptions!B66+Assumptions!B67+Assumptions!B68+Assumptions!B69/12+IF(A38>=3,Assumptions!B72,0)+ROUND(I38*Assumptions!B70+H38*Assumptions!B71,0)+0 -> 221 | O38: =M38-N38 -> 1651 | P38: =IF((Q37+O38)<N38*Assumptions!B89,0,IF((Q37+O38)<N38*6,ROUND(MAX(O38,0)*Assumptions!B90,0),ROUND(MAX(O38,0)*Assumptions!B91,0))) -> 826 | Q38: =Q37+O38-P38 -> 10175
