Workbook

Sheet Dashboard
A1: MyAdvocate Projections v14 — Executive Dashboard
A2: Source: PMP v19 | Version: v14.0 — March 2026 | Scenarios: Conservative / Expected / Optimistic
A4: KEY METRICS — MONTH 36
B5: Conservative | C5: Expected | D5: Optimistic
A6: Monthly Visitors | B6: =Conservative!B41 -> 9181.6988 | C6: =Expected!B41 -> 52461.702 | D6: =Optimistic!B41 -> 198484.8
A7: Paid Subscribers | B7: =Conservative!E41 -> 92 | C7: =Expected!E41 -> 812 | D7: =Optimistic!E41 -> 5994
A8: MRR | B8: =Conservative!H41 -> 1056 | C8: =Expected!H41 -> 9318 | D8: =Optimistic!H41 -> 68781
A9: Monthly Referral Revenue | B9: =Conservative!R41 -> 3214 | C9: =Expected!R41 -> 18362 | D9: =Optimistic!R41 -> 69470
A10: Per-Case Revenue (M36) | B10: =Conservative!W41 -> 358 | C10: =Expected!W41 -> 2046 | D10: =Optimistic!W41 -> 7741
A11: Total Revenue (M36) | B11: =Conservative!S41 -> 4628 | C11: =Expected!S41 -> 29726 | D11: =Optimistic!S41 -> 145992
A12: Owner's Draw (M36) | B12: =Conservative!T41 -> 1234 | C12: =Expected!T41 -> 8119 | D12: =Optimistic!T41 -> 39722
A13: Reserve Balance | B13: =Conservative!U41 -> 46391 | C13: =Expected!U41 -> 249148 | D13: =Optimistic!U41 -> 1036002
A14: Traffic Signal | B14: =Conservative!V41 -> Pre-Signal 1 | C14: =Expected!V41 -> Signal 3 | D14: =Optimistic!V41 -> Signal 6
A15: 3-Yr Subscription Revenue | B15: =Conservative!I43 -> 12386 | C15: =Expected!I43 -> 82970 | D15: =Optimistic!I43 -> 513896
A16: 3-Yr Total Referral Revenue | B16: =Conservative!R43 -> 39390 | C16: =Expected!R43 -> 166268 | D16: =Optimistic!R43 -> 525609
A17: 3-Yr Per-Case Revenue | B17: =Conservative!W43 -> 4517 | C17: =Expected!W43 -> 18744 | D17: =Optimistic!W43 -> 58915
A18: 3-Yr Total Revenue | B18: =Conservative!S43 -> 56293 | C18: =Expected!S43 -> 267982 | D18: =Optimistic!S43 -> 1098420
A20: CONVERSION & GROWTH ASSUMPTIONS
B21: Conservative | C21: Expected | D21: Optimistic
A22: Paid Conversion Rate | B22: =Assumptions!B22 -> 0.0015 | C22: =Assumptions!B23 -> 0.0025 | D22: =Assumptions!B24 -> 0.005
A23: Monthly Traffic Growth | B23: =Assumptions!B33 -> 0.08 | C23: =Assumptions!B34 -> 0.12 | D23: =Assumptions!B35 -> 0.15
A24: Monthly Churn | B24: =Assumptions!B43 -> 0.08 | C24: =Assumptions!B44 -> 0.06 | D24: =Assumptions!B45 -> 0.04
A25: Per-Case Price | B25: =Assumptions!B136 -> 13 | C25: =Assumptions!B136 -> 13 | D25: =Assumptions!B136 -> 13
A26: Tool Engagement Rate | B26: =Assumptions!B137 -> 0.08 | C26: =Assumptions!B137 -> 0.08 | D26: =Assumptions!B137 -> 0.08

Sheet Assumptions
A1: MyAdvocate Financial Model v14 — Assumptions
A2: Source: PMP v19 | Blue = input (user-editable) | Black = calculated | Green = cross-sheet link
A3: Version: v14.0 — March 2026 | Scenarios: Conservative / Expected / Optimistic
A5: CORE BUSINESS ASSUMPTIONS
A6: Launch Month | B6: 1 | C6: Month 1 = Launch
A7: Planning Horizon (months) | B7: 36 | C7: 3-year projection
A9: PRICING STRUCTURE
A10: Founding Advocate Annual Price | B10: 34 | C10: $34/year — first 250 subs, locked forever
A11: Founding Advocate Monthly Equivalent | B11: =B10/12 -> 2.8333333 | C11: $34/12 — for MRR calculation purposes
A12: Founding Advocate Renewal Price (Year 2+) | B12: 55 | C12: $55/yr — permanent FA rate after Year 1 lock
A13: FA Cohort Cap | B13: 250 | C13: Maximum Founding Advocates — hard cap
A14: Basic Tier Monthly | B14: 8 | C14: Launch tier — all new subs Months 1–8
A15: Standard Tier Monthly (Month 9+) | B15: 13 | C15: Price increase Month 9 — new subs only
A16: Advocate Builder Quarterly | B16: 21 | C16: $21/quarter — alternative entry point
A17: Advocate Builder Monthly Equivalent | B17: =B16/3 -> 7 | C17: $21/3 — for MRR purposes
A18: Annual Standard Price | B18: 55 | C18: $55/yr for committed annual subscribers
A19: Premium Monthly (Phase 4+) | B19: 21 | C19: Native app tier — Phase 4 unlock
A21: CONVERSION RATES — HEALTHCARE COLD TRAFFIC
A22: Conservative Paid Conversion Rate | B22: 0.0015 | C22: 0.15% — cold traffic baseline. Source: PMP v19 §3
A23: Expected Paid Conversion Rate | B23: 0.0025 | C23: 0.25% — moderate, denial-code SEO boost
A24: Optimistic Paid Conversion Rate | B24: 0.005 | C24: 0.50% — high-intent denial code + SEO optimization
A25: Free Signup / Email Capture Rate | B25: 0.02 | C25: 2.0% of visitors — owned email list growth
A26: Denial Decoder Free-to-Paid Lift | B26: 1.15 | C26: 15% higher conversion from denial code page visitors
A27: Founding Advocate Conversion Rate (of early subs) | B27: 0.4 | C27: ~40% of first subs take the FA offer
A29: SEO TRAFFIC GROWTH MODEL
A30: Month 1 Traffic — Conservative | B30: 500 | C30: Minimal launch, no prior SEO momentum
A31: Month 1 Traffic — Expected | B31: 800 | C31: Early SEO content live at launch
A32: Month 1 Traffic — Optimistic | B32: 1200 | C32: Aggressive pre-launch content build
A33: Monthly Traffic Growth — Conservative | B33: 0.08 | C33: 8% MoM — slow organic compounding
A34: Monthly Traffic Growth — Expected | B34: 0.12 | C34: 12% MoM — consistent 2x/week publishing
A35: Monthly Traffic Growth — Optimistic | B35: 0.15 | C35: 15% MoM — aggressive SEO + denial codes indexing fast
A36: Denial Code Program Traffic Boost (Month 3+) | B36: 1.15 | C36: 15% additional traffic lift from 200+ denial code pages indexing
A37: Content Cluster Maturity Boost (Month 6+) | B37: 1.08 | C37: 8% additional lift as pillar/cluster architecture matures
A38: Publishing Cadence (articles/week) | B38: 2 | C38: 2x/week per PMP v19 §4C — sustained from Month 1
A39: Denial Code Pages (Month 3 launch) | B39: 200 | C39: 200 denial code pages built — one-time SEO asset
A40: Month 12 Cumulative Articles Target | B40: 60 | C40: ~2x/week × 26 weeks = ~52 articles + backlog
A42: CHURN & RETENTION
A43: Monthly Churn — Conservative | B43: 0.08 | C43: 8% monthly churn — challenging retention environment
A44: Monthly Churn — Expected | B44: 0.06 | C44: 6% monthly churn — decent product-market fit
A45: Monthly Churn — Optimistic | B45: 0.04 | C45: 4% monthly churn — strong engagement, content value
...

Sheet Conservative
A1: CONSERVATIVE SCENARIO — Conservative Growth
A2: 0.15% paid conversion | 8% MoM traffic growth | 8% monthly churn | Referral: 0.1% of visitors x $350 blended
A3: Blue = hardcoded inputs | Black = calculated formulas | Green = Assumptions references
A5: Month | B5: Monthly Visitors | C5: Free Signups (Email 2%) | D5: New Paid Subs | E5: Total Paid Subs | F5: Churn This Month | G5: Net New Subs | H5: MRR ($) | I5: Monthly Revenue ($) | J5: Letter Generations | K5: API Costs ($) | L5: Infrastructure ($) | M5: Content/SEO ($) | N5: n8n + Tools ($) | O5: Stripe Fees ($) | P5: Total Costs ($) | Q5: Gross Profit ($) | R5: Referral Revenue ($) | S5: Total Revenue ($) | T5: Owner's Draw ($) | U5: Reserve Balance ($) | V5: Traffic Signal | W5: Per-Case Revenue ($) | X5: Free Tier API Cost ($)
A6: 1 | B6: =Assumptions!B30 -> 500 | C6: =ROUND(B6*Assumptions!B25,0) -> 10 | D6: =ROUND(B6*Assumptions!B22,0) -> 1 | E6: =D6 -> 1 | F6: =0 -> 0 | G6: =D6-F6 -> 1 | H6: =ROUND(E6*Assumptions!B14,0) -> 8 | I6: =H6 -> 8 | J6: =ROUND(E6*Assumptions!B68,0) -> 4 | K6: =ROUND(J6*Assumptions!B65,0) -> 0 | L6: =Assumptions!B70+IF(E6>Assumptions!B72,45,0) -> 31 | M6: =Assumptions!B94+Assumptions!B95+Assumptions!B76+Assumptions!B77 -> 2785 | N6: =Assumptions!B81+Assumptions!B82+Assumptions!B87/12 -> 50 | O6: =ROUND(I6*Assumptions!B85+E6*Assumptions!B86+W6*Assumptions!B85+ROUND(B6*Assumptions!B137*Assumptions!B138*Assumptions!B139,0)*Assumptions!B86,0) -> 2 | P6: =K6+L6+M6+N6+O6+X6 -> 2871 | Q6: =I6-P6 -> -2863 | R6: =0 -> 0 | S6: =I6+R6+W6 -> 28 | T6: =IF(U6<P6*3,0,IF(U6<P6*6,ROUND((Q6+R6+W6)*0.75*Assumptions!B113,0),ROUND((Q6+R6+W6)*0.75*Assumptions!B114,0))) -> 0 | U6: =Q6+R6+W6 -> -2843 | V6: =IF(B6>=Assumptions!B107,"Signal 6",IF(B6>=Assumptions!B106,"Signal 5",IF(B6>=Assumptions!B105,"Signal 4",IF(B6>=Assumptions!B104,"Signal 3",IF(B6>=Assumptions!B103,"Signal 2",IF(B6>=Assumptions!B102,"Signal 1","Pre-Signal 1")))))) -> Pre-Signal 1 | W6: =ROUND(B6*Assumptions!B137*Assumptions!B138*Assumptions!B139*Assumptions!B136,0) -> 20 | X6: =ROUND(B6*Assumptions!B137*Assumptions!B65,0) -> 3
A7: 2 | B7: =B6*(1+Assumptions!B33) -> 540 | C7: =ROUND(B7*Assumptions!B25,0) -> 11 | D7: =ROUND(B7*Assumptions!B22,0) -> 1 | E7: =E6+D7-F7 -> 2 | F7: =ROUND(E6*Assumptions!B43,0) -> 0 | G7: =D7-F7 -> 1 | H7: =ROUND(E7*Assumptions!B14,0) -> 16 | I7: =H7 -> 16 | J7: =ROUND(E7*Assumptions!B68,0) -> 7 | K7: =ROUND(J7*Assumptions!B65,0) -> 1 | L7: =Assumptions!B70+IF(E7>Assumptions!B72,45,0) -> 31 | M7: =Assumptions!B76+Assumptions!B77 -> 35 | N7: =Assumptions!B81+Assumptions!B82+Assumptions!B87/12 -> 50 | O7: =ROUND(I7*Assumptions!B85+E7*Assumptions!B86+W7*Assumptions!B85+ROUND(B7*Assumptions!B137*Assumptions!B138*Assumptions!B139,0)*Assumptions!B86,0) -> 2 | P7: =K7+L7+M7+N7+O7+X7 -> 122 | Q7: =I7-P7 -> -106 | R7: =0 -> 0 | S7: =I7+R7+W7 -> 37 | T7: =IF(U7<P7*3,0,IF(U7<P7*6,ROUND((Q7+R7+W7)*0.75*Assumptions!B113,0),ROUND((Q7+R7+W7)*0.75*Assumptions!B114,0))) -> 0 | U7: =U6+Q7+R7+W7 -> -2928 | V7: =IF(B7>=Assumptions!B107,"Signal 6",IF(B7>=Assumptions!B106,"Signal 5",IF(B7>=Assumptions!B105,"Signal 4",IF(B7>=Assumptions!B104,"Signal 3",IF(B7>=Assumptions!B103,"Signal 2",IF(B7>=Assumptions!B102,"Signal 1","Pre-Signal 1")))))) -> Pre-Signal 1 | W7: =ROUND(B7*Assumptions!B137*Assumptions!B138*Assumptions!B139*Assumptions!B136,0) -> 21 | X7: =ROUND(B7*Assumptions!B137*Assumptions!B65,0) -> 3
A8: 3 | B8: =B7*(1+Assumptions!B33)*Assumptions!B36 -> 670.68 | C8: =ROUND(B8*Assumptions!B25,0) -> 13 | D8: =ROUND(B8*Assumptions!B22,0) -> 1 | E8: =E7+D8-F8 -> 3 | F8: =ROUND(E7*Assumptions!B43,0) -> 0 | G8: =D8-F8 -> 1 | H8: =ROUND(E8*Assumptions!B14,0) -> 24 | I8: =H8 -> 24 | J8: =ROUND(E8*Assumptions!B68,0) -> 11 | K8: =ROUND(J8*Assumptions!B65,0) -> 1 | L8: =Assumptions!B70+IF(E8>Assumptions!B72,45,0) -> 31 | M8: =Assumptions!B76+Assumptions!B77 -> 35 | N8: =Assumptions!B81+Assumptions!B82+Assumptions!B87/12 -> 50 | O8: =ROUND(I8*Assumptions!B85+E8*Assumptions!B86+W8*Assumptions!B85+ROUND(B8*Assumptions!B137*Assumptions!B138*Assumptions!B139,0)*Assumptions!B86,0) -> 3 | P8: =K8+L8+M8+N8+O8+X8 -> 124 | Q8: =I8-P8 -> -100 | R8: =0 -> 0 | S8: =I8+R8+W8 -> 50 | T8: =IF(U8<P8*3,0,IF(U8<P8*6,ROUND((Q8+R8+W8)*0.75*Assumptions!B113,0),ROUND((Q8+R8+W8)*0.75*Assumptions!B114,0))) -> 0 | U8: =U7+Q8+R8+W8 -> -3002 | V8: =IF(B8>=Assumptions!B107,"Signal 6",IF(B8>=Assumptions!B106,"Signal 5",IF(B8>=Assumptions!B105,"Signal 4",IF(B8>=Assumptions!B104,"Signal 3",IF(B8>=Assumptions!B103,"Signal 2",IF(B8>=Assumptions!B102,"Signal 1","Pre-Signal 1")))))) -> Pre-Signal 1 | W8: =ROUND(B8*Assumptions!B137*Assumptions!B138*Assumptions!B139*Assumptions!B136,0) -> 26 | X8: =ROUND(B8*Assumptions!B137*Assumptions!B65,0) -> 4
A9: 4 | B9: =B8*(1+Assumptions!B33) -> 724.3344 | C9: =ROUND(B9*Assumptions!B25,0) -> 14 | D9: =ROUND(B9*Assumptions!B22,0) -> 1 | E9: =E8+D9-F9 -> 4 | F9: =ROUND(E8*Assumptions!B43,0) -> 0 | G9: =D9-F9 -> 1 | H9: =ROUND(E9*Assumptions!B14,0) -> 32 | I9: =H9 -> 32 | J9: =ROUND(E9*Assumptions!B68,0) -> 14 | K9: =ROUND(J9*Assumptions!B65,0) -> 1 | L9: =Assumptions!B70+IF(E9>Assumptions!B72,45,0) -> 31 | M9: =Assumptions!B76+Assumptions!B77 -> 35 | N9: =Assumptions!B81+Assumptions!B82+Assumptions!B87/12 -> 50 | O9: =ROUND(I9*Assumptions!B85+E9*Assumptions!B86+W9*Assumptions!B85+ROUND(B9*Assumptions!B137*Assumptions!B138*Assumptions!B139,0)*Assumptions!B86,0) -> 4 | P9: =K9+L9+M9+N9+O9+X9 -> 126 | Q9: =I9-P9 -> -94 | R9: =0 -> 0 | S9: =I9+R9+W9 -> 60 | T9: =IF(U9<P9*3,0,IF(U9<P9*6,ROUND((Q9+R9+W9)*0.75*Assumptions!B113,0),ROUND((Q9+R9+W9)*0.75*Assumptions!B114,0))) -> 0 | U9: =U8+Q9+R9+W9 -> -3068 | V9: =IF(B9>=Assumptions!B107,"Signal 6",IF(B9>=Assumptions!B106,"Signal 5",IF(B9>=Assumptions!B105,"Signal 4",IF(B9>=Assumptions!B104,"Signal 3",IF(B9>=Assumptions!B103,"Signal 2",IF(B9>=Assumptions!B102,"Signal 1","Pre-Signal 1")))))) -> Pre-Signal 1 | W9: =ROUND(B9*Assumptions!B137*Assumptions!B138*Assumptions!B139*Assumptions!B136,0) -> 28 | X9: =ROUND(B9*Assumptions!B137*Assumptions!B65,0) -> 5
A10: 5 | B10: =B9*(1+Assumptions!B33) -> 782.28115 | C10: =ROUND(B10*Assumptions!B25,0) -> 16 | D10: =ROUND(B10*Assumptions!B22,0) -> 1 | E10: =E9+D10-F10 -> 5 | F10: =ROUND(E9*Assumptions!B43,0) -> 0 | G10: =D10-F10 -> 1 | H10: =ROUND(E10*Assumptions!B14,0) -> 40 | I10: =H10 -> 40 | J10: =ROUND(E10*Assumptions!B68,0) -> 18 | K10: =ROUND(J10*Assumptions!B65,0) -> 1 | L10: =Assumptions!B70+IF(E10>Assumptions!B72,45,0) -> 31 | M10: =Assumptions!B76+Assumptions!B77 -> 35 | N10: =Assumptions!B81+Assumptions!B82+Assumptions!B87/12 -> 50 | O10: =ROUND(I10*Assumptions!B85+E10*Assumptions!B86+W10*Assumptions!B85+ROUND(B10*Assumptions!B137*Assumptions!B138*Assumptions!B139,0)*Assumptions!B86,0) -> 4 | P10: =K10+L10+M10+N10+O10+X10 -> 126 | Q10: =I10-P10 -> -86 | R10: =0 -> 0 | S10: =I10+R10+W10 -> 71 | T10: =IF(U10<P10*3,0,IF(U10<P10*6,ROUND((Q10+R10+W10)*0.75*Assumptions!B113,0),ROUND((Q10+R10+W10)*0.75*Assumptions!B114,0))) -> 0 | U10: =U9+Q10+R10+W10 -> -3123 | V10: =IF(B10>=Assumptions!B107,"Signal 6",IF(B10>=Assumptions!B106,"Signal 5",IF(B10>=Assumptions!B105,"Signal 4",IF(B10>=Assumptions!B104,"Signal 3",IF(B10>=Assumptions!B103,"Signal 2",IF(B10>=Assumptions!B102,"Signal 1","Pre-Signal 1")))))) -> Pre-Signal 1 | W10: =ROUND(B10*Assumptions!B137*Assumptions!B138*Assumptions!B139*Assumptions!B136,0) -> 31 | X10: =ROUND(B10*Assumptions!B137*Assumptions!B65,0) -> 5
A11: 6 | B11: =B10*(1+Assumptions!B33)*Assumptions!B37 -> 912.45274 | C11: =ROUND(B11*Assumptions!B25,0) -> 18 | D11: =ROUND(B11*Assumptions!B22,0) -> 1 | E11: =E10+D11-F11 -> 6 | F11: =ROUND(E10*Assumptions!B43,0) -> 0 | G11: =D11-F11 -> 1 | H11: =ROUND(E11*Assumptions!B14,0) -> 48 | I11: =H11 -> 48 | J11: =ROUND(E11*Assumptions!B68,0) -> 21 | K11: =ROUND(J11*Assumptions!B65,0) -> 2 | L11: =Assumptions!B70+IF(E11>Assumptions!B72,45,0) -> 31 | M11: =Assumptions!B76+Assumptions!B77 -> 35 | N11: =Assumptions!B81+Assumptions!B82+Assumptions!B87/12 -> 50 | O11: =ROUND(I11*Assumptions!B85+E11*Assumptions!B86+W11*Assumptions!B85+ROUND(B11*Assumptions!B137*Assumptions!B138*Assumptions!B139,0)*Assumptions!B86,0) -> 5 | P11: =K11+L11+M11+N11+O11+X11 -> 129 | Q11: =I11-P11 -> -81 | R11: =ROUND(B11*Assumptions!B51*Assumptions!B52,0) -> 319 | S11: =I11+R11+W11 -> 403 | T11: =IF(U11<P11*3,0,IF(U11<P11*6,ROUND((Q11+R11+W11)*0.75*Assumptions!B113,0),ROUND((Q11+R11+W11)*0.75*Assumptions!B114,0))) -> 0 | U11: =U10+Q11+R11+W11 -> -2849 | V11: =IF(B11>=Assumptions!B107,"Signal 6",IF(B11>=Assumptions!B106,"Signal 5",IF(B11>=Assumptions!B105,"Signal 4",IF(B11>=Assumptions!B104,"Signal 3",IF(B11>=Assumptions!B103,"Signal 2",IF(B11>=Assumptions!B102,"Signal 1","Pre-Signal 1")))))) -> Pre-Signal 1 | W11: =ROUND(B11*Assumptions!B137*Assumptions!B138*Assumptions!B139*Assumptions!B136,0) -> 36 | X11: =ROUND(B11*Assumptions!B137*Assumptions!B65,0) -> 6
A12: 7 | B12: =B11*(1+Assumptions!B33) -> 985.44895 | C12: =ROUND(B12*Assumptions!B25,0) -> 20 | D12: =ROUND(B12*Assumptions!B22,0) -> 1 | E12: =E11+D12-F12 -> 7 | F12: =ROUND(E11*Assumptions!B43,0) -> 0 | G12: =D12-F12 -> 1 | H12: =ROUND(E12*Assumptions!B14,0) -> 56 | I12: =H12 -> 56 | J12: =ROUND(E12*Assumptions!B68,0) -> 25 | K12: =ROUND(J12*Assumptions!B65,0) -> 2 | L12: =Assumptions!B70+IF(E12>Assumptions!B72,45,0) -> 31 | M12: =Assumptions!B76+Assumptions!B77 -> 35 | N12: =Assumptions!B81+Assumptions!B82+Assumptions!B87/12 -> 50 | O12: =ROUND(I12*Assumptions!B85+E12*Assumptions!B86+W12*Assumptions!B85+ROUND(B12*Assumptions!B137*Assumptions!B138*Assumptions!B139,0)*Assumptions!B86,0) -> 6 | P12: =K12+L12+M12+N12+O12+X12 -> 130 | Q12: =I12-P12 -> -74 | R12: =ROUND(B12*Assumptions!B51*Assumptions!B52,0) -> 345 | S12: =I12+R12+W12 -> 439 | T12: =IF(U12<P12*3,0,IF(U12<P12*6,ROUND((Q12+R12+W12)*0.75*Assumptions!B113,0),ROUND((Q12+R12+W12)*0.75*Assumptions!B114,0))) -> 0 | U12: =U11+Q12+R12+W12 -> -2540 | V12: =IF(B12>=Assumptions!B107,"Signal 6",IF(B12>=Assumptions!B106,"Signal 5",IF(B12>=Assumptions!B105,"Signal 4",IF(B12>=Assumptions!B104,"Signal 3",IF(B12>=Assumptions!B103,"Signal 2",IF(B12>=Assumptions!B102,"Signal 1","Pre-Signal 1")))))) -> Pre-Signal 1 | W12: =ROUND(B12*Assumptions!B137*Assumptions!B138*Assumptions!B139*Assumptions!B136,0) -> 38 | X12: =ROUND(B12*Assumptions!B137*Assumptions!B65,0) -> 6
A13: 8 | B13: =B12*(1+Assumptions!B33) -> 1064.2849 | C13: =ROUND(B13*Assumptions!B25,0) -> 21 | D13: =ROUND(B13*Assumptions!B22,0) -> 2 | E13: =E12+D13-F13 -> 8 | F13: =ROUND(E12*Assumptions!B43,0) -> 1 | G13: =D13-F13 -> 1 | H13: =ROUND(E13*Assumptions!B14,0) -> 64 | I13: =H13 -> 64 | J13: =ROUND(E13*Assumptions!B68,0) -> 28 | K13: =ROUND(J13*Assumptions!B65,0) -> 2 | L13: =Assumptions!B70+IF(E13>Assumptions!B72,45,0) -> 31 | M13: =Assumptions!B76+Assumptions!B77 -> 35 | N13: =Assumptions!B81+Assumptions!B82+Assumptions!B87/12 -> 50 | O13: =ROUND(I13*Assumptions!B85+E13*Assumptions!B86+W13*Assumptions!B85+ROUND(B13*Assumptions!B137*Assumptions!B138*Assumptions!B139,0)*Assumptions!B86,0) -> 6 | P13: =K13+L13+M13+N13+O13+X13 -> 131 | Q13: =I13-P13 -> -67 | R13: =ROUND(B13*Assumptions!B51*Assumptions!B52,0) -> 372 | S13: =I13+R13+W13 -> 478 | T13: =IF(U13<P13*3,0,IF(U13<P13*6,ROUND((Q13+R13+W13)*0.75*Assumptions!B113,0),ROUND((Q13+R13+W13)*0.75*Assumptions!B114,0))) -> 0 | U13: =U12+Q13+R13+W13 -> -2193 | V13: =IF(B13>=Assumptions!B107,"Signal 6",IF(B13>=Assumptions!B106,"Signal 5",IF(B13>=Assumptions!B105,"Signal 4",IF(B13>=Assumptions!B104,"Signal 3",IF(B13>=Assumptions!B103,"Signal 2",IF(B13>=Assumptions!B102,"Signal 1","Pre-Signal 1")))))) -> Pre-Signal 1 | W13: =ROUND(B13*Assumptions!B137*Assumptions!B138*Assumptions!B139*Assumptions!B136,0) -> 42 | X13: =ROUND(B13*Assumptions!B137*Assumptions!B65,0) -> 7
A14: 9 | B14: =B13*(1+Assumptions!B33) -> 1149.4277 | C14: =ROUND(B14*Assumptions!B25,0) -> 23 | D14: =ROUND(B14*Assumptions!B22,0) -> 2 | E14: =E13+D14-F14 -> 9 | F14: =ROUND(E13*Assumptions!B43,0) -> 1 | G14: =D14-F14 -> 1 | H14: =ROUND(E14*((Assumptions!B14+Assumptions!B15)/2),0) -> 95 | I14: =H14 -> 95 | J14: =ROUND(E14*Assumptions!B68,0) -> 32 | K14: =ROUND(J14*Assumptions!B65,0) -> 3 | L14: =Assumptions!B70+IF(E14>Assumptions!B72,45,0) -> 31 | M14: =Assumptions!B76+Assumptions!B77 -> 35 | N14: =Assumptions!B81+Assumptions!B82+Assumptions!B87/12 -> 50 | O14: =ROUND(I14*Assumptions!B85+E14*Assumptions!B86+W14*Assumptions!B85+ROUND(B14*Assumptions!B137*Assumptions!B138*Assumptions!B139,0)*Assumptions!B86,0) -> 8 | P14: =K14+L14+M14+N14+O14+X14 -> 134 | Q14: =I14-P14 -> -39 | R14: =ROUND(B14*Assumptions!B51*Assumptions!B52,0) -> 402 | S14: =I14+R14+W14 -> 542 | T14: =IF(U14<P14*3,0,IF(U14<P14*6,ROUND((Q14+R14+W14)*0.75*Assumptions!B113,0),ROUND((Q14+R14+W14)*0.75*Assumptions!B114,0))) -> 0 | U14: =U13+Q14+R14+W14 -> -1785 | V14: =IF(B14>=Assumptions!B107,"Signal 6",IF(B14>=Assumptions!B106,"Signal 5",IF(B14>=Assumptions!B105,"Signal 4",IF(B14>=Assumptions!B104,"Signal 3",IF(B14>=Assumptions!B103,"Signal 2",IF(B14>=Assumptions!B102,"Signal 1","Pre-Signal 1")))))) -> Pre-Signal 1 | W14: =ROUND(B14*Assumptions!B137*Assumptions!B138*Assumptions!B139*Assumptions!B136,0) -> 45 | X14: =ROUND(B14*Assumptions!B137*Assumptions!B65,0) -> 7
A15: 10 | B15: =B14*(1+Assumptions!B33) -> 1241.3819 | C15: =ROUND(B15*Assumptions!B25,0) -> 25 | D15: =ROUND(B15*Assumptions!B22,0) -> 2 | E15: =E14+D15-F15 -> 10 | F15: =ROUND(E14*Assumptions!B43,0) -> 1 | G15: =D15-F15 -> 1 | H15: =ROUND(E15*(Assumptions!B15*0.85+Assumptions!B11*0.15),0) -> 115 | I15: =H15 -> 115 | J15: =ROUND(E15*Assumptions!B68,0) -> 35 | K15: =ROUND(J15*Assumptions!B65,0) -> 3 | L15: =Assumptions!B70+IF(E15>Assumptions!B72,45,0) -> 31 | M15: =Assumptions!B76+Assumptions!B77 -> 35 | N15: =Assumptions!B81+Assumptions!B82+Assumptions!B87/12 -> 50 | O15: =ROUND(I15*Assumptions!B85+E15*Assumptions!B86+W15*Assumptions!B85+ROUND(B15*Assumptions!B137*Assumptions!B138*Assumptions!B139,0)*Assumptions!B86,0) -> 9 | P15: =K15+L15+M15+N15+O15+X15 -> 136 | Q15: =I15-P15 -> -21 | R15: =ROUND(B15*Assumptions!B51*Assumptions!B52,0) -> 434 | S15: =I15+R15+W15 -> 597 | T15: =IF(U15<P15*3,0,IF(U15<P15*6,ROUND((Q15+R15+W15)*0.75*Assumptions!B113,0),ROUND((Q15+R15+W15)*0.75*Assumptions!B114,0))) -> 0 | U15: =U14+Q15+R15+W15 -> -1324 | V15: =IF(B15>=Assumptions!B107,"Signal 6",IF(B15>=Assumptions!B106,"Signal 5",IF(B15>=Assumptions!B105,"Signal 4",IF(B15>=Assumptions!B104,"Signal 3",IF(B15>=Assumptions!B103,"Signal 2",IF(B15>=Assumptions!B102,"Signal 1","Pre-Signal 1")))))) -> Pre-Signal 1 | W15: =ROUND(B15*Assumptions!B137*Assumptions!B138*Assumptions!B139*Assumptions!B136,0) -> 48 | X15: =ROUND(B15*Assumptions!B137*Assumptions!B65,0) -> 8
A16: 11 | B16: =B15*(1+Assumptions!B33) -> 1340.6924 | C16: =ROUND(B16*Assumptions!B25,0) -> 27 | D16: =ROUND(B16*Assumptions!B22,0) -> 2 | E16: =E15+D16-F16 -> 11 | F16: =ROUND(E15*Assumptions!B43,0) -> 1 | G16: =D16-F16 -> 1 | H16: =ROUND(E16*(Assumptions!B15*0.85+Assumptions!B11*0.15),0) -> 126 | I16: =H16 -> 126 | J16: =ROUND(E16*Assumptions!B68,0) -> 39 | K16: =ROUND(J16*Assumptions!B65,0) -> 3 | L16: =Assumptions!B70+IF(E16>Assumptions!B72,45,0) -> 31 | M16: =Assumptions!B76+Assumptions!B77 -> 35 | N16: =Assumptions!B81+Assumptions!B82+Assumptions!B87/12 -> 50 | O16: =ROUND(I16*Assumptions!B85+E16*Assumptions!B86+W16*Assumptions!B85+ROUND(B16*Assumptions!B137*Assumptions!B138*Assumptions!B139,0)*Assumptions!B86,0) -> 10 | P16: =K16+L16+M16+N16+O16+X16 -> 138 | Q16: =I16-P16 -> -12 | R16: =ROUND(B16*Assumptions!B51*Assumptions!B52,0) -> 469 | S16: =I16+R16+W16 -> 647 | T16: =IF(U16<P16*3,0,IF(U16<P16*6,ROUND((Q16+R16+W16)*0.75*Assumptions!B113,0),ROUND((Q16+R16+W16)*0.75*Assumptions!B114,0))) -> 0 | U16: =U15+Q16+R16+W16 -> -815 | V16: =IF(B16>=Assumptions!B107,"Signal 6",IF(B16>=Assumptions!B106,"Signal 5",IF(B16>=Assumptions!B105,"Signal 4",IF(B16>=Assumptions!B104,"Signal 3",IF(B16>=Assumptions!B103,"Signal 2",IF(B16>=Assumptions!B102,"Signal 1","Pre-Signal 1")))))) -> Pre-Signal 1 | W16: =ROUND(B16*Assumptions!B137*Assumptions!B138*Assumptions!B139*Assumptions!B136,0) -> 52 | X16: =ROUND(B16*Assumptions!B137*Assumptions!B65,0) -> 9
A17: 12 | B17: =B16*(1+Assumptions!B33) -> 1447.9478 | C17: =ROUND(B17*Assumptions!B25,0) -> 29 | D17: =ROUND(B17*Assumptions!B22,0) -> 2 | E17: =E16+D17-F17 -> 12 | F17: =ROUND(E16*Assumptions!B43,0) -> 1 | G17: =D17-F17 -> 1 | H17: =ROUND(E17*(Assumptions!B15*0.85+Assumptions!B11*0.15),0) -> 138 | I17: =H17 -> 138 | J17: =ROUND(E17*Assumptions!B68,0) -> 42 | K17: =ROUND(J17*Assumptions!B65,0) -> 3 | L17: =Assumptions!B70+IF(E17>Assumptions!B72,45,0) -> 31 | M17: =Assumptions!B76+Assumptions!B77 -> 35 | N17: =Assumptions!B81+Assumptions!B82+Assumptions!B87/12 -> 50 | O17: =ROUND(I17*Assumptions!B85+E17*Assumptions!B86+W17*Assumptions!B85+ROUND(B17*Assumptions!B137*Assumptions!B138*Assumptions!B139,0)*Assumptions!B86,0) -> 10 | P17: =K17+L17+M17+N17+O17+X17 -> 138 | Q17: =I17-P17 -> 0 | R17: =ROUND(B17*Assumptions!B51*Assumptions!B52,0) -> 507 | S17: =I17+R17+W17 -> 701 | T17: =IF(U17<P17*3,0,IF(U17<P17*6,ROUND((Q17+R17+W17)*0.75*Assumptions!B113,0),ROUND((Q17+R17+W17)*0.75*Assumptions!B114,0))) -> 0 | U17: =U16+Q17+R17+W17 -> -252 | V17: =IF(B17>=Assumptions!B107,"Signal 6",IF(B17>=Assumptions!B106,"Signal 5",IF(B17>=Assumptions!B105,"Signal 4",IF(B17>=Assumptions!B104,"Signal 3",IF(B17>=Assumptions!B103,"Signal 2",IF(B17>=Assumptions!B102,"Signal 1","Pre-Signal 1")))))) -> Pre-Signal 1 | W17: =ROUND(B17*Assumptions!B137*Assumptions!B138*Assumptions!B139*Assumptions!B136,0) -> 56 | X17: =ROUND(B17*Assumptions!B137*Assumptions!B65,0) -> 9
A18: 13 | B18: =B17*(1+Assumptions!B33) -> 1563.7836 | C18: =ROUND(B18*Assumptions!B25,0) -> 31 | D18: =ROUND(B18*Assumptions!B22,0) -> 2 | E18: =E17+D18-F18 -> 13 | F18: =ROUND(E17*Assumptions!B43,0) -> 1 | G18: =D18-F18 -> 1 | H18: =ROUND(E18*(Assumptions!B15*0.85+Assumptions!B11*0.15),0) -> 149 | I18: =H18 -> 149 | J18: =ROUND(E18*Assumptions!B68,0) -> 46 | K18: =ROUND(J18*Assumptions!B65,0) -> 4 | L18: =Assumptions!B70+IF(E18>Assumptions!B72,45,0) -> 31 | M18: =Assumptions!B76+Assumptions!B77 -> 35 | N18: =Assumptions!B81+Assumptions!B82+Assumptions!B87/12+Assumptions!B84 -> 92 | O18: =ROUND(I18*Assumptions!B85+E18*Assumptions!B86+W18*Assumptions!B85+ROUND(B18*Assumptions!B137*Assumptions!B138*Assumptions!B139,0)*Assumptions!B86,0) -> 11 | P18: =K18+L18+M18+N18+O18+X18 -> 183 | Q18: =I18-P18 -> -34 | R18: =ROUND(B18*Assumptions!B51*Assumptions!B52,0) -> 547 | S18: =I18+R18+W18 -> 757 | T18: =IF(U18<P18*3,0,IF(U18<P18*6,ROUND((Q18+R18+W18)*0.75*Assumptions!B113,0),ROUND((Q18+R18+W18)*0.75*Assumptions!B114,0))) -> 0 | U18: =U17+Q18+R18+W18 -> 322 | V18: =IF(B18>=Assumptions!B107,"Signal 6",IF(B18>=Assumptions!B106,"Signal 5",IF(B18>=Assumptions!B105,"Signal 4",IF(B18>=Assumptions!B104,"Signal 3",IF(B18>=Assumptions!B103,"Signal 2",IF(B18>=Assumptions!B102,"Signal 1","Pre-Signal 1")))))) -> Pre-Signal 1 | W18: =ROUND(B18*Assumptions!B137*Assumptions!B138*Assumptions!B139*Assumptions!B136,0) -> 61 | X18: =ROUND(B18*Assumptions!B137*Assumptions!B65,0) -> 10
A19: 14 | B19: =B18*(1+Assumptions!B33) -> 1688.8863 | C19: =ROUND(B19*Assumptions!B25,0) -> 34 | D19: =ROUND(B19*Assumptions!B22,0) -> 3 | E19: =E18+D19-F19 -> 15 | F19: =ROUND(E18*Assumptions!B43,0) -> 1 | G19: =D19-F19 -> 2 | H19: =ROUND(E19*(Assumptions!B15*0.85+Assumptions!B11*0.15),0) -> 172 | I19: =H19 -> 172 | J19: =ROUND(E19*Assumptions!B68,0) -> 53 | K19: =ROUND(J19*Assumptions!B65,0) -> 4 | L19: =Assumptions!B70+IF(E19>Assumptions!B72,45,0) -> 31 | M19: =Assumptions!B76+Assumptions!B77 -> 35 | N19: =Assumptions!B81+Assumptions!B82+Assumptions!B87/12+Assumptions!B84 -> 92 | O19: =ROUND(I19*Assumptions!B85+E19*Assumptions!B86+W19*Assumptions!B85+ROUND(B19*Assumptions!B137*Assumptions!B138*Assumptions!B139,0)*Assumptions!B86,0) -> 13 | P19: =K19+L19+M19+N19+O19+X19 -> 186 | Q19: =I19-P19 -> -14 | R19: =ROUND(B19*Assumptions!B51*Assumptions!B52,0) -> 591 | S19: =I19+R19+W19 -> 829 | T19: =IF(U19<P19*3,0,IF(U19<P19*6,ROUND((Q19+R19+W19)*0.75*Assumptions!B113,0),ROUND((Q19+R19+W19)*0.75*Assumptions!B114,0))) -> 114 | U19: =U18+Q19+R19+W19 -> 965 | V19: =IF(B19>=Assumptions!B107,"Signal 6",IF(B19>=Assumptions!B106,"Signal 5",IF(B19>=Assumptions!B105,"Signal 4",IF(B19>=Assumptions!B104,"Signal 3",IF(B19>=Assumptions!B103,"Signal 2",IF(B19>=Assumptions!B102,"Signal 1","Pre-Signal 1")))))) -> Pre-Signal 1 | W19: =ROUND(B19*Assumptions!B137*Assumptions!B138*Assumptions!B139*Assumptions!B136,0) -> 66 | X19: =ROUND(B19*Assumptions!B137*Assumptions!B65,0) -> 11
A20: 15 | B20: =B19*(1+Assumptions!B33) -> 1823.9972 | C20: =ROUND(B20*Assumptions!B25,0) -> 36 | D20: =ROUND(B20*Assumptions!B22,0) -> 3 | E20: =E19+D20-F20 -> 17 | F20: =ROUND(E19*Assumptions!B43,0) -> 1 | G20: =D20-F20 -> 2 | H20: =ROUND(E20*(Assumptions!B15*0.85+Assumptions!B11*0.15),0) -> 195 | I20: =H20 -> 195 | J20: =ROUND(E20*Assumptions!B68,0) -> 60 | K20: =ROUND(J20*Assumptions!B65,0) -> 5 | L20: =Assumptions!B70+IF(E20>Assumptions!B72,45,0) -> 31 | M20: =Assumptions!B76+Assumptions!B77 -> 35 | N20: =Assumptions!B81+Assumptions!B82+Assumptions!B87/12+Assumptions!B84 -> 92 | O20: =ROUND(I20*Assumptions!B85+E20*Assumptions!B86+W20*Assumptions!B85+ROUND(B20*Assumptions!B137*Assumptions!B138*Assumptions!B139,0)*Assumptions!B86,0) -> 14 | P20: =K20+L20+M20+N20+O20+X20 -> 189 | Q20: =I20-P20 -> 6 | R20: =ROUND(B20*Assumptions!B51*Assumptions!B52,0) -> 638 | S20: =I20+R20+W20 -> 904 | T20: =IF(U20<P20*3,0,IF(U20<P20*6,ROUND((Q20+R20+W20)*0.75*Assumptions!B113,0),ROUND((Q20+R20+W20)*0.75*Assumptions!B114,0))) -> 205 | U20: =U19+Q20+R20+W20 -> 1680 | V20: =IF(B20>=Assumptions!B107,"Signal 6",IF(B20>=Assumptions!B106,"Signal 5",IF(B20>=Assumptions!B105,"Signal 4",IF(B20>=Assumptions!B104,"Signal 3",IF(B20>=Assumptions!B103,"Signal 2",IF(B20>=Assumptions!B102,"Signal 1","Pre-Signal 1")))))) -> Pre-Signal 1 | W20: =ROUND(B20*Assumptions!B137*Assumptions!B138*Assumptions!B139*Assumptions!B136,0) -> 71 | X20: =ROUND(B20*Assumptions!B137*Assumptions!B65,0) -> 12
A21: 16 | B21: =B20*(1+Assumptions!B33) -> 1969.917 | C21: =ROUND(B21*Assumptions!B25,0) -> 39 | D21: =ROUND(B21*Assumptions!B22,0) -> 3 | E21: =E20+D21-F21 -> 19 | F21: =ROUND(E20*Assumptions!B43,0) -> 1 | G21: =D21-F21 -> 2 | H21: =ROUND(E21*(Assumptions!B15*0.85+Assumptions!B11*0.15),0) -> 218 | I21: =H21 -> 218 | J21: =ROUND(E21*Assumptions!B68,0) -> 67 | K21: =ROUND(J21*Assumptions!B65,0) -> 5 | L21: =Assumptions!B70+IF(E21>Assumptions!B72,45,0) -> 31 | M21: =Assumptions!B76+Assumptions!B77 -> 35 | N21: =Assumptions!B81+Assumptions!B82+Assumptions!B87/12+Assumptions!B84 -> 92 | O21: =ROUND(I21*Assumptions!B85+E21*Assumptions!B86+W21*Assumptions!B85+ROUND(B21*Assumptions!B137*Assumptions!B138*Assumptions!B139,0)*Assumptions!B86,0) -> 16 | P21: =K21+L21+M21+N21+O21+X21 -> 192 | Q21: =I21-P21 -> 26 | R21: =ROUND(B21*Assumptions!B51*Assumptions!B52,0) -> 689 | S21: =I21+R21+W21 -> 984 | T21: =IF(U21<P21*3,0,IF(U21<P21*6,ROUND((Q21+R21+W21)*0.75*Assumptions!B113,0),ROUND((Q21+R21+W21)*0.75*Assumptions!B114,0))) -> 227 | U21: =U20+Q21+R21+W21 -> 2472 | V21: =IF(B21>=Assumptions!B107,"Signal 6",IF(B21>=Assumptions!B106,"Signal 5",IF(B21>=Assumptions!B105,"Signal 4",IF(B21>=Assumptions!B104,"Signal 3",IF(B21>=Assumptions!B103,"Signal 2",IF(B21>=Assumptions!B102,"Signal 1","Pre-Signal 1")))))) -> Pre-Signal 1 | W21: =ROUND(B21*Assumptions!B137*Assumptions!B138*Assumptions!B139*Assumptions!B136,0) -> 77 | X21: =ROUND(B21*Assumptions!B137*Assumptions!B65,0) -> 13
A22: 17 | B22: =B21*(1+Assumptions!B33) -> 2127.5104 | C22: =ROUND(B22*Assumptions!B25,0) -> 43 | D22: =ROUND(B22*Assumptions!B22,0) -> 3 | E22: =E21+D22-F22 -> 20 | F22: =ROUND(E21*Assumptions!B43,0) -> 2 | G22: =D22-F22 -> 1 | H22: =ROUND(E22*(Assumptions!B15*0.85+Assumptions!B11*0.15),0) -> 230 | I22: =H22 -> 230 | J22: =ROUND(E22*Assumptions!B68,0) -> 70 | K22: =ROUND(J22*Assumptions!B65,0) -> 6 | L22: =Assumptions!B70+IF(E22>Assumptions!B72,45,0) -> 31 | M22: =Assumptions!B76+Assumptions!B77 -> 35 | N22: =Assumptions!B81+Assumptions!B82+Assumptions!B87/12+Assumptions!B84 -> 92 | O22: =ROUND(I22*Assumptions!B85+E22*Assumptions!B86+W22*Assumptions!B85+ROUND(B22*Assumptions!B137*Assumptions!B138*Assumptions!B139,0)*Assumptions!B86,0) -> 17 | P22: =K22+L22+M22+N22+O22+X22 -> 195 | Q22: =I22-P22 -> 35 | R22: =ROUND(B22*Assumptions!B51*Assumptions!B52,0) -> 745 | S22: =I22+R22+W22 -> 1058 | T22: =IF(U22<P22*3,0,IF(U22<P22*6,ROUND((Q22+R22+W22)*0.75*Assumptions!B113,0),ROUND((Q22+R22+W22)*0.75*Assumptions!B114,0))) -> 247 | U22: =U21+Q22+R22+W22 -> 3335 | V22: =IF(B22>=Assumptions!B107,"Signal 6",IF(B22>=Assumptions!B106,"Signal 5",IF(B22>=Assumptions!B105,"Signal 4",IF(B22>=Assumptions!B104,"Signal 3",IF(B22>=Assumptions!B103,"Signal 2",IF(B22>=Assumptions!B102,"Signal 1","Pre-Signal 1")))))) -> Pre-Signal 1 | W22: =ROUND(B22*Assumptions!B137*Assumptions!B138*Assumptions!B139*Assumptions!B136,0) -> 83 | X22: =ROUND(B22*Assumptions!B137*Assumptions!B65,0) -> 14
A23: 18 | B23: =B22*(1+Assumptions!B33) -> 2297.7112 | C23: =ROUND(B23*Assumptions!B25,0) -> 46 | D23: =ROUND(B23*Assumptions!B22,0) -> 3 | E23: =E22+D23-F23 -> 21 | F23: =ROUND(E22*Assumptions!B43,0) -> 2 | G23: =D23-F23 -> 1 | H23: =ROUND(E23*(Assumptions!B15*0.85+Assumptions!B11*0.15),0) -> 241 | I23: =H23 -> 241 | J23: =ROUND(E23*Assumptions!B68,0) -> 74 | K23: =ROUND(J23*Assumptions!B65,0) -> 6 | L23: =Assumptions!B70+IF(E23>Assumptions!B72,45,0) -> 31 | M23: =Assumptions!B76+Assumptions!B77 -> 35 | N23: =Assumptions!B81+Assumptions!B82+Assumptions!B87/12+Assumptions!B84 -> 92 | O23: =ROUND(I23*Assumptions!B85+E23*Assumptions!B86+W23*Assumptions!B85+ROUND(B23*Assumptions!B137*Assumptions!B138*Assumptions!B139,0)*Assumptions!B86,0) -> 18 | P23: =K23+L23+M23+N23+O23+X23 -> 197 | Q23: =I23-P23 -> 44 | R23: =ROUND(B23*Assumptions!B51*Assumptions!B52,0) -> 804 | S23: =I23+R23+W23 -> 1135 | T23: =IF(U23<P23*3,0,IF(U23<P23*6,ROUND((Q23+R23+W23)*0.75*Assumptions!B113,0),ROUND((Q23+R23+W23)*0.75*Assumptions!B114,0))) -> 269 | U23: =U22+Q23+R23+W23 -> 4273 | V23: =IF(B23>=Assumptions!B107,"Signal 6",IF(B23>=Assumptions!B106,"Signal 5",IF(B23>=Assumptions!B105,"Signal 4",IF(B23>=Assumptions!B104,"Signal 3",IF(B23>=Assumptions!B103,"Signal 2",IF(B23>=Assumptions!B102,"Signal 1","Pre-Signal 1")))))) -> Pre-Signal 1 | W23: =ROUND(B23*Assumptions!B137*Assumptions!B138*Assumptions!B139*Assumptions!B136,0) -> 90 | X23: =ROUND(B23*Assumptions!B137*Assumptions!B65,0) -> 15
A24: 19 | B24: =B23*(1+Assumptions!B33) -> 2481.5281 | C24: =ROUND(B24*Assumptions!B25,0) -> 50 | D24: =ROUND(B24*Assumptions!B22,0) -> 4 | E24: =E23+D24-F24 -> 23 | F24: =ROUND(E23*Assumptions!B43,0) -> 2 | G24: =D24-F24 -> 2 | H24: =ROUND(E24*(Assumptions!B15*0.85+Assumptions!B11*0.15),0) -> 264 | I24: =H24 -> 264 | J24: =ROUND(E24*Assumptions!B68,0) -> 81 | K24: =ROUND(J24*Assumptions!B65,0) -> 6 | L24: =Assumptions!B70+IF(E24>Assumptions!B72,45,0) -> 31 | M24: =Assumptions!B76+Assumptions!B77 -> 35 | N24: =Assumptions!B81+Assumptions!B82+Assumptions!B87/12+Assumptions!B84 -> 92 | O24: =ROUND(I24*Assumptions!B85+E24*Assumptions!B86+W24*Assumptions!B85+ROUND(B24*Assumptions!B137*Assumptions!B138*Assumptions!B139,0)*Assumptions!B86,0) -> 19 | P24: =K24+L24+M24+N24+O24+X24 -> 199 | Q24: =I24-P24 -> 65 | R24: =ROUND(B24*Assumptions!B51*Assumptions!B52,0) -> 869 | S24: =I24+R24+W24 -> 1230 | T24: =IF(U24<P24*3,0,IF(U24<P24*6,ROUND((Q24+R24+W24)*0.75*Assumptions!B113,0),ROUND((Q24+R24+W24)*0.75*Assumptions!B114,0))) -> 295 | U24: =U23+Q24+R24+W24 -> 5304 | V24: =IF(B24>=Assumptions!B107,"Signal 6",IF(B24>=Assumptions!B106,"Signal 5",IF(B24>=Assumptions!B105,"Signal 4",IF(B24>=Assumptions!B104,"Signal 3",IF(B24>=Assumptions!B103,"Signal 2",IF(B24>=Assumptions!B102,"Signal 1","Pre-Signal 1")))))) -> Pre-Signal 1 | W24: =ROUND(B24*Assumptions!B137*Assumptions!B138*Assumptions!B139*Assumptions!B136,0) -> 97 | X24: =ROUND(B24*Assumptions!B137*Assumptions!B65,0) -> 16
A25: 20 | B25: =B24*(1+Assumptions!B33) -> 2680.0504 | C25: =ROUND(B25*Assumptions!B25,0) -> 54 | D25: =ROUND(B25*Assumptions!B22,0) -> 4 | E25: =E24+D25-F25 -> 25 | F25: =ROUND(E24*Assumptions!B43,0) -> 2 | G25: =D25-F25 -> 2 | H25: =ROUND(E25*(Assumptions!B15*0.85+Assumptions!B11*0.15),0) -> 287 | I25: =H25 -> 287 | J25: =ROUND(E25*Assumptions!B68,0) -> 88 | K25: =ROUND(J25*Assumptions!B65,0) -> 7 | L25: =Assumptions!B70+IF(E25>Assumptions!B72,45,0) -> 31 | M25: =Assumptions!B76+Assumptions!B77 -> 35 | N25: =Assumptions!B81+Assumptions!B82+Assumptions!B87/12+Assumptions!B84 -> 92 | O25: =ROUND(I25*Assumptions!B85+E25*Assumptions!B86+W25*Assumptions!B85+ROUND(B25*Assumptions!B137*Assumptions!B138*Assumptions!B139,0)*Assumptions!B86,0) -> 21 | P25: =K25+L25+M25+N25+O25+X25 -> 203 | Q25: =I25-P25 -> 84 | R25: =ROUND(B25*Assumptions!B51*Assumptions!B52,0) -> 938 | S25: =I25+R25+W25 -> 1330 | T25: =IF(U25<P25*3,0,IF(U25<P25*6,ROUND((Q25+R25+W25)*0.75*Assumptions!B113,0),ROUND((Q25+R25+W25)*0.75*Assumptions!B114,0))) -> 323 | U25: =U24+Q25+R25+W25 -> 6431 | V25: =IF(B25>=Assumptions!B107,"Signal 6",IF(B25>=Assumptions!B106,"Signal 5",IF(B25>=Assumptions!B105,"Signal 4",IF(B25>=Assumptions!B104,"Signal 3",IF(B25>=Assumptions!B103,"Signal 2",IF(B25>=Assumptions!B102,"Signal 1","Pre-Signal 1")))))) -> Pre-Signal 1 | W25: =ROUND(B25*Assumptions!B137*Assumptions!B138*Assumptions!B139*Assumptions!B136,0) -> 105 | X25: =ROUND(B25*Assumptions!B137*Assumptions!B65,0) -> 17
A26: 21 | B26: =B25*(1+Assumptions!B33) -> 2894.4544 | C26: =ROUND(B26*Assumptions!B25,0) -> 58 | D26: =ROUND(B26*Assumptions!B22,0) -> 4 | E26: =E25+D26-F26 -> 27 | F26: =ROUND(E25*Assumptions!B43,0) -> 2 | G26: =D26-F26 -> 2 | H26: =ROUND(E26*(Assumptions!B15*0.85+Assumptions!B11*0.15),0) -> 310 | I26: =H26 -> 310 | J26: =ROUND(E26*Assumptions!B68,0) -> 95 | K26: =ROUND(J26*Assumptions!B65,0) -> 8 | L26: =Assumptions!B70+IF(E26>Assumptions!B72,45,0) -> 31 | M26: =Assumptions!B76+Assumptions!B77 -> 35 | N26: =Assumptions!B81+Assumptions!B82+Assumptions!B87/12+Assumptions!B84 -> 92 | O26: =ROUND(I26*Assumptions!B85+E26*Assumptions!B86+W26*Assumptions!B85+ROUND(B26*Assumptions!B137*Assumptions!B138*Assumptions!B139,0)*Assumptions!B86,0) -> 23 | P26: =K26+L26+M26+N26+O26+X26 -> 208 | Q26: =I26-P26 -> 102 | R26: =ROUND(B26*Assumptions!B51*Assumptions!B52,0) -> 1013 | S26: =I26+R26+W26 -> 1436 | T26: =IF(U26<P26*3,0,IF(U26<P26*6,ROUND((Q26+R26+W26)*0.75*Assumptions!B113,0),ROUND((Q26+R26+W26)*0.75*Assumptions!B114,0))) -> 352 | U26: =U25+Q26+R26+W26 -> 7659 | V26: =IF(B26>=Assumptions!B107,"Signal 6",IF(B26>=Assumptions!B106,"Signal 5",IF(B26>=Assumptions!B105,"Signal 4",IF(B26>=Assumptions!B104,"Signal 3",IF(B26>=Assumptions!B103,"Signal 2",IF(B26>=Assumptions!B102,"Signal 1","Pre-Signal 1")))))) -> Pre-Signal 1 | W26: =ROUND(B26*Assumptions!B137*Assumptions!B138*Assumptions!B139*Assumptions!B136,0) -> 113 | X26: =ROUND(B26*Assumptions!B137*Assumptions!B65,0) -> 19
A27: 22 | B27: =B26*(1+Assumptions!B33) -> 3126.0107 | C27: =ROUND(B27*Assumptions!B25,0) -> 63 | D27: =ROUND(B27*Assumptions!B22,0) -> 5 | E27: =E26+D27-F27 -> 30 | F27: =ROUND(E26*Assumptions!B43,0) -> 2 | G27: =D27-F27 -> 3 | H27: =ROUND(E27*(Assumptions!B15*0.85+Assumptions!B11*0.15),0) -> 344 | I27: =H27 -> 344 | J27: =ROUND(E27*Assumptions!B68,0) -> 105 | K27: =ROUND(J27*Assumptions!B65,0) -> 8 | L27: =Assumptions!B70+IF(E27>Assumptions!B72,45,0) -> 31 | M27: =Assumptions!B76+Assumptions!B77 -> 35 | N27: =Assumptions!B81+Assumptions!B82+Assumptions!B87/12+Assumptions!B84 -> 92 | O27: =ROUND(I27*Assumptions!B85+E27*Assumptions!B86+W27*Assumptions!B85+ROUND(B27*Assumptions!B137*Assumptions!B138*Assumptions!B139,0)*Assumptions!B86,0) -> 25 | P27: =K27+L27+M27+N27+O27+X27 -> 211 | Q27: =I27-P27 -> 133 | R27: =ROUND(B27*Assumptions!B51*Assumptions!B52,0) -> 1094 | S27: =I27+R27+W27 -> 1560 | T27: =IF(U27<P27*3,0,IF(U27<P27*6,ROUND((Q27+R27+W27)*0.75*Assumptions!B113,0),ROUND((Q27+R27+W27)*0.75*Assumptions!B114,0))) -> 386 | U27: =U26+Q27+R27+W27 -> 9008 | V27: =IF(B27>=Assumptions!B107,"Signal 6",IF(B27>=Assumptions!B106,"Signal 5",IF(B27>=Assumptions!B105,"Signal 4",IF(B27>=Assumptions!B104,"Signal 3",IF(B27>=Assumptions!B103,"Signal 2",IF(B27>=Assumptions!B102,"Signal 1","Pre-Signal 1")))))) -> Pre-Signal 1 | W27: =ROUND(B27*Assumptions!B137*Assumptions!B138*Assumptions!B139*Assumptions!B136,0) -> 122 | X27: =ROUND(B27*Assumptions!B137*Assumptions!B65,0) -> 20
A28: 23 | B28: =B27*(1+Assumptions!B33) -> 3376.0916 | C28: =ROUND(B28*Assumptions!B25,0) -> 68 | D28: =ROUND(B28*Assumptions!B22,0) -> 5 | E28: =E27+D28-F28 -> 33 | F28: =ROUND(E27*Assumptions!B43,0) -> 2 | G28: =D28-F28 -> 3 | H28: =ROUND(E28*(Assumptions!B15*0.85+Assumptions!B11*0.15),0) -> 379 | I28: =H28 -> 379 | J28: =ROUND(E28*Assumptions!B68,0) -> 116 | K28: =ROUND(J28*Assumptions!B65,0) -> 9 | L28: =Assumptions!B70+IF(E28>Assumptions!B72,45,0) -> 31 | M28: =Assumptions!B76+Assumptions!B77 -> 35 | N28: =Assumptions!B81+Assumptions!B82+Assumptions!B87/12+Assumptions!B84 -> 92 | O28: =ROUND(I28*Assumptions!B85+E28*Assumptions!B86+W28*Assumptions!B85+ROUND(B28*Assumptions!B137*Assumptions!B138*Assumptions!B139,0)*Assumptions!B86,0) -> 28 | P28: =K28+L28+M28+N28+O28+X28 -> 217 | Q28: =I28-P28 -> 162 | R28: =ROUND(B28*Assumptions!B51*Assumptions!B52,0) -> 1182 | S28: =I28+R28+W28 -> 1693 | T28: =IF(U28<P28*3,0,IF(U28<P28*6,ROUND((Q28+R28+W28)*0.75*Assumptions!B113,0),ROUND((Q28+R28+W28)*0.75*Assumptions!B114,0))) -> 423 | U28: =U27+Q28+R28+W28 -> 10484 | V28: =IF(B28>=Assumptions!B107,"Signal 6",IF(B28>=Assumptions!B106,"Signal 5",IF(B28>=Assumptions!B105,"Signal 4",IF(B28>=Assumptions!B104,"Signal 3",IF(B28>=Assumptions!B103,"Signal 2",IF(B28>=Assumptions!B102,"Signal 1","Pre-Signal 1")))))) -> Pre-Signal 1 | W28: =ROUND(B28*Assumptions!B137*Assumptions!B138*Assumptions!B139*Assumptions!B136,0) -> 132 | X28: =ROUND(B28*Assumptions!B137*Assumptions!B65,0) -> 22
A29: 24 | B29: =B28*(1+Assumptions!B33) -> 3646.1789 | C29: =ROUND(B29*Assumptions!B25,0) -> 73 | D29: =ROUND(B29*Assumptions!B22,0) -> 5 | E29: =E28+D29-F29 -> 35 | F29: =ROUND(E28*Assumptions!B43,0) -> 3 | G29: =D29-F29 -> 2 | H29: =ROUND(E29*(Assumptions!B15*0.85+Assumptions!B11*0.15),0) -> 402 | I29: =H29 -> 402 | J29: =ROUND(E29*Assumptions!B68,0) -> 123 | K29: =ROUND(J29*Assumptions!B65,0) -> 10 | L29: =Assumptions!B70+IF(E29>Assumptions!B72,45,0) -> 31 | M29: =Assumptions!B76+Assumptions!B77 -> 35 | N29: =Assumptions!B81+Assumptions!B82+Assumptions!B87/12+Assumptions!B84 -> 92 | O29: =ROUND(I29*Assumptions!B85+E29*Assumptions!B86+W29*Assumptions!B85+ROUND(B29*Assumptions!B137*Assumptions!B138*Assumptions!B139,0)*Assumptions!B86,0) -> 30 | P29: =K29+L29+M29+N29+O29+X29 -> 221 | Q29: =I29-P29 -> 181 | R29: =ROUND(B29*Assumptions!B51*Assumptions!B52,0) -> 1276 | S29: =I29+R29+W29 -> 1820 | T29: =IF(U29<P29*3,0,IF(U29<P29*6,ROUND((Q29+R29+W29)*0.75*Assumptions!B113,0),ROUND((Q29+R29+W29)*0.75*Assumptions!B114,0))) -> 458 | U29: =U28+Q29+R29+W29 -> 12083 | V29: =IF(B29>=Assumptions!B107,"Signal 6",IF(B29>=Assumptions!B106,"Signal 5",IF(B29>=Assumptions!B105,"Signal 4",IF(B29>=Assumptions!B104,"Signal 3",IF(B29>=Assumptions!B103,"Signal 2",IF(B29>=Assumptions!B102,"Signal 1","Pre-Signal 1")))))) -> Pre-Signal 1 | W29: =ROUND(B29*Assumptions!B137*Assumptions!B138*Assumptions!B139*Assumptions!B136,0) -> 142 | X29: =ROUND(B29*Assumptions!B137*Assumptions!B65,0) -> 23
A30: 25 | B30: =B29*(1+Assumptions!B33) -> 3937.8732 | C30: =ROUND(B30*Assumptions!B25,0) -> 79 | D30: =ROUND(B30*Assumptions!B22,0) -> 6 | E30: =E29+D30-F30 -> 38 | F30: =ROUND(E29*Assumptions!B43,0) -> 3 | G30: =D30-F30 -> 3 | H30: =ROUND(E30*(Assumptions!B15*0.85+Assumptions!B11*0.15),0) -> 436 | I30: =H30 -> 436 | J30: =ROUND(E30*Assumptions!B68,0) -> 133 | K30: =ROUND(J30*Assumptions!B65,0) -> 11 | L30: =Assumptions!B70+IF(E30>Assumptions!B72,45,0) -> 31 | M30: =Assumptions!B76+Assumptions!B77 -> 35 | N30: =Assumptions!B81+Assumptions!B82+Assumptions!B87/12+Assumptions!B84 -> 92 | O30: =ROUND(I30*Assumptions!B85+E30*Assumptions!B86+W30*Assumptions!B85+ROUND(B30*Assumptions!B137*Assumptions!B138*Assumptions!B139,0)*Assumptions!B86,0) -> 32 | P30: =K30+L30+M30+N30+O30+X30 -> 226 | Q30: =I30-P30 -> 210 | R30: =ROUND(B30*Assumptions!B51*Assumptions!B52,0) -> 1378 | S30: =I30+R30+W30 -> 1968 | T30: =IF(U30<P30*3,0,IF(U30<P30*6,ROUND((Q30+R30+W30)*0.75*Assumptions!B113,0),ROUND((Q30+R30+W30)*0.75*Assumptions!B114,0))) -> 499 | U30: =U29+Q30+R30+W30 -> 13825 | V30: =IF(B30>=Assumptions!B107,"Signal 6",IF(B30>=Assumptions!B106,"Signal 5",IF(B30>=Assumptions!B105,"Signal 4",IF(B30>=Assumptions!B104,"Signal 3",IF(B30>=Assumptions!B103,"Signal 2",IF(B30>=Assumptions!B102,"Signal 1","Pre-Signal 1")))))) -> Pre-Signal 1 | W30: =ROUND(B30*Assumptions!B137*Assumptions!B138*Assumptions!B139*Assumptions!B136,0) -> 154 | X30: =ROUND(B30*Assumptions!B137*Assumptions!B65,0) -> 25
A31: 26 | B31: =B30*(1+Assumptions!B33) -> 4252.9031 | C31: =ROUND(B31*Assumptions!B25,0) -> 85 | D31: =ROUND(B31*Assumptions!B22,0) -> 6 | E31: =E30+D31-F31 -> 41 | F31: =ROUND(E30*Assumptions!B43,0) -> 3 | G31: =D31-F31 -> 3 | H31: =ROUND(E31*(Assumptions!B15*0.85+Assumptions!B11*0.15),0) -> 470 | I31: =H31 -> 470 | J31: =ROUND(E31*Assumptions!B68,0) -> 144 | K31: =ROUND(J31*Assumptions!B65,0) -> 12 | L31: =Assumptions!B70+IF(E31>Assumptions!B72,45,0) -> 31 | M31: =Assumptions!B76+Assumptions!B77 -> 35 | N31: =Assumptions!B81+Assumptions!B82+Assumptions!B87/12+Assumptions!B84 -> 92 | O31: =ROUND(I31*Assumptions!B85+E31*Assumptions!B86+W31*Assumptions!B85+ROUND(B31*Assumptions!B137*Assumptions!B138*Assumptions!B139,0)*Assumptions!B86,0) -> 35 | P31: =K31+L31+M31+N31+O31+X31 -> 232 | Q31: =I31-P31 -> 238 | R31: =ROUND(B31*Assumptions!B51*Assumptions!B52,0) -> 1489 | S31: =I31+R31+W31 -> 2125 | T31: =IF(U31<P31*3,0,IF(U31<P31*6,ROUND((Q31+R31+W31)*0.75*Assumptions!B113,0),ROUND((Q31+R31+W31)*0.75*Assumptions!B114,0))) -> 542 | U31: =U30+Q31+R31+W31 -> 15718 | V31: =IF(B31>=Assumptions!B107,"Signal 6",IF(B31>=Assumptions!B106,"Signal 5",IF(B31>=Assumptions!B105,"Signal 4",IF(B31>=Assumptions!B104,"Signal 3",IF(B31>=Assumptions!B103,"Signal 2",IF(B31>=Assumptions!B102,"Signal 1","Pre-Signal 1")))))) -> Pre-Signal 1 | W31: =ROUND(B31*Assumptions!B137*Assumptions!B138*Assumptions!B139*Assumptions!B136,0) -> 166 | X31: =ROUND(B31*Assumptions!B137*Assumptions!B65,0) -> 27
A32: 27 | B32: =B31*(1+Assumptions!B33) -> 4593.1353 | C32: =ROUND(B32*Assumptions!B25,0) -> 92 | D32: =ROUND(B32*Assumptions!B22,0) -> 7 | E32: =E31+D32-F32 -> 45 | F32: =ROUND(E31*Assumptions!B43,0) -> 3 | G32: =D32-F32 -> 4 | H32: =ROUND(E32*(Assumptions!B15*0.85+Assumptions!B11*0.15),0) -> 516 | I32: =H32 -> 516 | J32: =ROUND(E32*Assumptions!B68,0) -> 158 | K32: =ROUND(J32*Assumptions!B65,0) -> 13 | L32: =Assumptions!B70+IF(E32>Assumptions!B72,45,0) -> 31 | M32: =Assumptions!B76+Assumptions!B77 -> 35 | N32: =Assumptions!B81+Assumptions!B82+Assumptions!B87/12+Assumptions!B84 -> 92 | O32: =ROUND(I32*Assumptions!B85+E32*Assumptions!B86+W32*Assumptions!B85+ROUND(B32*Assumptions!B137*Assumptions!B138*Assumptions!B139,0)*Assumptions!B86,0) -> 38 | P32: =K32+L32+M32+N32+O32+X32 -> 238 | Q32: =I32-P32 -> 278 | R32: =ROUND(B32*Assumptions!B51*Assumptions!B52,0) -> 1608 | S32: =I32+R32+W32 -> 2303 | T32: =IF(U32<P32*3,0,IF(U32<P32*6,ROUND((Q32+R32+W32)*0.75*Assumptions!B113,0),ROUND((Q32+R32+W32)*0.75*Assumptions!B114,0))) -> 592 | U32: =U31+Q32+R32+W32 -> 17783 | V32: =IF(B32>=Assumptions!B107,"Signal 6",IF(B32>=Assumptions!B106,"Signal 5",IF(B32>=Assumptions!B105,"Signal 4",IF(B32>=Assumptions!B104,"Signal 3",IF(B32>=Assumptions!B103,"Signal 2",IF(B32>=Assumptions!B102,"Signal 1","Pre-Signal 1")))))) -> Pre-Signal 1 | W32: =ROUND(B32*Assumptions!B137*Assumptions!B138*Assumptions!B139*Assumptions!B136,0) -> 179 | X32: =ROUND(B32*Assumptions!B137*Assumptions!B65,0) -> 29
A33: 28 | B33: =B32*(1+Assumptions!B33) -> 4960.5862 | C33: =ROUND(B33*Assumptions!B25,0) -> 99 | D33: =ROUND(B33*Assumptions!B22,0) -> 7 | E33: =E32+D33-F33 -> 48 | F33: =ROUND(E32*Assumptions!B43,0) -> 4 | G33: =D33-F33 -> 3 | H33: =ROUND(E33*(Assumptions!B15*0.85+Assumptions!B11*0.15),0) -> 551 | I33: =H33 -> 551 | J33: =ROUND(E33*Assumptions!B68,0) -> 168 | K33: =ROUND(J33*Assumptions!B65,0) -> 13 | L33: =Assumptions!B70+IF(E33>Assumptions!B72,45,0) -> 31 | M33: =Assumptions!B76+Assumptions!B77 -> 35 | N33: =Assumptions!B81+Assumptions!B82+Assumptions!B87/12+Assumptions!B84 -> 92 | O33: =ROUND(I33*Assumptions!B85+E33*Assumptions!B86+W33*Assumptions!B85+ROUND(B33*Assumptions!B137*Assumptions!B138*Assumptions!B139,0)*Assumptions!B86,0) -> 40 | P33: =K33+L33+M33+N33+O33+X33 -> 243 | Q33: =I33-P33 -> 308 | R33: =ROUND(B33*Assumptions!B51*Assumptions!B52,0) -> 1736 | S33: =I33+R33+W33 -> 2480 | T33: =IF(U33<P33*3,0,IF(U33<P33*6,ROUND((Q33+R33+W33)*0.75*Assumptions!B113,0),ROUND((Q33+R33+W33)*0.75*Assumptions!B114,0))) -> 641 | U33: =U32+Q33+R33+W33 -> 20020 | V33: =IF(B33>=Assumptions!B107,"Signal 6",IF(B33>=Assumptions!B106,"Signal 5",IF(B33>=Assumptions!B105,"Signal 4",IF(B33>=Assumptions!B104,"Signal 3",IF(B33>=Assumptions!B103,"Signal 2",IF(B33>=Assumptions!B102,"Signal 1","Pre-Signal 1")))))) -> Pre-Signal 1 | W33: =ROUND(B33*Assumptions!B137*Assumptions!B138*Assumptions!B139*Assumptions!B136,0) -> 193 | X33: =ROUND(B33*Assumptions!B137*Assumptions!B65,0) -> 32
A34: 29 | B34: =B33*(1+Assumptions!B33) -> 5357.4331 | C34: =ROUND(B34*Assumptions!B25,0) -> 107 | D34: =ROUND(B34*Assumptions!B22,0) -> 8 | E34: =E33+D34-F34 -> 52 | F34: =ROUND(E33*Assumptions!B43,0) -> 4 | G34: =D34-F34 -> 4 | H34: =ROUND(E34*(Assumptions!B15*0.85+Assumptions!B11*0.15),0) -> 597 | I34: =H34 -> 597 | J34: =ROUND(E34*Assumptions!B68,0) -> 182 | K34: =ROUND(J34*Assumptions!B65,0) -> 15 | L34: =Assumptions!B70+IF(E34>Assumptions!B72,45,0) -> 31 | M34: =Assumptions!B76+Assumptions!B77 -> 35 | N34: =Assumptions!B81+Assumptions!B82+Assumptions!B87/12+Assumptions!B84 -> 92 | O34: =ROUND(I34*Assumptions!B85+E34*Assumptions!B86+W34*Assumptions!B85+ROUND(B34*Assumptions!B137*Assumptions!B138*Assumptions!B139,0)*Assumptions!B86,0) -> 44 | P34: =K34+L34+M34+N34+O34+X34 -> 251 | Q34: =I34-P34 -> 346 | R34: =ROUND(B34*Assumptions!B51*Assumptions!B52,0) -> 1875 | S34: =I34+R34+W34 -> 2681 | T34: =IF(U34<P34*3,0,IF(U34<P34*6,ROUND((Q34+R34+W34)*0.75*Assumptions!B113,0),ROUND((Q34+R34+W34)*0.75*Assumptions!B114,0))) -> 696 | U34: =U33+Q34+R34+W34 -> 22450 | V34: =IF(B34>=Assumptions!B107,"Signal 6",IF(B34>=Assumptions!B106,"Signal 5",IF(B34>=Assumptions!B105,"Signal 4",IF(B34>=Assumptions!B104,"Signal 3",IF(B34>=Assumptions!B103,"Signal 2",IF(B34>=Assumptions!B102,"Signal 1","Pre-Signal 1")))))) -> Pre-Signal 1 | W34: =ROUND(B34*Assumptions!B137*Assumptions!B138*Assumptions!B139*Assumptions!B136,0) -> 209 | X34: =ROUND(B34*Assumptions!B137*Assumptions!B65,0) -> 34
A35: 30 | B35: =B34*(1+Assumptions!B33) -> 5786.0277 | C35: =ROUND(B35*Assumptions!B25,0) -> 116 | D35: =ROUND(B35*Assumptions!B22,0) -> 9 | E35: =E34+D35-F35 -> 57 | F35: =ROUND(E34*Assumptions!B43,0) -> 4 | G35: =D35-F35 -> 5 | H35: =ROUND(E35*(Assumptions!B15*0.85+Assumptions!B11*0.15),0) -> 654 | I35: =H35 -> 654 | J35: =ROUND(E35*Assumptions!B68,0) -> 200 | K35: =ROUND(J35*Assumptions!B65,0) -> 16 | L35: =Assumptions!B70+IF(E35>Assumptions!B72,45,0) -> 31 | M35: =Assumptions!B76+Assumptions!B77 -> 35 | N35: =Assumptions!B81+Assumptions!B82+Assumptions!B87/12+Assumptions!B84 -> 92 | O35: =ROUND(I35*Assumptions!B85+E35*Assumptions!B86+W35*Assumptions!B85+ROUND(B35*Assumptions!B137*Assumptions!B138*Assumptions!B139,0)*Assumptions!B86,0) -> 48 | P35: =K35+L35+M35+N35+O35+X35 -> 259 | Q35: =I35-P35 -> 395 | R35: =ROUND(B35*Assumptions!B51*Assumptions!B52,0) -> 2025 | S35: =I35+R35+W35 -> 2905 | T35: =IF(U35<P35*3,0,IF(U35<P35*6,ROUND((Q35+R35+W35)*0.75*Assumptions!B113,0),ROUND((Q35+R35+W35)*0.75*Assumptions!B114,0))) -> 758 | U35: =U34+Q35+R35+W35 -> 25096 | V35: =IF(B35>=Assumptions!B107,"Signal 6",IF(B35>=Assumptions!B106,"Signal 5",IF(B35>=Assumptions!B105,"Signal 4",IF(B35>=Assumptions!B104,"Signal 3",IF(B35>=Assumptions!B103,"Signal 2",IF(B35>=Assumptions!B102,"Signal 1","Pre-Signal 1")))))) -> Pre-Signal 1 | W35: =ROUND(B35*Assumptions!B137*Assumptions!B138*Assumptions!B139*Assumptions!B136,0) -> 226 | X35: =ROUND(B35*Assumptions!B137*Assumptions!B65,0) -> 37
A36: 31 | B36: =B35*(1+Assumptions!B33) -> 6248.9099 | C36: =ROUND(B36*Assumptions!B25,0) -> 125 | D36: =ROUND(B36*Assumptions!B22,0) -> 9 | E36: =E35+D36-F36 -> 61 | F36: =ROUND(E35*Assumptions!B43,0) -> 5 | G36: =D36-F36 -> 4 | H36: =ROUND(E36*(Assumptions!B15*0.85+Assumptions!B11*0.15),0) -> 700 | I36: =H36 -> 700 | J36: =ROUND(E36*Assumptions!B68,0) -> 214 | K36: =ROUND(J36*Assumptions!B65,0) -> 17 | L36: =Assumptions!B70+IF(E36>Assumptions!B72,45,0) -> 31 | M36: =Assumptions!B76+Assumptions!B77 -> 35 | N36: =Assumptions!B81+Assumptions!B82+Assumptions!B87/12+Assumptions!B84 -> 92 | O36: =ROUND(I36*Assumptions!B85+E36*Assumptions!B86+W36*Assumptions!B85+ROUND(B36*Assumptions!B137*Assumptions!B138*Assumptions!B139,0)*Assumptions!B86,0) -> 51 | P36: =K36+L36+M36+N36+O36+X36 -> 266 | Q36: =I36-P36 -> 434 | R36: =ROUND(B36*Assumptions!B51*Assumptions!B52,0) -> 2187 | S36: =I36+R36+W36 -> 3131 | T36: =IF(U36<P36*3,0,IF(U36<P36*6,ROUND((Q36+R36+W36)*0.75*Assumptions!B113,0),ROUND((Q36+R36+W36)*0.75*Assumptions!B114,0))) -> 821 | U36: =U35+Q36+R36+W36 -> 27961 | V36: =IF(B36>=Assumptions!B107,"Signal 6",IF(B36>=Assumptions!B106,"Signal 5",IF(B36>=Assumptions!B105,"Signal 4",IF(B36>=Assumptions!B104,"Signal 3",IF(B36>=Assumptions!B103,"Signal 2",IF(B36>=Assumptions!B102,"Signal 1","Pre-Signal 1")))))) -> Pre-Signal 1 | W36: =ROUND(B36*Assumptions!B137*Assumptions!B138*Assumptions!B139*Assumptions!B136,0) -> 244 | X36: =ROUND(B36*Assumptions!B137*Assumptions!B65,0) -> 40
A37: 32 | B37: =B36*(1+Assumptions!B33) -> 6748.8227 | C37: =ROUND(B37*Assumptions!B25,0) -> 135 | D37: =ROUND(B37*Assumptions!B22,0) -> 10 | E37: =E36+D37-F37 -> 66 | F37: =ROUND(E36*Assumptions!B43,0) -> 5 | G37: =D37-F37 -> 5 | H37: =ROUND(E37*(Assumptions!B15*0.85+Assumptions!B11*0.15),0) -> 757 | I37: =H37 -> 757 | J37: =ROUND(E37*Assumptions!B68,0) -> 231 | K37: =ROUND(J37*Assumptions!B65,0) -> 18 | L37: =Assumptions!B70+IF(E37>Assumptions!B72,45,0) -> 31 | M37: =Assumptions!B76+Assumptions!B77 -> 35 | N37: =Assumptions!B81+Assumptions!B82+Assumptions!B87/12+Assumptions!B84 -> 92 | O37: =ROUND(I37*Assumptions!B85+E37*Assumptions!B86+W37*Assumptions!B85+ROUND(B37*Assumptions!B137*Assumptions!B138*Assumptions!B139,0)*Assumptions!B86,0) -> 55 | P37: =K37+L37+M37+N37+O37+X37 -> 274 | Q37: =I37-P37 -> 483 | R37: =ROUND(B37*Assumptions!B51*Assumptions!B52,0) -> 2362 | S37: =I37+R37+W37 -> 3382 | T37: =IF(U37<P37*3,0,IF(U37<P37*6,ROUND((Q37+R37+W37)*0.75*Assumptions!B113,0),ROUND((Q37+R37+W37)*0.75*Assumptions!B114,0))) -> 890 | U37: =U36+Q37+R37+W37 -> 31069 | V37: =IF(B37>=Assumptions!B107,"Signal 6",IF(B37>=Assumptions!B106,"Signal 5",IF(B37>=Assumptions!B105,"Signal 4",IF(B37>=Assumptions!B104,"Signal 3",IF(B37>=Assumptions!B103,"Signal 2",IF(B37>=Assumptions!B102,"Signal 1","Pre-Signal 1")))))) -> Pre-Signal 1 | W37: =ROUND(B37*Assumptions!B137*Assumptions!B138*Assumptions!B139*Assumptions!B136,0) -> 263 | X37: =ROUND(B37*Assumptions!B137*Assumptions!B65,0) -> 43
A38: 33 | B38: =B37*(1+Assumptions!B33) -> 7288.7285 | C38: =ROUND(B38*Assumptions!B25,0) -> 146 | D38: =ROUND(B38*Assumptions!B22,0) -> 11 | E38: =E37+D38-F38 -> 72 | F38: =ROUND(E37*Assumptions!B43,0) -> 5 | G38: =D38-F38 -> 6 | H38: =ROUND(E38*(Assumptions!B15*0.85+Assumptions!B11*0.15),0) -> 826 | I38: =H38 -> 826 | J38: =ROUND(E38*Assumptions!B68,0) -> 252 | K38: =ROUND(J38*Assumptions!B65,0) -> 20 | L38: =Assumptions!B70+IF(E38>Assumptions!B72,45,0) -> 31 | M38: =Assumptions!B76+Assumptions!B77 -> 35 | N38: =Assumptions!B81+Assumptions!B82+Assumptions!B87/12+Assumptions!B84 -> 92 | O38: =ROUND(I38*Assumptions!B85+E38*Assumptions!B86+W38*Assumptions!B85+ROUND(B38*Assumptions!B137*Assumptions!B138*Assumptions!B139,0)*Assumptions!B86,0) -> 60 | P38: =K38+L38+M38+N38+O38+X38 -> 285 | Q38: =I38-P38 -> 541 | R38: =ROUND(B38*Assumptions!B51*Assumptions!B52,0) -> 2551 | S38: =I38+R38+W38 -> 3661 | T38: =IF(U38<P38*3,0,IF(U38<P38*6,ROUND((Q38+R38+W38)*0.75*Assumptions!B113,0),ROUND((Q38+R38+W38)*0.75*Assumptions!B114,0))) -> 967 | U38: =U37+Q38+R38+W38 -> 34445 | V38: =IF(B38>=Assumptions!B107,"Signal 6",IF(B38>=Assumptions!B106,"Signal 5",IF(B38>=Assumptions!B105,"Signal 4",IF(B38>=Assumptions!B104,"Signal 3",IF(B38>=Assumptions!B103,"Signal 2",IF(B38>=Assumptions!B102,"Signal 1","Pre-Signal 1")))))) -> Pre-Signal 1 | W38: =ROUND(B38*Assumptions!B137*Assumptions!B138*Assumptions!B139*Assumptions!B136,0) -> 284 | X38: =ROUND(B38*Assumptions!B137*Assumptions!B65,0) -> 47
A39: 34 | B39: =B38*(1+Assumptions!B33) -> 7871.8268 | C39: =ROUND(B39*Assumptions!B25,0) -> 157 | D39: =ROUND(B39*Assumptions!B22,0) -> 12 | E39: =E38+D39-F39 -> 78 | F39: =ROUND(E38*Assumptions!B43,0) -> 6 | G39: =D39-F39 -> 6 | H39: =ROUND(E39*(Assumptions!B15*0.85+Assumptions!B11*0.15),0) -> 895 | I39: =H39 -> 895 | J39: =ROUND(E39*Assumptions!B68,0) -> 273 | K39: =ROUND(J39*Assumptions!B65,0) -> 22 | L39: =Assumptions!B70+IF(E39>Assumptions!B72,45,0) -> 31 | M39: =Assumptions!B76+Assumptions!B77 -> 35 | N39: =Assumptions!B81+Assumptions!B82+Assumptions!B87/12+Assumptions!B84 -> 92 | O39: =ROUND(I39*Assumptions!B85+E39*Assumptions!B86+W39*Assumptions!B85+ROUND(B39*Assumptions!B137*Assumptions!B138*Assumptions!B139,0)*Assumptions!B86,0) -> 65 | P39: =K39+L39+M39+N39+O39+X39 -> 295 | Q39: =I39-P39 -> 600 | R39: =ROUND(B39*Assumptions!B51*Assumptions!B52,0) -> 2755 | S39: =I39+R39+W39 -> 3957 | T39: =IF(U39<P39*3,0,IF(U39<P39*6,ROUND((Q39+R39+W39)*0.75*Assumptions!B113,0),ROUND((Q39+R39+W39)*0.75*Assumptions!B114,0))) -> 1049 | U39: =U38+Q39+R39+W39 -> 38107 | V39: =IF(B39>=Assumptions!B107,"Signal 6",IF(B39>=Assumptions!B106,"Signal 5",IF(B39>=Assumptions!B105,"Signal 4",IF(B39>=Assumptions!B104,"Signal 3",IF(B39>=Assumptions!B103,"Signal 2",IF(B39>=Assumptions!B102,"Signal 1","Pre-Signal 1")))))) -> Pre-Signal 1 | W39: =ROUND(B39*Assumptions!B137*Assumptions!B138*Assumptions!B139*Assumptions!B136,0) -> 307 | X39: =ROUND(B39*Assumptions!B137*Assumptions!B65,0) -> 50
A40: 35 | B40: =B39*(1+Assumptions!B33) -> 8501.573 | C40: =ROUND(B40*Assumptions!B25,0) -> 170 | D40: =ROUND(B40*Assumptions!B22,0) -> 13 | E40: =E39+D40-F40 -> 85 | F40: =ROUND(E39*Assumptions!B43,0) -> 6 | G40: =D40-F40 -> 7 | H40: =ROUND(E40*(Assumptions!B15*0.85+Assumptions!B11*0.15),0) -> 975 | I40: =H40 -> 975 | J40: =ROUND(E40*Assumptions!B68,0) -> 298 | K40: =ROUND(J40*Assumptions!B65,0) -> 24 | L40: =Assumptions!B70+IF(E40>Assumptions!B72,45,0) -> 31 | M40: =Assumptions!B76+Assumptions!B77 -> 35 | N40: =Assumptions!B81+Assumptions!B82+Assumptions!B87/12+Assumptions!B84 -> 92 | O40: =ROUND(I40*Assumptions!B85+E40*Assumptions!B86+W40*Assumptions!B85+ROUND(B40*Assumptions!B137*Assumptions!B138*Assumptions!B139,0)*Assumptions!B86,0) -> 71 | P40: =K40+L40+M40+N40+O40+X40 -> 307 | Q40: =I40-P40 -> 668 | R40: =ROUND(B40*Assumptions!B51*Assumptions!B52,0) -> 2976 | S40: =I40+R40+W40 -> 4283 | T40: =IF(U40<P40*3,0,IF(U40<P40*6,ROUND((Q40+R40+W40)*0.75*Assumptions!B113,0),ROUND((Q40+R40+W40)*0.75*Assumptions!B114,0))) -> 1139 | U40: =U39+Q40+R40+W40 -> 42083 | V40: =IF(B40>=Assumptions!B107,"Signal 6",IF(B40>=Assumptions!B106,"Signal 5",IF(B40>=Assumptions!B105,"Signal 4",IF(B40>=Assumptions!B104,"Signal 3",IF(B40>=Assumptions!B103,"Signal 2",IF(B40>=Assumptions!B102,"Signal 1","Pre-Signal 1")))))) -> Pre-Signal 1 | W40: =ROUND(B40*Assumptions!B137*Assumptions!B138*Assumptions!B139*Assumptions!B136,0) -> 332 | X40: =ROUND(B40*Assumptions!B137*Assumptions!B65,0) -> 54
A41: 36 | B41: =B40*(1+Assumptions!B33) -> 9181.6988 | C41: =ROUND(B41*Assumptions!B25,0) -> 184 | D41: =ROUND(B41*Assumptions!B22,0) -> 14 | E41: =E40+D41-F41 -> 92 | F41: =ROUND(E40*Assumptions!B43,0) -> 7 | G41: =D41-F41 -> 7 | H41: =ROUND(E41*(Assumptions!B15*0.85+Assumptions!B11*0.15),0) -> 1056 | I41: =H41 -> 1056 | J41: =ROUND(E41*Assumptions!B68,0) -> 322 | K41: =ROUND(J41*Assumptions!B65,0) -> 26 | L41: =Assumptions!B70+IF(E41>Assumptions!B72,45,0) -> 31 | M41: =Assumptions!B76+Assumptions!B77 -> 35 | N41: =Assumptions!B81+Assumptions!B82+Assumptions!B87/12+Assumptions!B84 -> 92 | O41: =ROUND(I41*Assumptions!B85+E41*Assumptions!B86+W41*Assumptions!B85+ROUND(B41*Assumptions!B137*Assumptions!B138*Assumptions!B139,0)*Assumptions!B86,0) -> 77 | P41: =K41+L41+M41+N41+O41+X41 -> 320 | Q41: =I41-P41 -> 736 | R41: =ROUND(B41*Assumptions!B51*Assumptions!B52,0) -> 3214 | S41: =I41+R41+W41 -> 4628 | T41: =IF(U41<P41*3,0,IF(U41<P41*6,ROUND((Q41+R41+W41)*0.75*Assumptions!B113,0),ROUND((Q41+R41+W41)*0.75*Assumptions!B114,0))) -> 1234 | U41: =U40+Q41+R41+W41 -> 46391 | V41: =IF(B41>=Assumptions!B107,"Signal 6",IF(B41>=Assumptions!B106,"Signal 5",IF(B41>=Assumptions!B105,"Signal 4",IF(B41>=Assumptions!B104,"Signal 3",IF(B41>=Assumptions!B103,"Signal 2",IF(B41>=Assumptions!B102,"Signal 1","Pre-Signal 1")))))) -> Pre-Signal 1 | W41: =ROUND(B41*Assumptions!B137*Assumptions!B138*Assumptions!B139*Assumptions!B136,0) -> 358 | X41: =ROUND(B41*Assumptions!B137*Assumptions!B65,0) -> 59
...

Sheet Expected
A1: EXPECTED SCENARIO — Expected Growth
A2: 0.25% paid conversion | 12% MoM traffic growth | 6% monthly churn | Referral: 0.1% of visitors x $350 blended
A3: Blue = hardcoded inputs | Black = calculated formulas | Green = Assumptions references
