Workbook

Sheet Dashboard
A1: MyAdvocate Projections v16 — Executive Dashboard
A2: Source: PMP v22 | v16.0 — March 2026 | NEW: YouTube (MA-YT-001) + Instagram (MA-IG-001) revenue streams integrated
A4: KEY METRICS — MONTH 36 | B4: Conservative | C4: Expected | D4: Optimistic
A5: Total Monthly Visitors (incl. YT+IG) | B5: =Conservative!AB41 -> 9590.6988 | C5: =Expected!AB41 -> 52870.702 | D5: =Optimistic!AB41 -> 198893.8
A6: → Organic SEO Visitors | B6: =Conservative!B41 -> 9181.6988 | C6: =Expected!B41 -> 52461.702 | D6: =Optimistic!B41 -> 198484.8
A7: → YT Referral Visitors | B7: =Conservative!Z41 -> 400 | C7: =Expected!Z41 -> 400 | D7: =Optimistic!Z41 -> 400
A8: → IG Direct Visitors | B8: =Conservative!AA41 -> 9 | C8: =Expected!AA41 -> 9 | D8: =Optimistic!AA41 -> 9
A9: Paid Subscribers | B9: =Conservative!E41 -> 99 | C9: =Expected!E41 -> 825 | D9: =Optimistic!E41 -> 6021
A10: MRR ($) | B10: =Conservative!H41 -> 1136 | C10: =Expected!H41 -> 9467 | D10: =Optimistic!H41 -> 69091
A11: Monthly Referral Revenue ($) | B11: =Conservative!R41 -> 3357 | C11: =Expected!R41 -> 18505 | D11: =Optimistic!R41 -> 69613
A12: Per-Case Revenue ($) | B12: =Conservative!W41 -> 374 | C12: =Expected!W41 -> 2062 | D12: =Optimistic!W41 -> 7757
A13: YT AdSense Revenue ($) ▼NEW | B13: =Conservative!AC41 -> 76 | C13: =Expected!AC41 -> 76 | D13: =Optimistic!AC41 -> 76
A14: IG Direct Revenue ($) ▼NEW | B14: =Conservative!AD41 -> 20 | C14: =Expected!AD41 -> 20 | D14: =Optimistic!AD41 -> 20
A15: Total Revenue ($) | B15: =Conservative!S41 -> 4963 | C15: =Expected!S41 -> 30130 | D15: =Optimistic!S41 -> 146557
A16: Owner's Draw ($) | B16: =Conservative!T41 -> 1321 | C16: =Expected!T41 -> 8224 | D16: =Optimistic!T41 -> 39868
A17: Reserve Balance ($) | B17: =Conservative!U41 -> 50924 | C17: =Expected!U41 -> 254020 | D17: =Optimistic!U41 -> 1042634
A18: Traffic Signal | B18: =Conservative!V41 -> Pre-Signal 1 | C18: =Expected!V41 -> Signal 3 | D18: =Optimistic!V41 -> Signal 6
A20: 3-YEAR TOTALS (M1-M36)
A21: 3-Yr Subscription Revenue | B21: =Conservative!I43 -> 13742 | C21: =Expected!I43 -> 84687 | D21: =Optimistic!I43 -> 517537
A22: 3-Yr Referral Revenue | B22: =Conservative!R43 -> 42154 | C22: =Expected!R43 -> 169031 | D22: =Optimistic!R43 -> 528369
A23: 3-Yr Per-Case Revenue | B23: =Conservative!W43 -> 4823 | C23: =Expected!W43 -> 19052 | D23: =Optimistic!W43 -> 59224
A24: 3-Yr YT AdSense Revenue ▼NEW | B24: =Conservative!AC43 -> 1363 | C24: =Expected!AC43 -> 1363 | D24: =Optimistic!AC43 -> 1363
A25: 3-Yr IG Direct Revenue ▼NEW | B25: =Conservative!AD43 -> 155 | C25: =Expected!AD43 -> 155 | D25: =Optimistic!AD43 -> 155
A26: 3-Yr Total Revenue | B26: =Conservative!S43 -> 62237 | C26: =Expected!S43 -> 274288 | D26: =Optimistic!S43 -> 1106648
A28: CONVERSION & GROWTH ASSUMPTIONS
B29: Conservative | C29: Expected | D29: Optimistic
A30: Paid Conversion Rate | B30: =Assumptions!B22 -> 0.0015 | C30: =Assumptions!B23 -> 0.0025 | D30: =Assumptions!B24 -> 0.005
A31: Monthly Traffic Growth | B31: =Assumptions!B33 -> 0.08 | C31: =Assumptions!B34 -> 0.12 | D31: =Assumptions!B35 -> 0.15
A32: Monthly Churn | B32: =Assumptions!B43 -> 0.08 | C32: =Assumptions!B44 -> 0.06 | D32: =Assumptions!B45 -> 0.04
A33: Per-Case Price | B33: =Assumptions!B136 -> 13 | C33: =Assumptions!B136 -> 13 | D33: =Assumptions!B136 -> 13
A34: Tool Engagement Rate | B34: =Assumptions!B137 -> 0.08 | C34: =Assumptions!B137 -> 0.08 | D34: =Assumptions!B137 -> 0.08
A35: EN AdSense CPM | B35: =Assumptions!B146 -> 8 | C35: =Assumptions!B146 -> 8 | D35: =Assumptions!B146 -> 8
A36: IG Bio Link CTR | B36: =Assumptions!B166 -> 0.003 | C36: =Assumptions!B166 -> 0.003 | D36: =Assumptions!B166 -> 0.003

Sheet Assumptions
A1: MyAdvocate Financial Model v16 — Assumptions
A2: Source: PMP v22 | Blue = input (user-editable) | Black = calculated | Green = cross-sheet link
A3: Version: v16.0 — March 2026 | Scenarios: Conservative / Expected / Optimistic | NEW v16: YouTube (MA-YT-001) + Instagram (MA-IG-001)
A5: CORE BUSINESS ASSUMPTIONS
A6: Launch Month | B6: 1 | C6: Month 1 = Launch
A7: Planning Horizon (months) | B7: 36 | C7: 3-year projection
A9: PRICING STRUCTURE
A10: Founding Advocate Annual Price | B10: 34 | C10: $34/year — first 250 subs, locked forever
A11: Founding Advocate Monthly Equivalent | B11: =B10/12 -> 2.8333333 | C11: $34/12 — for MRR calculation purposes
A12: Founding Advocate Renewal Price (Year 2+) | B12: 55 | C12: $55/yr — permanent FA rate after Year 1 lock
A13: FA Cohort Cap | B13: 250 | C13: Maximum Founding Advocates — hard cap
A14: Basic Tier Monthly | B14: 8 | C14: Launch tier — all new subs Months 1–8
A15: Standard Tier Monthly (Month 9+) | B15: 13 | C15: Price increase Month 9 — new subs only
A16: Advocate Builder Quarterly | B16: 21 | C16: $21/quarter — alternative entry point
A17: Advocate Builder Monthly Equivalent | B17: =B16/3 -> 7 | C17: $21/3 — for MRR purposes
A18: Annual Standard Price | B18: 55 | C18: $55/yr for committed annual subscribers
A19: Premium Monthly (Phase 4+) | B19: 21 | C19: Native app tier — Phase 4 unlock
A21: CONVERSION RATES — HEALTHCARE COLD TRAFFIC
A22: Conservative Paid Conversion Rate | B22: 0.0015 | C22: 0.15% — cold traffic baseline. Source: PMP v22 §3
A23: Expected Paid Conversion Rate | B23: 0.0025 | C23: 0.25% — moderate, denial-code SEO boost
A24: Optimistic Paid Conversion Rate | B24: 0.005 | C24: 0.50% — high-intent denial code + SEO optimization
A25: Free Signup / Email Capture Rate | B25: 0.02 | C25: 2.0% of total visitors — owned email list growth
A26: Denial Decoder Free-to-Paid Lift | B26: 1.15 | C26: 15% higher conversion from denial code page visitors
A27: Founding Advocate Conversion Rate (of early subs) | B27: 0.4 | C27: ~40% of first subs take the FA offer
A29: SEO TRAFFIC GROWTH MODEL
A30: Month 1 Traffic — Conservative | B30: 500 | C30: Minimal launch, no prior SEO momentum
A31: Month 1 Traffic — Expected | B31: 800 | C31: Early SEO content live at launch
A32: Month 1 Traffic — Optimistic | B32: 1200 | C32: Aggressive pre-launch content build
A33: Monthly Traffic Growth — Conservative | B33: 0.08 | C33: 8% MoM — slow organic compounding
A34: Monthly Traffic Growth — Expected | B34: 0.12 | C34: 12% MoM — consistent 2x/week publishing
A35: Monthly Traffic Growth — Optimistic | B35: 0.15 | C35: 15% MoM — aggressive SEO + denial codes indexing fast
A36: Denial Code Program Traffic Boost (Month 3+) | B36: 1.15 | C36: 15% additional traffic lift from 200+ denial code pages indexing
A37: Content Cluster Maturity Boost (Month 6+) | B37: 1.08 | C37: 8% additional lift as pillar/cluster architecture matures
A38: Publishing Cadence (articles/week) | B38: 2 | C38: 2x/week per PMP v22 §4C — sustained from Month 1
A39: Denial Code Pages (Month 3 launch) | B39: 200 | C39: 200 denial code pages built — one-time SEO asset
A40: Month 12 Cumulative Articles Target | B40: 60 | C40: ~2x/week × 26 weeks = ~52 articles + backlog
A42: CHURN & RETENTION
A43: Monthly Churn — Conservative | B43: 0.08 | C43: 8% monthly churn — challenging retention environment
A44: Monthly Churn — Expected | B44: 0.06 | C44: 6% monthly churn — decent product-market fit
A45: Monthly Churn — Optimistic | B45: 0.04 | C45: 4% monthly churn — strong engagement, content value
...

Sheet Conservative
A1: CONSERVATIVE SCENARIO — Conservative Growth
A2: 0.15% paid conversion | 8% MoM traffic growth | 8% monthly churn | Referral: 0.1% of total visitors x $350 blended
A3: Blue = hardcoded inputs | Black = calculated formulas | Green = Assumptions references | ▼ = NEW v16 columns (YT+IG integration)
A5: Month | B5: Organic Visitors | C5: Free Signups (Email 2%) | D5: New Paid Subs | E5: Total Paid Subs | F5: Churn This Month | G5: Net New Subs | H5: MRR ($) | I5: Monthly Revenue ($) | J5: Letter Gens | K5: API Costs ($) | L5: Infra ($) | M5: Content/ SEO ($) | N5: n8n+Tools ($) | O5: Stripe Fees ($) | P5: Total Costs ($) | Q5: Gross Profit ($) | R5: Referral Revenue ($) | S5: Total Revenue ($) | T5: Owner's Draw ($) | U5: Reserve Balance ($) | V5: Traffic Signal | W5: Per-Case Revenue ($) | X5: Free Tier API Cost ($) | Y5: IG Followers ▼ | Z5: YT Referral Visitors ▼ | AA5: IG Direct Visitors ▼ | AB5: TOTAL Visitors ▼ | AC5: YT AdSense Revenue ($) ▼ | AD5: IG Direct Revenue ($) ▼
A6: 1 | B6: =Assumptions!B30 -> 500 | C6: =ROUND(AB6*Assumptions!B25,0) -> 10 | D6: =ROUND(AB6*Assumptions!B22,0) -> 1 | E6: =D6 -> 1 | F6: =0 -> 0 | G6: =D6-F6 -> 1 | H6: =ROUND(E6*Assumptions!B14,0) -> 8 | I6: =H6 -> 8 | J6: =ROUND(E6*Assumptions!B68,0) -> 4 | K6: =ROUND(J6*Assumptions!B65,0) -> 0 | L6: =Assumptions!B70+IF(E6>Assumptions!B72,45,0) -> 31 | M6: =Assumptions!B94+Assumptions!B95+Assumptions!B76+Assumptions!B77 -> 2785 | N6: =Assumptions!B81+Assumptions!B82+Assumptions!B87/12 -> 50 | O6: =ROUND(I6*Assumptions!B85+E6*Assumptions!B86+W6*Assumptions!B85+ROUND(AB6*Assumptions!B137*Assumptions!B138*Assumptions!B139,0)*Assumptions!B86,0) -> 2 | P6: =K6+L6+M6+N6+O6+X6 -> 2871 | Q6: =I6-P6 -> -2863 | R6: =0 -> 0 | S6: =I6+R6+W6+AC6+AD6 -> 28 | T6: =IF(U6<P6*3,0,IF(U6<P6*6,ROUND((Q6+R6+W6+AC6+AD6)*0.75*Assumptions!B113,0),ROUND((Q6+R6+W6+AC6+AD6)*0.75*Assumptions!B114,0))) -> 0 | U6: =Q6+R6+W6+AC6+AD6 -> -2843 | V6: =IF(AB6>=Assumptions!B107,"Signal 6",IF(AB6>=Assumptions!B106,"Signal 5",IF(AB6>=Assumptions!B105,"Signal 4",IF(AB6>=Assumptions!B104,"Signal 3",IF(AB6>=Assumptions!B103,"Signal 2",IF(AB6>=Assumptions!B102,"Signal 1","Pre-Signal 1")))))) -> Pre-Signal 1 | W6: =ROUND(AB6*Assumptions!B137*Assumptions!B138*Assumptions!B139*Assumptions!B136,0) -> 20 | X6: =ROUND(AB6*Assumptions!B137*Assumptions!B65,0) -> 3 | Y6: =Assumptions!B162 -> 50 | Z6: =Assumptions!B153 -> 0 | AA6: =ROUND(Y6*Assumptions!B166,0) -> 0 | AB6: =B6+Z6+AA6 -> 500 | AC6: =ROUND(IF(A6>=Assumptions!B144,(IF(A6>=25,Assumptions!B151,IF(A6>=16,Assumptions!B150,Assumptions!B149))/1000*Assumptions!B146)+IF(A6>=Assumptions!B145,(IF(A6>=25,Assumptions!B151,IF(A6>=16,Assumptions!B150,Assumptions!B149))*Assumptions!B152/1000*Assumptions!B147),0),0),0) -> 0 | AD6: =IF(Y6>=10000,Assumptions!B170,IF(Y6>=5000,Assumptions!B169,IF(Y6>=2000,Assumptions!B168,IF(Y6>=500,Assumptions!B167,0)))) -> 0
A7: 2 | B7: =B6*(1+Assumptions!B33) -> 540 | C7: =ROUND(AB7*Assumptions!B25,0) -> 11 | D7: =ROUND(AB7*Assumptions!B22,0) -> 1 | E7: =E6+D7-F7 -> 2 | F7: =ROUND(E6*Assumptions!B43,0) -> 0 | G7: =D7-F7 -> 1 | H7: =ROUND(E7*Assumptions!B14,0) -> 16 | I7: =H7 -> 16 | J7: =ROUND(E7*Assumptions!B68,0) -> 7 | K7: =ROUND(J7*Assumptions!B65,0) -> 1 | L7: =Assumptions!B70+IF(E7>Assumptions!B72,45,0) -> 31 | M7: =Assumptions!B76+Assumptions!B77 -> 35 | N7: =Assumptions!B81+Assumptions!B82+Assumptions!B87/12 -> 50 | O7: =ROUND(I7*Assumptions!B85+E7*Assumptions!B86+W7*Assumptions!B85+ROUND(AB7*Assumptions!B137*Assumptions!B138*Assumptions!B139,0)*Assumptions!B86,0) -> 2 | P7: =K7+L7+M7+N7+O7+X7 -> 122 | Q7: =I7-P7 -> -106 | R7: =0 -> 0 | S7: =I7+R7+W7+AC7+AD7 -> 37 | T7: =IF(U7<P7*3,0,IF(U7<P7*6,ROUND((Q7+R7+W7+AC7+AD7)*0.75*Assumptions!B113,0),ROUND((Q7+R7+W7+AC7+AD7)*0.75*Assumptions!B114,0))) -> 0 | U7: =U6+Q7+R7+W7+AC7+AD7 -> -2928 | V7: =IF(AB7>=Assumptions!B107,"Signal 6",IF(AB7>=Assumptions!B106,"Signal 5",IF(AB7>=Assumptions!B105,"Signal 4",IF(AB7>=Assumptions!B104,"Signal 3",IF(AB7>=Assumptions!B103,"Signal 2",IF(AB7>=Assumptions!B102,"Signal 1","Pre-Signal 1")))))) -> Pre-Signal 1 | W7: =ROUND(AB7*Assumptions!B137*Assumptions!B138*Assumptions!B139*Assumptions!B136,0) -> 21 | X7: =ROUND(AB7*Assumptions!B137*Assumptions!B65,0) -> 3 | Y7: =ROUND(Y6*(1+Assumptions!B163),0) -> 60 | Z7: =Assumptions!B153 -> 0 | AA7: =ROUND(Y7*Assumptions!B166,0) -> 0 | AB7: =B7+Z7+AA7 -> 540 | AC7: =ROUND(IF(A7>=Assumptions!B144,(IF(A7>=25,Assumptions!B151,IF(A7>=16,Assumptions!B150,Assumptions!B149))/1000*Assumptions!B146)+IF(A7>=Assumptions!B145,(IF(A7>=25,Assumptions!B151,IF(A7>=16,Assumptions!B150,Assumptions!B149))*Assumptions!B152/1000*Assumptions!B147),0),0),0) -> 0 | AD7: =IF(Y7>=10000,Assumptions!B170,IF(Y7>=5000,Assumptions!B169,IF(Y7>=2000,Assumptions!B168,IF(Y7>=500,Assumptions!B167,0)))) -> 0
A8: 3 | B8: =B7*(1+Assumptions!B33)*Assumptions!B36 -> 670.68 | C8: =ROUND(AB8*Assumptions!B25,0) -> 13 | D8: =ROUND(AB8*Assumptions!B22,0) -> 1 | E8: =E7+D8-F8 -> 3 | F8: =ROUND(E7*Assumptions!B43,0) -> 0 | G8: =D8-F8 -> 1 | H8: =ROUND(E8*Assumptions!B14,0) -> 24 | I8: =H8 -> 24 | J8: =ROUND(E8*Assumptions!B68,0) -> 11 | K8: =ROUND(J8*Assumptions!B65,0) -> 1 | L8: =Assumptions!B70+IF(E8>Assumptions!B72,45,0) -> 31 | M8: =Assumptions!B76+Assumptions!B77 -> 35 | N8: =Assumptions!B81+Assumptions!B82+Assumptions!B87/12+Assumptions!B148 -> 116 | O8: =ROUND(I8*Assumptions!B85+E8*Assumptions!B86+W8*Assumptions!B85+ROUND(AB8*Assumptions!B137*Assumptions!B138*Assumptions!B139,0)*Assumptions!B86,0) -> 3 | P8: =K8+L8+M8+N8+O8+X8 -> 190 | Q8: =I8-P8 -> -166 | R8: =0 -> 0 | S8: =I8+R8+W8+AC8+AD8 -> 50 | T8: =IF(U8<P8*3,0,IF(U8<P8*6,ROUND((Q8+R8+W8+AC8+AD8)*0.75*Assumptions!B113,0),ROUND((Q8+R8+W8+AC8+AD8)*0.75*Assumptions!B114,0))) -> 0 | U8: =U7+Q8+R8+W8+AC8+AD8 -> -3068 | V8: =IF(AB8>=Assumptions!B107,"Signal 6",IF(AB8>=Assumptions!B106,"Signal 5",IF(AB8>=Assumptions!B105,"Signal 4",IF(AB8>=Assumptions!B104,"Signal 3",IF(AB8>=Assumptions!B103,"Signal 2",IF(AB8>=Assumptions!B102,"Signal 1","Pre-Signal 1")))))) -> Pre-Signal 1 | W8: =ROUND(AB8*Assumptions!B137*Assumptions!B138*Assumptions!B139*Assumptions!B136,0) -> 26 | X8: =ROUND(AB8*Assumptions!B137*Assumptions!B65,0) -> 4 | Y8: =ROUND(Y7*(1+Assumptions!B163),0) -> 72 | Z8: =Assumptions!B153 -> 0 | AA8: =ROUND(Y8*Assumptions!B166,0) -> 0 | AB8: =B8+Z8+AA8 -> 670.68 | AC8: =ROUND(IF(A8>=Assumptions!B144,(IF(A8>=25,Assumptions!B151,IF(A8>=16,Assumptions!B150,Assumptions!B149))/1000*Assumptions!B146)+IF(A8>=Assumptions!B145,(IF(A8>=25,Assumptions!B151,IF(A8>=16,Assumptions!B150,Assumptions!B149))*Assumptions!B152/1000*Assumptions!B147),0),0),0) -> 0 | AD8: =IF(Y8>=10000,Assumptions!B170,IF(Y8>=5000,Assumptions!B169,IF(Y8>=2000,Assumptions!B168,IF(Y8>=500,Assumptions!B167,0)))) -> 0
A9: 4 | B9: =B8*(1+Assumptions!B33) -> 724.3344 | C9: =ROUND(AB9*Assumptions!B25,0) -> 14 | D9: =ROUND(AB9*Assumptions!B22,0) -> 1 | E9: =E8+D9-F9 -> 4 | F9: =ROUND(E8*Assumptions!B43,0) -> 0 | G9: =D9-F9 -> 1 | H9: =ROUND(E9*Assumptions!B14,0) -> 32 | I9: =H9 -> 32 | J9: =ROUND(E9*Assumptions!B68,0) -> 14 | K9: =ROUND(J9*Assumptions!B65,0) -> 1 | L9: =Assumptions!B70+IF(E9>Assumptions!B72,45,0) -> 31 | M9: =Assumptions!B76+Assumptions!B77 -> 35 | N9: =Assumptions!B81+Assumptions!B82+Assumptions!B87/12+Assumptions!B148 -> 116 | O9: =ROUND(I9*Assumptions!B85+E9*Assumptions!B86+W9*Assumptions!B85+ROUND(AB9*Assumptions!B137*Assumptions!B138*Assumptions!B139,0)*Assumptions!B86,0) -> 4 | P9: =K9+L9+M9+N9+O9+X9 -> 192 | Q9: =I9-P9 -> -160 | R9: =0 -> 0 | S9: =I9+R9+W9+AC9+AD9 -> 60 | T9: =IF(U9<P9*3,0,IF(U9<P9*6,ROUND((Q9+R9+W9+AC9+AD9)*0.75*Assumptions!B113,0),ROUND((Q9+R9+W9+AC9+AD9)*0.75*Assumptions!B114,0))) -> 0 | U9: =U8+Q9+R9+W9+AC9+AD9 -> -3200 | V9: =IF(AB9>=Assumptions!B107,"Signal 6",IF(AB9>=Assumptions!B106,"Signal 5",IF(AB9>=Assumptions!B105,"Signal 4",IF(AB9>=Assumptions!B104,"Signal 3",IF(AB9>=Assumptions!B103,"Signal 2",IF(AB9>=Assumptions!B102,"Signal 1","Pre-Signal 1")))))) -> Pre-Signal 1 | W9: =ROUND(AB9*Assumptions!B137*Assumptions!B138*Assumptions!B139*Assumptions!B136,0) -> 28 | X9: =ROUND(AB9*Assumptions!B137*Assumptions!B65,0) -> 5 | Y9: =ROUND(Y8*(1+Assumptions!B163),0) -> 86 | Z9: =Assumptions!B153 -> 0 | AA9: =ROUND(Y9*Assumptions!B166,0) -> 0 | AB9: =B9+Z9+AA9 -> 724.3344 | AC9: =ROUND(IF(A9>=Assumptions!B144,(IF(A9>=25,Assumptions!B151,IF(A9>=16,Assumptions!B150,Assumptions!B149))/1000*Assumptions!B146)+IF(A9>=Assumptions!B145,(IF(A9>=25,Assumptions!B151,IF(A9>=16,Assumptions!B150,Assumptions!B149))*Assumptions!B152/1000*Assumptions!B147),0),0),0) -> 0 | AD9: =IF(Y9>=10000,Assumptions!B170,IF(Y9>=5000,Assumptions!B169,IF(Y9>=2000,Assumptions!B168,IF(Y9>=500,Assumptions!B167,0)))) -> 0
A10: 5 | B10: =B9*(1+Assumptions!B33) -> 782.28115 | C10: =ROUND(AB10*Assumptions!B25,0) -> 16 | D10: =ROUND(AB10*Assumptions!B22,0) -> 1 | E10: =E9+D10-F10 -> 5 | F10: =ROUND(E9*Assumptions!B43,0) -> 0 | G10: =D10-F10 -> 1 | H10: =ROUND(E10*Assumptions!B14,0) -> 40 | I10: =H10 -> 40 | J10: =ROUND(E10*Assumptions!B68,0) -> 18 | K10: =ROUND(J10*Assumptions!B65,0) -> 1 | L10: =Assumptions!B70+IF(E10>Assumptions!B72,45,0) -> 31 | M10: =Assumptions!B76+Assumptions!B77 -> 35 | N10: =Assumptions!B81+Assumptions!B82+Assumptions!B87/12+Assumptions!B148 -> 116 | O10: =ROUND(I10*Assumptions!B85+E10*Assumptions!B86+W10*Assumptions!B85+ROUND(AB10*Assumptions!B137*Assumptions!B138*Assumptions!B139,0)*Assumptions!B86,0) -> 4 | P10: =K10+L10+M10+N10+O10+X10 -> 192 | Q10: =I10-P10 -> -152 | R10: =0 -> 0 | S10: =I10+R10+W10+AC10+AD10 -> 71 | T10: =IF(U10<P10*3,0,IF(U10<P10*6,ROUND((Q10+R10+W10+AC10+AD10)*0.75*Assumptions!B113,0),ROUND((Q10+R10+W10+AC10+AD10)*0.75*Assumptions!B114,0))) -> 0 | U10: =U9+Q10+R10+W10+AC10+AD10 -> -3321 | V10: =IF(AB10>=Assumptions!B107,"Signal 6",IF(AB10>=Assumptions!B106,"Signal 5",IF(AB10>=Assumptions!B105,"Signal 4",IF(AB10>=Assumptions!B104,"Signal 3",IF(AB10>=Assumptions!B103,"Signal 2",IF(AB10>=Assumptions!B102,"Signal 1","Pre-Signal 1")))))) -> Pre-Signal 1 | W10: =ROUND(AB10*Assumptions!B137*Assumptions!B138*Assumptions!B139*Assumptions!B136,0) -> 31 | X10: =ROUND(AB10*Assumptions!B137*Assumptions!B65,0) -> 5 | Y10: =ROUND(Y9*(1+Assumptions!B163),0) -> 103 | Z10: =Assumptions!B153 -> 0 | AA10: =ROUND(Y10*Assumptions!B166,0) -> 0 | AB10: =B10+Z10+AA10 -> 782.28115 | AC10: =ROUND(IF(A10>=Assumptions!B144,(IF(A10>=25,Assumptions!B151,IF(A10>=16,Assumptions!B150,Assumptions!B149))/1000*Assumptions!B146)+IF(A10>=Assumptions!B145,(IF(A10>=25,Assumptions!B151,IF(A10>=16,Assumptions!B150,Assumptions!B149))*Assumptions!B152/1000*Assumptions!B147),0),0),0) -> 0 | AD10: =IF(Y10>=10000,Assumptions!B170,IF(Y10>=5000,Assumptions!B169,IF(Y10>=2000,Assumptions!B168,IF(Y10>=500,Assumptions!B167,0)))) -> 0
A11: 6 | B11: =B10*(1+Assumptions!B33)*Assumptions!B37 -> 912.45274 | C11: =ROUND(AB11*Assumptions!B25,0) -> 19 | D11: =ROUND(AB11*Assumptions!B22,0) -> 1 | E11: =E10+D11-F11 -> 6 | F11: =ROUND(E10*Assumptions!B43,0) -> 0 | G11: =D11-F11 -> 1 | H11: =ROUND(E11*Assumptions!B14,0) -> 48 | I11: =H11 -> 48 | J11: =ROUND(E11*Assumptions!B68,0) -> 21 | K11: =ROUND(J11*Assumptions!B65,0) -> 2 | L11: =Assumptions!B70+IF(E11>Assumptions!B72,45,0) -> 31 | M11: =Assumptions!B76+Assumptions!B77 -> 35 | N11: =Assumptions!B81+Assumptions!B82+Assumptions!B87/12+Assumptions!B148 -> 116 | O11: =ROUND(I11*Assumptions!B85+E11*Assumptions!B86+W11*Assumptions!B85+ROUND(AB11*Assumptions!B137*Assumptions!B138*Assumptions!B139,0)*Assumptions!B86,0) -> 5 | P11: =K11+L11+M11+N11+O11+X11 -> 195 | Q11: =I11-P11 -> -147 | R11: =ROUND(AB11*Assumptions!B51*Assumptions!B52,0) -> 328 | S11: =I11+R11+W11+AC11+AD11 -> 413 | T11: =IF(U11<P11*3,0,IF(U11<P11*6,ROUND((Q11+R11+W11+AC11+AD11)*0.75*Assumptions!B113,0),ROUND((Q11+R11+W11+AC11+AD11)*0.75*Assumptions!B114,0))) -> 0 | U11: =U10+Q11+R11+W11+AC11+AD11 -> -3103 | V11: =IF(AB11>=Assumptions!B107,"Signal 6",IF(AB11>=Assumptions!B106,"Signal 5",IF(AB11>=Assumptions!B105,"Signal 4",IF(AB11>=Assumptions!B104,"Signal 3",IF(AB11>=Assumptions!B103,"Signal 2",IF(AB11>=Assumptions!B102,"Signal 1","Pre-Signal 1")))))) -> Pre-Signal 1 | W11: =ROUND(AB11*Assumptions!B137*Assumptions!B138*Assumptions!B139*Assumptions!B136,0) -> 37 | X11: =ROUND(AB11*Assumptions!B137*Assumptions!B65,0) -> 6 | Y11: =ROUND(Y10*(1+Assumptions!B163),0) -> 124 | Z11: =Assumptions!B154 -> 25 | AA11: =ROUND(Y11*Assumptions!B166,0) -> 0 | AB11: =B11+Z11+AA11 -> 937.45274 | AC11: =ROUND(IF(A11>=Assumptions!B144,(IF(A11>=25,Assumptions!B151,IF(A11>=16,Assumptions!B150,Assumptions!B149))/1000*Assumptions!B146)+IF(A11>=Assumptions!B145,(IF(A11>=25,Assumptions!B151,IF(A11>=16,Assumptions!B150,Assumptions!B149))*Assumptions!B152/1000*Assumptions!B147),0),0),0) -> 0 | AD11: =IF(Y11>=10000,Assumptions!B170,IF(Y11>=5000,Assumptions!B169,IF(Y11>=2000,Assumptions!B168,IF(Y11>=500,Assumptions!B167,0)))) -> 0
A12: 7 | B12: =B11*(1+Assumptions!B33) -> 985.44895 | C12: =ROUND(AB12*Assumptions!B25,0) -> 20 | D12: =ROUND(AB12*Assumptions!B22,0) -> 2 | E12: =E11+D12-F12 -> 8 | F12: =ROUND(E11*Assumptions!B43,0) -> 0 | G12: =D12-F12 -> 2 | H12: =ROUND(E12*Assumptions!B14,0) -> 64 | I12: =H12 -> 64 | J12: =ROUND(E12*Assumptions!B68,0) -> 28 | K12: =ROUND(J12*Assumptions!B65,0) -> 2 | L12: =Assumptions!B70+IF(E12>Assumptions!B72,45,0) -> 31 | M12: =Assumptions!B76+Assumptions!B77 -> 35 | N12: =Assumptions!B81+Assumptions!B82+Assumptions!B87/12+Assumptions!B148 -> 116 | O12: =ROUND(I12*Assumptions!B85+E12*Assumptions!B86+W12*Assumptions!B85+ROUND(AB12*Assumptions!B137*Assumptions!B138*Assumptions!B139,0)*Assumptions!B86,0) -> 6 | P12: =K12+L12+M12+N12+O12+X12 -> 196 | Q12: =I12-P12 -> -132 | R12: =ROUND(AB12*Assumptions!B51*Assumptions!B52,0) -> 354 | S12: =I12+R12+W12+AC12+AD12 -> 457 | T12: =IF(U12<P12*3,0,IF(U12<P12*6,ROUND((Q12+R12+W12+AC12+AD12)*0.75*Assumptions!B113,0),ROUND((Q12+R12+W12+AC12+AD12)*0.75*Assumptions!B114,0))) -> 0 | U12: =U11+Q12+R12+W12+AC12+AD12 -> -2842 | V12: =IF(AB12>=Assumptions!B107,"Signal 6",IF(AB12>=Assumptions!B106,"Signal 5",IF(AB12>=Assumptions!B105,"Signal 4",IF(AB12>=Assumptions!B104,"Signal 3",IF(AB12>=Assumptions!B103,"Signal 2",IF(AB12>=Assumptions!B102,"Signal 1","Pre-Signal 1")))))) -> Pre-Signal 1 | W12: =ROUND(AB12*Assumptions!B137*Assumptions!B138*Assumptions!B139*Assumptions!B136,0) -> 39 | X12: =ROUND(AB12*Assumptions!B137*Assumptions!B65,0) -> 6 | Y12: =ROUND(Y11*(1+Assumptions!B164),0) -> 143 | Z12: =Assumptions!B154 -> 25 | AA12: =ROUND(Y12*Assumptions!B166,0) -> 0 | AB12: =B12+Z12+AA12 -> 1010.449 | AC12: =ROUND(IF(A12>=Assumptions!B144,(IF(A12>=25,Assumptions!B151,IF(A12>=16,Assumptions!B150,Assumptions!B149))/1000*Assumptions!B146)+IF(A12>=Assumptions!B145,(IF(A12>=25,Assumptions!B151,IF(A12>=16,Assumptions!B150,Assumptions!B149))*Assumptions!B152/1000*Assumptions!B147),0),0),0) -> 0 | AD12: =IF(Y12>=10000,Assumptions!B170,IF(Y12>=5000,Assumptions!B169,IF(Y12>=2000,Assumptions!B168,IF(Y12>=500,Assumptions!B167,0)))) -> 0
A13: 8 | B13: =B12*(1+Assumptions!B33) -> 1064.2849 | C13: =ROUND(AB13*Assumptions!B25,0) -> 22 | D13: =ROUND(AB13*Assumptions!B22,0) -> 2 | E13: =E12+D13-F13 -> 9 | F13: =ROUND(E12*Assumptions!B43,0) -> 1 | G13: =D13-F13 -> 1 | H13: =ROUND(E13*Assumptions!B14,0) -> 72 | I13: =H13 -> 72 | J13: =ROUND(E13*Assumptions!B68,0) -> 32 | K13: =ROUND(J13*Assumptions!B65,0) -> 3 | L13: =Assumptions!B70+IF(E13>Assumptions!B72,45,0) -> 31 | M13: =Assumptions!B76+Assumptions!B77 -> 35 | N13: =Assumptions!B81+Assumptions!B82+Assumptions!B87/12+Assumptions!B148 -> 116 | O13: =ROUND(I13*Assumptions!B85+E13*Assumptions!B86+W13*Assumptions!B85+ROUND(AB13*Assumptions!B137*Assumptions!B138*Assumptions!B139,0)*Assumptions!B86,0) -> 7 | P13: =K13+L13+M13+N13+O13+X13 -> 199 | Q13: =I13-P13 -> -127 | R13: =ROUND(AB13*Assumptions!B51*Assumptions!B52,0) -> 381 | S13: =I13+R13+W13+AC13+AD13 -> 495 | T13: =IF(U13<P13*3,0,IF(U13<P13*6,ROUND((Q13+R13+W13+AC13+AD13)*0.75*Assumptions!B113,0),ROUND((Q13+R13+W13+AC13+AD13)*0.75*Assumptions!B114,0))) -> 0 | U13: =U12+Q13+R13+W13+AC13+AD13 -> -2546 | V13: =IF(AB13>=Assumptions!B107,"Signal 6",IF(AB13>=Assumptions!B106,"Signal 5",IF(AB13>=Assumptions!B105,"Signal 4",IF(AB13>=Assumptions!B104,"Signal 3",IF(AB13>=Assumptions!B103,"Signal 2",IF(AB13>=Assumptions!B102,"Signal 1","Pre-Signal 1")))))) -> Pre-Signal 1 | W13: =ROUND(AB13*Assumptions!B137*Assumptions!B138*Assumptions!B139*Assumptions!B136,0) -> 42 | X13: =ROUND(AB13*Assumptions!B137*Assumptions!B65,0) -> 7 | Y13: =ROUND(Y12*(1+Assumptions!B164),0) -> 164 | Z13: =Assumptions!B154 -> 25 | AA13: =ROUND(Y13*Assumptions!B166,0) -> 0 | AB13: =B13+Z13+AA13 -> 1089.2849 | AC13: =ROUND(IF(A13>=Assumptions!B144,(IF(A13>=25,Assumptions!B151,IF(A13>=16,Assumptions!B150,Assumptions!B149))/1000*Assumptions!B146)+IF(A13>=Assumptions!B145,(IF(A13>=25,Assumptions!B151,IF(A13>=16,Assumptions!B150,Assumptions!B149))*Assumptions!B152/1000*Assumptions!B147),0),0),0) -> 0 | AD13: =IF(Y13>=10000,Assumptions!B170,IF(Y13>=5000,Assumptions!B169,IF(Y13>=2000,Assumptions!B168,IF(Y13>=500,Assumptions!B167,0)))) -> 0
A14: 9 | B14: =B13*(1+Assumptions!B33) -> 1149.4277 | C14: =ROUND(AB14*Assumptions!B25,0) -> 24 | D14: =ROUND(AB14*Assumptions!B22,0) -> 2 | E14: =E13+D14-F14 -> 10 | F14: =ROUND(E13*Assumptions!B43,0) -> 1 | G14: =D14-F14 -> 1 | H14: =ROUND(E14*((Assumptions!B14+Assumptions!B15)/2),0) -> 105 | I14: =H14 -> 105 | J14: =ROUND(E14*Assumptions!B68,0) -> 35 | K14: =ROUND(J14*Assumptions!B65,0) -> 3 | L14: =Assumptions!B70+IF(E14>Assumptions!B72,45,0) -> 31 | M14: =Assumptions!B76+Assumptions!B77 -> 35 | N14: =Assumptions!B81+Assumptions!B82+Assumptions!B87/12+Assumptions!B148 -> 116 | O14: =ROUND(I14*Assumptions!B85+E14*Assumptions!B86+W14*Assumptions!B85+ROUND(AB14*Assumptions!B137*Assumptions!B138*Assumptions!B139,0)*Assumptions!B86,0) -> 9 | P14: =K14+L14+M14+N14+O14+X14 -> 202 | Q14: =I14-P14 -> -97 | R14: =ROUND(AB14*Assumptions!B51*Assumptions!B52,0) -> 424 | S14: =I14+R14+W14+AC14+AD14 -> 576 | T14: =IF(U14<P14*3,0,IF(U14<P14*6,ROUND((Q14+R14+W14+AC14+AD14)*0.75*Assumptions!B113,0),ROUND((Q14+R14+W14+AC14+AD14)*0.75*Assumptions!B114,0))) -> 0 | U14: =U13+Q14+R14+W14+AC14+AD14 -> -2172 | V14: =IF(AB14>=Assumptions!B107,"Signal 6",IF(AB14>=Assumptions!B106,"Signal 5",IF(AB14>=Assumptions!B105,"Signal 4",IF(AB14>=Assumptions!B104,"Signal 3",IF(AB14>=Assumptions!B103,"Signal 2",IF(AB14>=Assumptions!B102,"Signal 1","Pre-Signal 1")))))) -> Pre-Signal 1 | W14: =ROUND(AB14*Assumptions!B137*Assumptions!B138*Assumptions!B139*Assumptions!B136,0) -> 47 | X14: =ROUND(AB14*Assumptions!B137*Assumptions!B65,0) -> 8 | Y14: =ROUND(Y13*(1+Assumptions!B164),0) -> 189 | Z14: =Assumptions!B155 -> 60 | AA14: =ROUND(Y14*Assumptions!B166,0) -> 1 | AB14: =B14+Z14+AA14 -> 1210.4277 | AC14: =ROUND(IF(A14>=Assumptions!B144,(IF(A14>=25,Assumptions!B151,IF(A14>=16,Assumptions!B150,Assumptions!B149))/1000*Assumptions!B146)+IF(A14>=Assumptions!B145,(IF(A14>=25,Assumptions!B151,IF(A14>=16,Assumptions!B150,Assumptions!B149))*Assumptions!B152/1000*Assumptions!B147),0),0),0) -> 0 | AD14: =IF(Y14>=10000,Assumptions!B170,IF(Y14>=5000,Assumptions!B169,IF(Y14>=2000,Assumptions!B168,IF(Y14>=500,Assumptions!B167,0)))) -> 0
A15: 10 | B15: =B14*(1+Assumptions!B33) -> 1241.3819 | C15: =ROUND(AB15*Assumptions!B25,0) -> 26 | D15: =ROUND(AB15*Assumptions!B22,0) -> 2 | E15: =E14+D15-F15 -> 11 | F15: =ROUND(E14*Assumptions!B43,0) -> 1 | G15: =D15-F15 -> 1 | H15: =ROUND(E15*(Assumptions!B15*0.85+Assumptions!B11*0.15),0) -> 126 | I15: =H15 -> 126 | J15: =ROUND(E15*Assumptions!B68,0) -> 39 | K15: =ROUND(J15*Assumptions!B65,0) -> 3 | L15: =Assumptions!B70+IF(E15>Assumptions!B72,45,0) -> 31 | M15: =Assumptions!B76+Assumptions!B77 -> 35 | N15: =Assumptions!B81+Assumptions!B82+Assumptions!B87/12+Assumptions!B148 -> 116 | O15: =ROUND(I15*Assumptions!B85+E15*Assumptions!B86+W15*Assumptions!B85+ROUND(AB15*Assumptions!B137*Assumptions!B138*Assumptions!B139,0)*Assumptions!B86,0) -> 10 | P15: =K15+L15+M15+N15+O15+X15 -> 203 | Q15: =I15-P15 -> -77 | R15: =ROUND(AB15*Assumptions!B51*Assumptions!B52,0) -> 456 | S15: =I15+R15+W15+AC15+AD15 -> 633 | T15: =IF(U15<P15*3,0,IF(U15<P15*6,ROUND((Q15+R15+W15+AC15+AD15)*0.75*Assumptions!B113,0),ROUND((Q15+R15+W15+AC15+AD15)*0.75*Assumptions!B114,0))) -> 0 | U15: =U14+Q15+R15+W15+AC15+AD15 -> -1742 | V15: =IF(AB15>=Assumptions!B107,"Signal 6",IF(AB15>=Assumptions!B106,"Signal 5",IF(AB15>=Assumptions!B105,"Signal 4",IF(AB15>=Assumptions!B104,"Signal 3",IF(AB15>=Assumptions!B103,"Signal 2",IF(AB15>=Assumptions!B102,"Signal 1","Pre-Signal 1")))))) -> Pre-Signal 1 | W15: =ROUND(AB15*Assumptions!B137*Assumptions!B138*Assumptions!B139*Assumptions!B136,0) -> 51 | X15: =ROUND(AB15*Assumptions!B137*Assumptions!B65,0) -> 8 | Y15: =ROUND(Y14*(1+Assumptions!B164),0) -> 217 | Z15: =Assumptions!B155 -> 60 | AA15: =ROUND(Y15*Assumptions!B166,0) -> 1 | AB15: =B15+Z15+AA15 -> 1302.3819 | AC15: =ROUND(IF(A15>=Assumptions!B144,(IF(A15>=25,Assumptions!B151,IF(A15>=16,Assumptions!B150,Assumptions!B149))/1000*Assumptions!B146)+IF(A15>=Assumptions!B145,(IF(A15>=25,Assumptions!B151,IF(A15>=16,Assumptions!B150,Assumptions!B149))*Assumptions!B152/1000*Assumptions!B147),0),0),0) -> 0 | AD15: =IF(Y15>=10000,Assumptions!B170,IF(Y15>=5000,Assumptions!B169,IF(Y15>=2000,Assumptions!B168,IF(Y15>=500,Assumptions!B167,0)))) -> 0
A16: 11 | B16: =B15*(1+Assumptions!B33) -> 1340.6924 | C16: =ROUND(AB16*Assumptions!B25,0) -> 28 | D16: =ROUND(AB16*Assumptions!B22,0) -> 2 | E16: =E15+D16-F16 -> 12 | F16: =ROUND(E15*Assumptions!B43,0) -> 1 | G16: =D16-F16 -> 1 | H16: =ROUND(E16*(Assumptions!B15*0.85+Assumptions!B11*0.15),0) -> 138 | I16: =H16 -> 138 | J16: =ROUND(E16*Assumptions!B68,0) -> 42 | K16: =ROUND(J16*Assumptions!B65,0) -> 3 | L16: =Assumptions!B70+IF(E16>Assumptions!B72,45,0) -> 31 | M16: =Assumptions!B76+Assumptions!B77 -> 35 | N16: =Assumptions!B81+Assumptions!B82+Assumptions!B87/12+Assumptions!B148 -> 116 | O16: =ROUND(I16*Assumptions!B85+E16*Assumptions!B86+W16*Assumptions!B85+ROUND(AB16*Assumptions!B137*Assumptions!B138*Assumptions!B139,0)*Assumptions!B86,0) -> 10 | P16: =K16+L16+M16+N16+O16+X16 -> 204 | Q16: =I16-P16 -> -66 | R16: =ROUND(AB16*Assumptions!B51*Assumptions!B52,0) -> 491 | S16: =I16+R16+W16+AC16+AD16 -> 684 | T16: =IF(U16<P16*3,0,IF(U16<P16*6,ROUND((Q16+R16+W16+AC16+AD16)*0.75*Assumptions!B113,0),ROUND((Q16+R16+W16+AC16+AD16)*0.75*Assumptions!B114,0))) -> 0 | U16: =U15+Q16+R16+W16+AC16+AD16 -> -1262 | V16: =IF(AB16>=Assumptions!B107,"Signal 6",IF(AB16>=Assumptions!B106,"Signal 5",IF(AB16>=Assumptions!B105,"Signal 4",IF(AB16>=Assumptions!B104,"Signal 3",IF(AB16>=Assumptions!B103,"Signal 2",IF(AB16>=Assumptions!B102,"Signal 1","Pre-Signal 1")))))) -> Pre-Signal 1 | W16: =ROUND(AB16*Assumptions!B137*Assumptions!B138*Assumptions!B139*Assumptions!B136,0) -> 55 | X16: =ROUND(AB16*Assumptions!B137*Assumptions!B65,0) -> 9 | Y16: =ROUND(Y15*(1+Assumptions!B164),0) -> 250 | Z16: =Assumptions!B155 -> 60 | AA16: =ROUND(Y16*Assumptions!B166,0) -> 1 | AB16: =B16+Z16+AA16 -> 1401.6924 | AC16: =ROUND(IF(A16>=Assumptions!B144,(IF(A16>=25,Assumptions!B151,IF(A16>=16,Assumptions!B150,Assumptions!B149))/1000*Assumptions!B146)+IF(A16>=Assumptions!B145,(IF(A16>=25,Assumptions!B151,IF(A16>=16,Assumptions!B150,Assumptions!B149))*Assumptions!B152/1000*Assumptions!B147),0),0),0) -> 0 | AD16: =IF(Y16>=10000,Assumptions!B170,IF(Y16>=5000,Assumptions!B169,IF(Y16>=2000,Assumptions!B168,IF(Y16>=500,Assumptions!B167,0)))) -> 0
A17: 12 | B17: =B16*(1+Assumptions!B33) -> 1447.9478 | C17: =ROUND(AB17*Assumptions!B25,0) -> 31 | D17: =ROUND(AB17*Assumptions!B22,0) -> 2 | E17: =E16+D17-F17 -> 13 | F17: =ROUND(E16*Assumptions!B43,0) -> 1 | G17: =D17-F17 -> 1 | H17: =ROUND(E17*(Assumptions!B15*0.85+Assumptions!B11*0.15),0) -> 149 | I17: =H17 -> 149 | J17: =ROUND(E17*Assumptions!B68,0) -> 46 | K17: =ROUND(J17*Assumptions!B65,0) -> 4 | L17: =Assumptions!B70+IF(E17>Assumptions!B72,45,0) -> 31 | M17: =Assumptions!B76+Assumptions!B77 -> 35 | N17: =Assumptions!B81+Assumptions!B82+Assumptions!B87/12+Assumptions!B148 -> 116 | O17: =ROUND(I17*Assumptions!B85+E17*Assumptions!B86+W17*Assumptions!B85+ROUND(AB17*Assumptions!B137*Assumptions!B138*Assumptions!B139,0)*Assumptions!B86,0) -> 11 | P17: =K17+L17+M17+N17+O17+X17 -> 207 | Q17: =I17-P17 -> -58 | R17: =ROUND(AB17*Assumptions!B51*Assumptions!B52,0) -> 551 | S17: =I17+R17+W17+AC17+AD17 -> 777 | T17: =IF(U17<P17*3,0,IF(U17<P17*6,ROUND((Q17+R17+W17+AC17+AD17)*0.75*Assumptions!B113,0),ROUND((Q17+R17+W17+AC17+AD17)*0.75*Assumptions!B114,0))) -> 0 | U17: =U16+Q17+R17+W17+AC17+AD17 -> -692 | V17: =IF(AB17>=Assumptions!B107,"Signal 6",IF(AB17>=Assumptions!B106,"Signal 5",IF(AB17>=Assumptions!B105,"Signal 4",IF(AB17>=Assumptions!B104,"Signal 3",IF(AB17>=Assumptions!B103,"Signal 2",IF(AB17>=Assumptions!B102,"Signal 1","Pre-Signal 1")))))) -> Pre-Signal 1 | W17: =ROUND(AB17*Assumptions!B137*Assumptions!B138*Assumptions!B139*Assumptions!B136,0) -> 61 | X17: =ROUND(AB17*Assumptions!B137*Assumptions!B65,0) -> 10 | Y17: =ROUND(Y16*(1+Assumptions!B164),0) -> 288 | Z17: =Assumptions!B156 -> 125 | AA17: =ROUND(Y17*Assumptions!B166,0) -> 1 | AB17: =B17+Z17+AA17 -> 1573.9478 | AC17: =ROUND(IF(A17>=Assumptions!B144,(IF(A17>=25,Assumptions!B151,IF(A17>=16,Assumptions!B150,Assumptions!B149))/1000*Assumptions!B146)+IF(A17>=Assumptions!B145,(IF(A17>=25,Assumptions!B151,IF(A17>=16,Assumptions!B150,Assumptions!B149))*Assumptions!B152/1000*Assumptions!B147),0),0),0) -> 16 | AD17: =IF(Y17>=10000,Assumptions!B170,IF(Y17>=5000,Assumptions!B169,IF(Y17>=2000,Assumptions!B168,IF(Y17>=500,Assumptions!B167,0)))) -> 0
A18: 13 | B18: =B17*(1+Assumptions!B33) -> 1563.7836 | C18: =ROUND(AB18*Assumptions!B25,0) -> 34 | D18: =ROUND(AB18*Assumptions!B22,0) -> 3 | E18: =E17+D18-F18 -> 15 | F18: =ROUND(E17*Assumptions!B43,0) -> 1 | G18: =D18-F18 -> 2 | H18: =ROUND(E18*(Assumptions!B15*0.85+Assumptions!B11*0.15),0) -> 172 | I18: =H18 -> 172 | J18: =ROUND(E18*Assumptions!B68,0) -> 53 | K18: =ROUND(J18*Assumptions!B65,0) -> 4 | L18: =Assumptions!B70+IF(E18>Assumptions!B72,45,0) -> 31 | M18: =Assumptions!B76+Assumptions!B77 -> 35 | N18: =Assumptions!B81+Assumptions!B82+Assumptions!B87/12+Assumptions!B148 -> 116 | O18: =ROUND(I18*Assumptions!B85+E18*Assumptions!B86+W18*Assumptions!B85+ROUND(AB18*Assumptions!B137*Assumptions!B138*Assumptions!B139,0)*Assumptions!B86,0) -> 13 | P18: =K18+L18+M18+N18+O18+X18 -> 210 | Q18: =I18-P18 -> -38 | R18: =ROUND(AB18*Assumptions!B51*Assumptions!B52,0) -> 591 | S18: =I18+R18+W18+AC18+AD18 -> 845 | T18: =IF(U18<P18*3,0,IF(U18<P18*6,ROUND((Q18+R18+W18+AC18+AD18)*0.75*Assumptions!B113,0),ROUND((Q18+R18+W18+AC18+AD18)*0.75*Assumptions!B114,0))) -> 0 | U18: =U17+Q18+R18+W18+AC18+AD18 -> -57 | V18: =IF(AB18>=Assumptions!B107,"Signal 6",IF(AB18>=Assumptions!B106,"Signal 5",IF(AB18>=Assumptions!B105,"Signal 4",IF(AB18>=Assumptions!B104,"Signal 3",IF(AB18>=Assumptions!B103,"Signal 2",IF(AB18>=Assumptions!B102,"Signal 1","Pre-Signal 1")))))) -> Pre-Signal 1 | W18: =ROUND(AB18*Assumptions!B137*Assumptions!B138*Assumptions!B139*Assumptions!B136,0) -> 66 | X18: =ROUND(AB18*Assumptions!B137*Assumptions!B65,0) -> 11 | Y18: =ROUND(Y17*(1+Assumptions!B165),0) -> 317 | Z18: =Assumptions!B156 -> 125 | AA18: =ROUND(Y18*Assumptions!B166,0) -> 1 | AB18: =B18+Z18+AA18 -> 1689.7836 | AC18: =ROUND(IF(A18>=Assumptions!B144,(IF(A18>=25,Assumptions!B151,IF(A18>=16,Assumptions!B150,Assumptions!B149))/1000*Assumptions!B146)+IF(A18>=Assumptions!B145,(IF(A18>=25,Assumptions!B151,IF(A18>=16,Assumptions!B150,Assumptions!B149))*Assumptions!B152/1000*Assumptions!B147),0),0),0) -> 16 | AD18: =IF(Y18>=10000,Assumptions!B170,IF(Y18>=5000,Assumptions!B169,IF(Y18>=2000,Assumptions!B168,IF(Y18>=500,Assumptions!B167,0)))) -> 0
A19: 14 | B19: =B18*(1+Assumptions!B33) -> 1688.8863 | C19: =ROUND(AB19*Assumptions!B25,0) -> 36 | D19: =ROUND(AB19*Assumptions!B22,0) -> 3 | E19: =E18+D19-F19 -> 17 | F19: =ROUND(E18*Assumptions!B43,0) -> 1 | G19: =D19-F19 -> 2 | H19: =ROUND(E19*(Assumptions!B15*0.85+Assumptions!B11*0.15),0) -> 195 | I19: =H19 -> 195 | J19: =ROUND(E19*Assumptions!B68,0) -> 60 | K19: =ROUND(J19*Assumptions!B65,0) -> 5 | L19: =Assumptions!B70+IF(E19>Assumptions!B72,45,0) -> 31 | M19: =Assumptions!B76+Assumptions!B77 -> 35 | N19: =Assumptions!B81+Assumptions!B82+Assumptions!B87/12+Assumptions!B148 -> 116 | O19: =ROUND(I19*Assumptions!B85+E19*Assumptions!B86+W19*Assumptions!B85+ROUND(AB19*Assumptions!B137*Assumptions!B138*Assumptions!B139,0)*Assumptions!B86,0) -> 14 | P19: =K19+L19+M19+N19+O19+X19 -> 213 | Q19: =I19-P19 -> -18 | R19: =ROUND(AB19*Assumptions!B51*Assumptions!B52,0) -> 635 | S19: =I19+R19+W19+AC19+AD19 -> 917 | T19: =IF(U19<P19*3,0,IF(U19<P19*6,ROUND((Q19+R19+W19+AC19+AD19)*0.75*Assumptions!B113,0),ROUND((Q19+R19+W19+AC19+AD19)*0.75*Assumptions!B114,0))) -> 125 | U19: =U18+Q19+R19+W19+AC19+AD19 -> 647 | V19: =IF(AB19>=Assumptions!B107,"Signal 6",IF(AB19>=Assumptions!B106,"Signal 5",IF(AB19>=Assumptions!B105,"Signal 4",IF(AB19>=Assumptions!B104,"Signal 3",IF(AB19>=Assumptions!B103,"Signal 2",IF(AB19>=Assumptions!B102,"Signal 1","Pre-Signal 1")))))) -> Pre-Signal 1 | W19: =ROUND(AB19*Assumptions!B137*Assumptions!B138*Assumptions!B139*Assumptions!B136,0) -> 71 | X19: =ROUND(AB19*Assumptions!B137*Assumptions!B65,0) -> 12 | Y19: =ROUND(Y18*(1+Assumptions!B165),0) -> 349 | Z19: =Assumptions!B156 -> 125 | AA19: =ROUND(Y19*Assumptions!B166,0) -> 1 | AB19: =B19+Z19+AA19 -> 1814.8863 | AC19: =ROUND(IF(A19>=Assumptions!B144,(IF(A19>=25,Assumptions!B151,IF(A19>=16,Assumptions!B150,Assumptions!B149))/1000*Assumptions!B146)+IF(A19>=Assumptions!B145,(IF(A19>=25,Assumptions!B151,IF(A19>=16,Assumptions!B150,Assumptions!B149))*Assumptions!B152/1000*Assumptions!B147),0),0),0) -> 16 | AD19: =IF(Y19>=10000,Assumptions!B170,IF(Y19>=5000,Assumptions!B169,IF(Y19>=2000,Assumptions!B168,IF(Y19>=500,Assumptions!B167,0)))) -> 0
A20: 15 | B20: =B19*(1+Assumptions!B33) -> 1823.9972 | C20: =ROUND(AB20*Assumptions!B25,0) -> 39 | D20: =ROUND(AB20*Assumptions!B22,0) -> 3 | E20: =E19+D20-F20 -> 19 | F20: =ROUND(E19*Assumptions!B43,0) -> 1 | G20: =D20-F20 -> 2 | H20: =ROUND(E20*(Assumptions!B15*0.85+Assumptions!B11*0.15),0) -> 218 | I20: =H20 -> 218 | J20: =ROUND(E20*Assumptions!B68,0) -> 67 | K20: =ROUND(J20*Assumptions!B65,0) -> 5 | L20: =Assumptions!B70+IF(E20>Assumptions!B72,45,0) -> 31 | M20: =Assumptions!B76+Assumptions!B77 -> 35 | N20: =Assumptions!B81+Assumptions!B82+Assumptions!B87/12+Assumptions!B148 -> 116 | O20: =ROUND(I20*Assumptions!B85+E20*Assumptions!B86+W20*Assumptions!B85+ROUND(AB20*Assumptions!B137*Assumptions!B138*Assumptions!B139,0)*Assumptions!B86,0) -> 16 | P20: =K20+L20+M20+N20+O20+X20 -> 215 | Q20: =I20-P20 -> 3 | R20: =ROUND(AB20*Assumptions!B51*Assumptions!B52,0) -> 682 | S20: =I20+R20+W20+AC20+AD20 -> 992 | T20: =IF(U20<P20*3,0,IF(U20<P20*6,ROUND((Q20+R20+W20+AC20+AD20)*0.75*Assumptions!B113,0),ROUND((Q20+R20+W20+AC20+AD20)*0.75*Assumptions!B114,0))) -> 223 | U20: =U19+Q20+R20+W20+AC20+AD20 -> 1424 | V20: =IF(AB20>=Assumptions!B107,"Signal 6",IF(AB20>=Assumptions!B106,"Signal 5",IF(AB20>=Assumptions!B105,"Signal 4",IF(AB20>=Assumptions!B104,"Signal 3",IF(AB20>=Assumptions!B103,"Signal 2",IF(AB20>=Assumptions!B102,"Signal 1","Pre-Signal 1")))))) -> Pre-Signal 1 | W20: =ROUND(AB20*Assumptions!B137*Assumptions!B138*Assumptions!B139*Assumptions!B136,0) -> 76 | X20: =ROUND(AB20*Assumptions!B137*Assumptions!B65,0) -> 12 | Y20: =ROUND(Y19*(1+Assumptions!B165),0) -> 384 | Z20: =Assumptions!B156 -> 125 | AA20: =ROUND(Y20*Assumptions!B166,0) -> 1 | AB20: =B20+Z20+AA20 -> 1949.9972 | AC20: =ROUND(IF(A20>=Assumptions!B144,(IF(A20>=25,Assumptions!B151,IF(A20>=16,Assumptions!B150,Assumptions!B149))/1000*Assumptions!B146)+IF(A20>=Assumptions!B145,(IF(A20>=25,Assumptions!B151,IF(A20>=16,Assumptions!B150,Assumptions!B149))*Assumptions!B152/1000*Assumptions!B147),0),0),0) -> 16 | AD20: =IF(Y20>=10000,Assumptions!B170,IF(Y20>=5000,Assumptions!B169,IF(Y20>=2000,Assumptions!B168,IF(Y20>=500,Assumptions!B167,0)))) -> 0
A21: 16 | B21: =B20*(1+Assumptions!B33) -> 1969.917 | C21: =ROUND(AB21*Assumptions!B25,0) -> 44 | D21: =ROUND(AB21*Assumptions!B22,0) -> 3 | E21: =E20+D21-F21 -> 20 | F21: =ROUND(E20*Assumptions!B43,0) -> 2 | G21: =D21-F21 -> 1 | H21: =ROUND(E21*(Assumptions!B15*0.85+Assumptions!B11*0.15),0) -> 230 | I21: =H21 -> 230 | J21: =ROUND(E21*Assumptions!B68,0) -> 70 | K21: =ROUND(J21*Assumptions!B65,0) -> 6 | L21: =Assumptions!B70+IF(E21>Assumptions!B72,45,0) -> 31 | M21: =Assumptions!B76+Assumptions!B77 -> 35 | N21: =Assumptions!B81+Assumptions!B82+Assumptions!B87/12+Assumptions!B148 -> 116 | O21: =ROUND(I21*Assumptions!B85+E21*Assumptions!B86+W21*Assumptions!B85+ROUND(AB21*Assumptions!B137*Assumptions!B138*Assumptions!B139,0)*Assumptions!B86,0) -> 17 | P21: =K21+L21+M21+N21+O21+X21 -> 219 | Q21: =I21-P21 -> 11 | R21: =ROUND(AB21*Assumptions!B51*Assumptions!B52,0) -> 777 | S21: =I21+R21+W21+AC21+AD21 -> 1137 | T21: =IF(U21<P21*3,0,IF(U21<P21*6,ROUND((Q21+R21+W21+AC21+AD21)*0.75*Assumptions!B113,0),ROUND((Q21+R21+W21+AC21+AD21)*0.75*Assumptions!B114,0))) -> 263 | U21: =U20+Q21+R21+W21+AC21+AD21 -> 2342 | V21: =IF(AB21>=Assumptions!B107,"Signal 6",IF(AB21>=Assumptions!B106,"Signal 5",IF(AB21>=Assumptions!B105,"Signal 4",IF(AB21>=Assumptions!B104,"Signal 3",IF(AB21>=Assumptions!B103,"Signal 2",IF(AB21>=Assumptions!B102,"Signal 1","Pre-Signal 1")))))) -> Pre-Signal 1 | W21: =ROUND(AB21*Assumptions!B137*Assumptions!B138*Assumptions!B139*Assumptions!B136,0) -> 87 | X21: =ROUND(AB21*Assumptions!B137*Assumptions!B65,0) -> 14 | Y21: =ROUND(Y20*(1+Assumptions!B165),0) -> 422 | Z21: =Assumptions!B157 -> 250 | AA21: =ROUND(Y21*Assumptions!B166,0) -> 1 | AB21: =B21+Z21+AA21 -> 2220.917 | AC21: =ROUND(IF(A21>=Assumptions!B144,(IF(A21>=25,Assumptions!B151,IF(A21>=16,Assumptions!B150,Assumptions!B149))/1000*Assumptions!B146)+IF(A21>=Assumptions!B145,(IF(A21>=25,Assumptions!B151,IF(A21>=16,Assumptions!B150,Assumptions!B149))*Assumptions!B152/1000*Assumptions!B147),0),0),0) -> 43 | AD21: =IF(Y21>=10000,Assumptions!B170,IF(Y21>=5000,Assumptions!B169,IF(Y21>=2000,Assumptions!B168,IF(Y21>=500,Assumptions!B167,0)))) -> 0
A22: 17 | B22: =B21*(1+Assumptions!B33) -> 2127.5104 | C22: =ROUND(AB22*Assumptions!B25,0) -> 48 | D22: =ROUND(AB22*Assumptions!B22,0) -> 4 | E22: =E21+D22-F22 -> 22 | F22: =ROUND(E21*Assumptions!B43,0) -> 2 | G22: =D22-F22 -> 2 | H22: =ROUND(E22*(Assumptions!B15*0.85+Assumptions!B11*0.15),0) -> 252 | I22: =H22 -> 252 | J22: =ROUND(E22*Assumptions!B68,0) -> 77 | K22: =ROUND(J22*Assumptions!B65,0) -> 6 | L22: =Assumptions!B70+IF(E22>Assumptions!B72,45,0) -> 31 | M22: =Assumptions!B76+Assumptions!B77 -> 35 | N22: =Assumptions!B81+Assumptions!B82+Assumptions!B87/12+Assumptions!B148 -> 116 | O22: =ROUND(I22*Assumptions!B85+E22*Assumptions!B86+W22*Assumptions!B85+ROUND(AB22*Assumptions!B137*Assumptions!B138*Assumptions!B139,0)*Assumptions!B86,0) -> 19 | P22: =K22+L22+M22+N22+O22+X22 -> 222 | Q22: =I22-P22 -> 30 | R22: =ROUND(AB22*Assumptions!B51*Assumptions!B52,0) -> 832 | S22: =I22+R22+W22+AC22+AD22 -> 1220 | T22: =IF(U22<P22*3,0,IF(U22<P22*6,ROUND((Q22+R22+W22+AC22+AD22)*0.75*Assumptions!B113,0),ROUND((Q22+R22+W22+AC22+AD22)*0.75*Assumptions!B114,0))) -> 286 | U22: =U21+Q22+R22+W22+AC22+AD22 -> 3340 | V22: =IF(AB22>=Assumptions!B107,"Signal 6",IF(AB22>=Assumptions!B106,"Signal 5",IF(AB22>=Assumptions!B105,"Signal 4",IF(AB22>=Assumptions!B104,"Signal 3",IF(AB22>=Assumptions!B103,"Signal 2",IF(AB22>=Assumptions!B102,"Signal 1","Pre-Signal 1")))))) -> Pre-Signal 1 | W22: =ROUND(AB22*Assumptions!B137*Assumptions!B138*Assumptions!B139*Assumptions!B136,0) -> 93 | X22: =ROUND(AB22*Assumptions!B137*Assumptions!B65,0) -> 15 | Y22: =ROUND(Y21*(1+Assumptions!B165),0) -> 464 | Z22: =Assumptions!B157 -> 250 | AA22: =ROUND(Y22*Assumptions!B166,0) -> 1 | AB22: =B22+Z22+AA22 -> 2378.5104 | AC22: =ROUND(IF(A22>=Assumptions!B144,(IF(A22>=25,Assumptions!B151,IF(A22>=16,Assumptions!B150,Assumptions!B149))/1000*Assumptions!B146)+IF(A22>=Assumptions!B145,(IF(A22>=25,Assumptions!B151,IF(A22>=16,Assumptions!B150,Assumptions!B149))*Assumptions!B152/1000*Assumptions!B147),0),0),0) -> 43 | AD22: =IF(Y22>=10000,Assumptions!B170,IF(Y22>=5000,Assumptions!B169,IF(Y22>=2000,Assumptions!B168,IF(Y22>=500,Assumptions!B167,0)))) -> 0
A23: 18 | B23: =B22*(1+Assumptions!B33) -> 2297.7112 | C23: =ROUND(AB23*Assumptions!B25,0) -> 51 | D23: =ROUND(AB23*Assumptions!B22,0) -> 4 | E23: =E22+D23-F23 -> 24 | F23: =ROUND(E22*Assumptions!B43,0) -> 2 | G23: =D23-F23 -> 2 | H23: =ROUND(E23*(Assumptions!B15*0.85+Assumptions!B11*0.15),0) -> 275 | I23: =H23 -> 275 | J23: =ROUND(E23*Assumptions!B68,0) -> 84 | K23: =ROUND(J23*Assumptions!B65,0) -> 7 | L23: =Assumptions!B70+IF(E23>Assumptions!B72,45,0) -> 31 | M23: =Assumptions!B76+Assumptions!B77 -> 35 | N23: =Assumptions!B81+Assumptions!B82+Assumptions!B87/12+Assumptions!B148 -> 116 | O23: =ROUND(I23*Assumptions!B85+E23*Assumptions!B86+W23*Assumptions!B85+ROUND(AB23*Assumptions!B137*Assumptions!B138*Assumptions!B139,0)*Assumptions!B86,0) -> 20 | P23: =K23+L23+M23+N23+O23+X23 -> 225 | Q23: =I23-P23 -> 50 | R23: =ROUND(AB23*Assumptions!B51*Assumptions!B52,0) -> 892 | S23: =I23+R23+W23+AC23+AD23 -> 1314 | T23: =IF(U23<P23*3,0,IF(U23<P23*6,ROUND((Q23+R23+W23+AC23+AD23)*0.75*Assumptions!B113,0),ROUND((Q23+R23+W23+AC23+AD23)*0.75*Assumptions!B114,0))) -> 312 | U23: =U22+Q23+R23+W23+AC23+AD23 -> 4429 | V23: =IF(AB23>=Assumptions!B107,"Signal 6",IF(AB23>=Assumptions!B106,"Signal 5",IF(AB23>=Assumptions!B105,"Signal 4",IF(AB23>=Assumptions!B104,"Signal 3",IF(AB23>=Assumptions!B103,"Signal 2",IF(AB23>=Assumptions!B102,"Signal 1","Pre-Signal 1")))))) -> Pre-Signal 1 | W23: =ROUND(AB23*Assumptions!B137*Assumptions!B138*Assumptions!B139*Assumptions!B136,0) -> 99 | X23: =ROUND(AB23*Assumptions!B137*Assumptions!B65,0) -> 16 | Y23: =ROUND(Y22*(1+Assumptions!B165),0) -> 510 | Z23: =Assumptions!B157 -> 250 | AA23: =ROUND(Y23*Assumptions!B166,0) -> 2 | AB23: =B23+Z23+AA23 -> 2549.7112 | AC23: =ROUND(IF(A23>=Assumptions!B144,(IF(A23>=25,Assumptions!B151,IF(A23>=16,Assumptions!B150,Assumptions!B149))/1000*Assumptions!B146)+IF(A23>=Assumptions!B145,(IF(A23>=25,Assumptions!B151,IF(A23>=16,Assumptions!B150,Assumptions!B149))*Assumptions!B152/1000*Assumptions!B147),0),0),0) -> 43 | AD23: =IF(Y23>=10000,Assumptions!B170,IF(Y23>=5000,Assumptions!B169,IF(Y23>=2000,Assumptions!B168,IF(Y23>=500,Assumptions!B167,0)))) -> 5
A24: 19 | B24: =B23*(1+Assumptions!B33) -> 2481.5281 | C24: =ROUND(AB24*Assumptions!B25,0) -> 55 | D24: =ROUND(AB24*Assumptions!B22,0) -> 4 | E24: =E23+D24-F24 -> 26 | F24: =ROUND(E23*Assumptions!B43,0) -> 2 | G24: =D24-F24 -> 2 | H24: =ROUND(E24*(Assumptions!B15*0.85+Assumptions!B11*0.15),0) -> 298 | I24: =H24 -> 298 | J24: =ROUND(E24*Assumptions!B68,0) -> 91 | K24: =ROUND(J24*Assumptions!B65,0) -> 7 | L24: =Assumptions!B70+IF(E24>Assumptions!B72,45,0) -> 31 | M24: =Assumptions!B76+Assumptions!B77 -> 35 | N24: =Assumptions!B81+Assumptions!B82+Assumptions!B87/12+Assumptions!B148 -> 116 | O24: =ROUND(I24*Assumptions!B85+E24*Assumptions!B86+W24*Assumptions!B85+ROUND(AB24*Assumptions!B137*Assumptions!B138*Assumptions!B139,0)*Assumptions!B86,0) -> 22 | P24: =K24+L24+M24+N24+O24+X24 -> 228 | Q24: =I24-P24 -> 70 | R24: =ROUND(AB24*Assumptions!B51*Assumptions!B52,0) -> 957 | S24: =I24+R24+W24+AC24+AD24 -> 1410 | T24: =IF(U24<P24*3,0,IF(U24<P24*6,ROUND((Q24+R24+W24+AC24+AD24)*0.75*Assumptions!B113,0),ROUND((Q24+R24+W24+AC24+AD24)*0.75*Assumptions!B114,0))) -> 339 | U24: =U23+Q24+R24+W24+AC24+AD24 -> 5611 | V24: =IF(AB24>=Assumptions!B107,"Signal 6",IF(AB24>=Assumptions!B106,"Signal 5",IF(AB24>=Assumptions!B105,"Signal 4",IF(AB24>=Assumptions!B104,"Signal 3",IF(AB24>=Assumptions!B103,"Signal 2",IF(AB24>=Assumptions!B102,"Signal 1","Pre-Signal 1")))))) -> Pre-Signal 1 | W24: =ROUND(AB24*Assumptions!B137*Assumptions!B138*Assumptions!B139*Assumptions!B136,0) -> 107 | X24: =ROUND(AB24*Assumptions!B137*Assumptions!B65,0) -> 17 | Y24: =ROUND(Y23*(1+Assumptions!B165),0) -> 561 | Z24: =Assumptions!B157 -> 250 | AA24: =ROUND(Y24*Assumptions!B166,0) -> 2 | AB24: =B24+Z24+AA24 -> 2733.5281 | AC24: =ROUND(IF(A24>=Assumptions!B144,(IF(A24>=25,Assumptions!B151,IF(A24>=16,Assumptions!B150,Assumptions!B149))/1000*Assumptions!B146)+IF(A24>=Assumptions!B145,(IF(A24>=25,Assumptions!B151,IF(A24>=16,Assumptions!B150,Assumptions!B149))*Assumptions!B152/1000*Assumptions!B147),0),0),0) -> 43 | AD24: =IF(Y24>=10000,Assumptions!B170,IF(Y24>=5000,Assumptions!B169,IF(Y24>=2000,Assumptions!B168,IF(Y24>=500,Assumptions!B167,0)))) -> 5
A25: 20 | B25: =B24*(1+Assumptions!B33) -> 2680.0504 | C25: =ROUND(AB25*Assumptions!B25,0) -> 59 | D25: =ROUND(AB25*Assumptions!B22,0) -> 4 | E25: =E24+D25-F25 -> 28 | F25: =ROUND(E24*Assumptions!B43,0) -> 2 | G25: =D25-F25 -> 2 | H25: =ROUND(E25*(Assumptions!B15*0.85+Assumptions!B11*0.15),0) -> 321 | I25: =H25 -> 321 | J25: =ROUND(E25*Assumptions!B68,0) -> 98 | K25: =ROUND(J25*Assumptions!B65,0) -> 8 | L25: =Assumptions!B70+IF(E25>Assumptions!B72,45,0) -> 31 | M25: =Assumptions!B76+Assumptions!B77 -> 35 | N25: =Assumptions!B81+Assumptions!B82+Assumptions!B87/12+Assumptions!B148 -> 116 | O25: =ROUND(I25*Assumptions!B85+E25*Assumptions!B86+W25*Assumptions!B85+ROUND(AB25*Assumptions!B137*Assumptions!B138*Assumptions!B139,0)*Assumptions!B86,0) -> 24 | P25: =K25+L25+M25+N25+O25+X25 -> 233 | Q25: =I25-P25 -> 88 | R25: =ROUND(AB25*Assumptions!B51*Assumptions!B52,0) -> 1026 | S25: =I25+R25+W25+AC25+AD25 -> 1509 | T25: =IF(U25<P25*3,0,IF(U25<P25*6,ROUND((Q25+R25+W25+AC25+AD25)*0.75*Assumptions!B113,0),ROUND((Q25+R25+W25+AC25+AD25)*0.75*Assumptions!B114,0))) -> 366 | U25: =U24+Q25+R25+W25+AC25+AD25 -> 6887 | V25: =IF(AB25>=Assumptions!B107,"Signal 6",IF(AB25>=Assumptions!B106,"Signal 5",IF(AB25>=Assumptions!B105,"Signal 4",IF(AB25>=Assumptions!B104,"Signal 3",IF(AB25>=Assumptions!B103,"Signal 2",IF(AB25>=Assumptions!B102,"Signal 1","Pre-Signal 1")))))) -> Pre-Signal 1 | W25: =ROUND(AB25*Assumptions!B137*Assumptions!B138*Assumptions!B139*Assumptions!B136,0) -> 114 | X25: =ROUND(AB25*Assumptions!B137*Assumptions!B65,0) -> 19 | Y25: =ROUND(Y24*(1+Assumptions!B165),0) -> 617 | Z25: =Assumptions!B157 -> 250 | AA25: =ROUND(Y25*Assumptions!B166,0) -> 2 | AB25: =B25+Z25+AA25 -> 2932.0504 | AC25: =ROUND(IF(A25>=Assumptions!B144,(IF(A25>=25,Assumptions!B151,IF(A25>=16,Assumptions!B150,Assumptions!B149))/1000*Assumptions!B146)+IF(A25>=Assumptions!B145,(IF(A25>=25,Assumptions!B151,IF(A25>=16,Assumptions!B150,Assumptions!B149))*Assumptions!B152/1000*Assumptions!B147),0),0),0) -> 43 | AD25: =IF(Y25>=10000,Assumptions!B170,IF(Y25>=5000,Assumptions!B169,IF(Y25>=2000,Assumptions!B168,IF(Y25>=500,Assumptions!B167,0)))) -> 5
A26: 21 | B26: =B25*(1+Assumptions!B33) -> 2894.4544 | C26: =ROUND(AB26*Assumptions!B25,0) -> 63 | D26: =ROUND(AB26*Assumptions!B22,0) -> 5 | E26: =E25+D26-F26 -> 31 | F26: =ROUND(E25*Assumptions!B43,0) -> 2 | G26: =D26-F26 -> 3 | H26: =ROUND(E26*(Assumptions!B15*0.85+Assumptions!B11*0.15),0) -> 356 | I26: =H26 -> 356 | J26: =ROUND(E26*Assumptions!B68,0) -> 109 | K26: =ROUND(J26*Assumptions!B65,0) -> 9 | L26: =Assumptions!B70+IF(E26>Assumptions!B72,45,0) -> 31 | M26: =Assumptions!B76+Assumptions!B77 -> 35 | N26: =Assumptions!B81+Assumptions!B82+Assumptions!B87/12+Assumptions!B148 -> 116 | O26: =ROUND(I26*Assumptions!B85+E26*Assumptions!B86+W26*Assumptions!B85+ROUND(AB26*Assumptions!B137*Assumptions!B138*Assumptions!B139,0)*Assumptions!B86,0) -> 26 | P26: =K26+L26+M26+N26+O26+X26 -> 237 | Q26: =I26-P26 -> 119 | R26: =ROUND(AB26*Assumptions!B51*Assumptions!B52,0) -> 1101 | S26: =I26+R26+W26+AC26+AD26 -> 1628 | T26: =IF(U26<P26*3,0,IF(U26<P26*6,ROUND((Q26+R26+W26+AC26+AD26)*0.75*Assumptions!B113,0),ROUND((Q26+R26+W26+AC26+AD26)*0.75*Assumptions!B114,0))) -> 399 | U26: =U25+Q26+R26+W26+AC26+AD26 -> 8278 | V26: =IF(AB26>=Assumptions!B107,"Signal 6",IF(AB26>=Assumptions!B106,"Signal 5",IF(AB26>=Assumptions!B105,"Signal 4",IF(AB26>=Assumptions!B104,"Signal 3",IF(AB26>=Assumptions!B103,"Signal 2",IF(AB26>=Assumptions!B102,"Signal 1","Pre-Signal 1")))))) -> Pre-Signal 1 | W26: =ROUND(AB26*Assumptions!B137*Assumptions!B138*Assumptions!B139*Assumptions!B136,0) -> 123 | X26: =ROUND(AB26*Assumptions!B137*Assumptions!B65,0) -> 20 | Y26: =ROUND(Y25*(1+Assumptions!B165),0) -> 679 | Z26: =Assumptions!B157 -> 250 | AA26: =ROUND(Y26*Assumptions!B166,0) -> 2 | AB26: =B26+Z26+AA26 -> 3146.4544 | AC26: =ROUND(IF(A26>=Assumptions!B144,(IF(A26>=25,Assumptions!B151,IF(A26>=16,Assumptions!B150,Assumptions!B149))/1000*Assumptions!B146)+IF(A26>=Assumptions!B145,(IF(A26>=25,Assumptions!B151,IF(A26>=16,Assumptions!B150,Assumptions!B149))*Assumptions!B152/1000*Assumptions!B147),0),0),0) -> 43 | AD26: =IF(Y26>=10000,Assumptions!B170,IF(Y26>=5000,Assumptions!B169,IF(Y26>=2000,Assumptions!B168,IF(Y26>=500,Assumptions!B167,0)))) -> 5
A27: 22 | B27: =B26*(1+Assumptions!B33) -> 3126.0107 | C27: =ROUND(AB27*Assumptions!B25,0) -> 68 | D27: =ROUND(AB27*Assumptions!B22,0) -> 5 | E27: =E26+D27-F27 -> 34 | F27: =ROUND(E26*Assumptions!B43,0) -> 2 | G27: =D27-F27 -> 3 | H27: =ROUND(E27*(Assumptions!B15*0.85+Assumptions!B11*0.15),0) -> 390 | I27: =H27 -> 390 | J27: =ROUND(E27*Assumptions!B68,0) -> 119 | K27: =ROUND(J27*Assumptions!B65,0) -> 10 | L27: =Assumptions!B70+IF(E27>Assumptions!B72,45,0) -> 31 | M27: =Assumptions!B76+Assumptions!B77 -> 35 | N27: =Assumptions!B81+Assumptions!B82+Assumptions!B87/12+Assumptions!B148 -> 116 | O27: =ROUND(I27*Assumptions!B85+E27*Assumptions!B86+W27*Assumptions!B85+ROUND(AB27*Assumptions!B137*Assumptions!B138*Assumptions!B139,0)*Assumptions!B86,0) -> 28 | P27: =K27+L27+M27+N27+O27+X27 -> 242 | Q27: =I27-P27 -> 148 | R27: =ROUND(AB27*Assumptions!B51*Assumptions!B52,0) -> 1182 | S27: =I27+R27+W27+AC27+AD27 -> 1752 | T27: =IF(U27<P27*3,0,IF(U27<P27*6,ROUND((Q27+R27+W27+AC27+AD27)*0.75*Assumptions!B113,0),ROUND((Q27+R27+W27+AC27+AD27)*0.75*Assumptions!B114,0))) -> 433 | U27: =U26+Q27+R27+W27+AC27+AD27 -> 9788 | V27: =IF(AB27>=Assumptions!B107,"Signal 6",IF(AB27>=Assumptions!B106,"Signal 5",IF(AB27>=Assumptions!B105,"Signal 4",IF(AB27>=Assumptions!B104,"Signal 3",IF(AB27>=Assumptions!B103,"Signal 2",IF(AB27>=Assumptions!B102,"Signal 1","Pre-Signal 1")))))) -> Pre-Signal 1 | W27: =ROUND(AB27*Assumptions!B137*Assumptions!B138*Assumptions!B139*Assumptions!B136,0) -> 132 | X27: =ROUND(AB27*Assumptions!B137*Assumptions!B65,0) -> 22 | Y27: =ROUND(Y26*(1+Assumptions!B165),0) -> 747 | Z27: =Assumptions!B157 -> 250 | AA27: =ROUND(Y27*Assumptions!B166,0) -> 2 | AB27: =B27+Z27+AA27 -> 3378.0107 | AC27: =ROUND(IF(A27>=Assumptions!B144,(IF(A27>=25,Assumptions!B151,IF(A27>=16,Assumptions!B150,Assumptions!B149))/1000*Assumptions!B146)+IF(A27>=Assumptions!B145,(IF(A27>=25,Assumptions!B151,IF(A27>=16,Assumptions!B150,Assumptions!B149))*Assumptions!B152/1000*Assumptions!B147),0),0),0) -> 43 | AD27: =IF(Y27>=10000,Assumptions!B170,IF(Y27>=5000,Assumptions!B169,IF(Y27>=2000,Assumptions!B168,IF(Y27>=500,Assumptions!B167,0)))) -> 5
A28: 23 | B28: =B27*(1+Assumptions!B33) -> 3376.0916 | C28: =ROUND(AB28*Assumptions!B25,0) -> 73 | D28: =ROUND(AB28*Assumptions!B22,0) -> 5 | E28: =E27+D28-F28 -> 36 | F28: =ROUND(E27*Assumptions!B43,0) -> 3 | G28: =D28-F28 -> 2 | H28: =ROUND(E28*(Assumptions!B15*0.85+Assumptions!B11*0.15),0) -> 413 | I28: =H28 -> 413 | J28: =ROUND(E28*Assumptions!B68,0) -> 126 | K28: =ROUND(J28*Assumptions!B65,0) -> 10 | L28: =Assumptions!B70+IF(E28>Assumptions!B72,45,0) -> 31 | M28: =Assumptions!B76+Assumptions!B77 -> 35 | N28: =Assumptions!B81+Assumptions!B82+Assumptions!B87/12+Assumptions!B148 -> 116 | O28: =ROUND(I28*Assumptions!B85+E28*Assumptions!B86+W28*Assumptions!B85+ROUND(AB28*Assumptions!B137*Assumptions!B138*Assumptions!B139,0)*Assumptions!B86,0) -> 30 | P28: =K28+L28+M28+N28+O28+X28 -> 245 | Q28: =I28-P28 -> 168 | R28: =ROUND(AB28*Assumptions!B51*Assumptions!B52,0) -> 1270 | S28: =I28+R28+W28+AC28+AD28 -> 1872 | T28: =IF(U28<P28*3,0,IF(U28<P28*6,ROUND((Q28+R28+W28+AC28+AD28)*0.75*Assumptions!B113,0),ROUND((Q28+R28+W28+AC28+AD28)*0.75*Assumptions!B114,0))) -> 466 | U28: =U27+Q28+R28+W28+AC28+AD28 -> 11415 | V28: =IF(AB28>=Assumptions!B107,"Signal 6",IF(AB28>=Assumptions!B106,"Signal 5",IF(AB28>=Assumptions!B105,"Signal 4",IF(AB28>=Assumptions!B104,"Signal 3",IF(AB28>=Assumptions!B103,"Signal 2",IF(AB28>=Assumptions!B102,"Signal 1","Pre-Signal 1")))))) -> Pre-Signal 1 | W28: =ROUND(AB28*Assumptions!B137*Assumptions!B138*Assumptions!B139*Assumptions!B136,0) -> 141 | X28: =ROUND(AB28*Assumptions!B137*Assumptions!B65,0) -> 23 | Y28: =ROUND(Y27*(1+Assumptions!B165),0) -> 822 | Z28: =Assumptions!B157 -> 250 | AA28: =ROUND(Y28*Assumptions!B166,0) -> 2 | AB28: =B28+Z28+AA28 -> 3628.0916 | AC28: =ROUND(IF(A28>=Assumptions!B144,(IF(A28>=25,Assumptions!B151,IF(A28>=16,Assumptions!B150,Assumptions!B149))/1000*Assumptions!B146)+IF(A28>=Assumptions!B145,(IF(A28>=25,Assumptions!B151,IF(A28>=16,Assumptions!B150,Assumptions!B149))*Assumptions!B152/1000*Assumptions!B147),0),0),0) -> 43 | AD28: =IF(Y28>=10000,Assumptions!B170,IF(Y28>=5000,Assumptions!B169,IF(Y28>=2000,Assumptions!B168,IF(Y28>=500,Assumptions!B167,0)))) -> 5
A29: 24 | B29: =B28*(1+Assumptions!B33) -> 3646.1789 | C29: =ROUND(AB29*Assumptions!B25,0) -> 78 | D29: =ROUND(AB29*Assumptions!B22,0) -> 6 | E29: =E28+D29-F29 -> 39 | F29: =ROUND(E28*Assumptions!B43,0) -> 3 | G29: =D29-F29 -> 3 | H29: =ROUND(E29*(Assumptions!B15*0.85+Assumptions!B11*0.15),0) -> 448 | I29: =H29 -> 448 | J29: =ROUND(E29*Assumptions!B68,0) -> 137 | K29: =ROUND(J29*Assumptions!B65,0) -> 11 | L29: =Assumptions!B70+IF(E29>Assumptions!B72,45,0) -> 31 | M29: =Assumptions!B76+Assumptions!B77 -> 35 | N29: =Assumptions!B81+Assumptions!B82+Assumptions!B87/12+Assumptions!B148 -> 116 | O29: =ROUND(I29*Assumptions!B85+E29*Assumptions!B86+W29*Assumptions!B85+ROUND(AB29*Assumptions!B137*Assumptions!B138*Assumptions!B139,0)*Assumptions!B86,0) -> 33 | P29: =K29+L29+M29+N29+O29+X29 -> 251 | Q29: =I29-P29 -> 197 | R29: =ROUND(AB29*Assumptions!B51*Assumptions!B52,0) -> 1365 | S29: =I29+R29+W29+AC29+AD29 -> 2013 | T29: =IF(U29<P29*3,0,IF(U29<P29*6,ROUND((Q29+R29+W29+AC29+AD29)*0.75*Assumptions!B113,0),ROUND((Q29+R29+W29+AC29+AD29)*0.75*Assumptions!B114,0))) -> 505 | U29: =U28+Q29+R29+W29+AC29+AD29 -> 13177 | V29: =IF(AB29>=Assumptions!B107,"Signal 6",IF(AB29>=Assumptions!B106,"Signal 5",IF(AB29>=Assumptions!B105,"Signal 4",IF(AB29>=Assumptions!B104,"Signal 3",IF(AB29>=Assumptions!B103,"Signal 2",IF(AB29>=Assumptions!B102,"Signal 1","Pre-Signal 1")))))) -> Pre-Signal 1 | W29: =ROUND(AB29*Assumptions!B137*Assumptions!B138*Assumptions!B139*Assumptions!B136,0) -> 152 | X29: =ROUND(AB29*Assumptions!B137*Assumptions!B65,0) -> 25 | Y29: =ROUND(Y28*(1+Assumptions!B165),0) -> 904 | Z29: =Assumptions!B157 -> 250 | AA29: =ROUND(Y29*Assumptions!B166,0) -> 3 | AB29: =B29+Z29+AA29 -> 3899.1789 | AC29: =ROUND(IF(A29>=Assumptions!B144,(IF(A29>=25,Assumptions!B151,IF(A29>=16,Assumptions!B150,Assumptions!B149))/1000*Assumptions!B146)+IF(A29>=Assumptions!B145,(IF(A29>=25,Assumptions!B151,IF(A29>=16,Assumptions!B150,Assumptions!B149))*Assumptions!B152/1000*Assumptions!B147),0),0),0) -> 43 | AD29: =IF(Y29>=10000,Assumptions!B170,IF(Y29>=5000,Assumptions!B169,IF(Y29>=2000,Assumptions!B168,IF(Y29>=500,Assumptions!B167,0)))) -> 5
